{
 "cells": [
  {
   "cell_type": "markdown",
   "source": [
    "## Question 1"
   ],
   "metadata": {
    "collapsed": false
   }
  },
  {
   "cell_type": "markdown",
   "source": [
    "Answer: @task(retries=3, retry_delay_seconds=2, name=\"Read taxi data\")\n"
   ],
   "metadata": {
    "collapsed": false
   }
  },
  {
   "cell_type": "markdown",
   "source": [],
   "metadata": {
    "collapsed": false
   }
  },
  {
   "cell_type": "markdown",
   "source": [
    "## Question 2"
   ],
   "metadata": {
    "collapsed": false
   }
  },
  {
   "cell_type": "markdown",
   "source": [
    "![test](Cron_Example.png)"
   ],
   "metadata": {
    "collapsed": false
   }
  },
  {
   "cell_type": "markdown",
   "source": [
    "Answer: `0 9 3 * *`"
   ],
   "metadata": {
    "collapsed": false
   }
  },
  {
   "cell_type": "markdown",
   "source": [
    "## Question 3"
   ],
   "metadata": {
    "collapsed": false
   }
  },
  {
   "cell_type": "code",
   "execution_count": 5,
   "outputs": [
    {
     "name": "stdout",
     "output_type": "stream",
     "text": [
      "Collecting package metadata (current_repodata.json): done\r\n",
      "Solving environment: failed with repodata from current_repodata.json, will retry with next repodata source.\r\n",
      "Collecting package metadata (repodata.json): done\r\n",
      "Solving environment: done\r\n",
      "\r\n",
      "## Package Plan ##\r\n",
      "\r\n",
      "  environment location: /Users/evanhofmeister/opt/anaconda3/envs/prefect-ex\r\n",
      "\r\n",
      "  added / updated specs:\r\n",
      "    - python=3.9.12\r\n",
      "\r\n",
      "\r\n",
      "The following NEW packages will be INSTALLED:\r\n",
      "\r\n",
      "  ca-certificates    pkgs/main/osx-64::ca-certificates-2023.05.30-hecd8cb5_0 \r\n",
      "  libcxx             pkgs/main/osx-64::libcxx-14.0.6-h9765a3e_0 \r\n",
      "  libffi             pkgs/main/osx-64::libffi-3.3-hb1e8313_2 \r\n",
      "  ncurses            pkgs/main/osx-64::ncurses-6.4-hcec6c5f_0 \r\n",
      "  openssl            pkgs/main/osx-64::openssl-1.1.1u-hca72f7f_0 \r\n",
      "  pip                pkgs/main/osx-64::pip-23.1.2-py39hecd8cb5_0 \r\n",
      "  python             pkgs/main/osx-64::python-3.9.12-hdfd78df_1 \r\n",
      "  readline           pkgs/main/osx-64::readline-8.2-hca72f7f_0 \r\n",
      "  setuptools         pkgs/main/osx-64::setuptools-67.8.0-py39hecd8cb5_0 \r\n",
      "  sqlite             pkgs/main/osx-64::sqlite-3.41.2-h6c40b1e_0 \r\n",
      "  tk                 pkgs/main/osx-64::tk-8.6.12-h5d9f67b_0 \r\n",
      "  tzdata             pkgs/main/noarch::tzdata-2023c-h04d1e81_0 \r\n",
      "  wheel              pkgs/main/osx-64::wheel-0.38.4-py39hecd8cb5_0 \r\n",
      "  xz                 pkgs/main/osx-64::xz-5.4.2-h6c40b1e_0 \r\n",
      "  zlib               pkgs/main/osx-64::zlib-1.2.13-h4dc903c_0 \r\n",
      "\r\n",
      "\r\n",
      "\r\n",
      "Downloading and Extracting Packages\r\n",
      "\r\n",
      "Preparing transaction: done\r\n",
      "Verifying transaction: done\r\n",
      "Executing transaction: done\r\n",
      "#\r\n",
      "# To activate this environment, use\r\n",
      "#\r\n",
      "#     $ conda activate prefect-ex\r\n",
      "#\r\n",
      "# To deactivate an active environment, use\r\n",
      "#\r\n",
      "#     $ conda deactivate\r\n",
      "\r\n",
      "\r\n",
      "CommandNotFoundError: Your shell has not been properly configured to use 'conda activate'.\r\n",
      "To initialize your shell, run\r\n",
      "\r\n",
      "    $ conda init <SHELL_NAME>\r\n",
      "\r\n",
      "Currently supported shells are:\r\n",
      "  - bash\r\n",
      "  - fish\r\n",
      "  - tcsh\r\n",
      "  - xonsh\r\n",
      "  - zsh\r\n",
      "  - powershell\r\n",
      "\r\n",
      "See 'conda init --help' for more information and options.\r\n",
      "\r\n",
      "IMPORTANT: You may need to close and restart your shell after running 'conda init'.\r\n",
      "\r\n",
      "\r\n"
     ]
    }
   ],
   "source": [
    "!mkdir hw3_Orchestrate\n",
    "!cd hw3_Orchestrate\n",
    "!conda create -n prefect-ex python=3.9.12 -y\n",
    "!conda activate prefect-ex"
   ],
   "metadata": {
    "collapsed": false
   }
  },
  {
   "cell_type": "code",
   "execution_count": 7,
   "outputs": [
    {
     "name": "stdout",
     "output_type": "stream",
     "text": [
      "mkdir: data: File exists\r\n",
      "--2023-06-19 00:41:00--  https://d37ci6vzurychx.cloudfront.net/trip-data/green_tripdata_2023-01.parquet\r\n",
      "Resolving d37ci6vzurychx.cloudfront.net (d37ci6vzurychx.cloudfront.net)... 13.249.90.181, 13.249.90.174, 13.249.90.209, ...\r\n",
      "Connecting to d37ci6vzurychx.cloudfront.net (d37ci6vzurychx.cloudfront.net)|13.249.90.181|:443... connected.\r\n",
      "HTTP request sent, awaiting response... 200 OK\r\n",
      "Length: 1427002 (1.4M) [binary/octet-stream]\r\n",
      "Saving to: './data/green_tripdata_2023-01.parquet.1'\r\n",
      "\r\n",
      "green_tripdata_2023 100%[===================>]   1.36M  4.30MB/s    in 0.3s    \r\n",
      "\r\n",
      "2023-06-19 00:41:01 (4.30 MB/s) - './data/green_tripdata_2023-01.parquet.1' saved [1427002/1427002]\r\n",
      "\r\n",
      "--2023-06-19 00:41:01--  https://d37ci6vzurychx.cloudfront.net/trip-data/green_tripdata_2023-02.parquet\r\n",
      "Resolving d37ci6vzurychx.cloudfront.net (d37ci6vzurychx.cloudfront.net)... 13.249.90.174, 13.249.90.209, 13.249.90.176, ...\r\n",
      "Connecting to d37ci6vzurychx.cloudfront.net (d37ci6vzurychx.cloudfront.net)|13.249.90.174|:443... connected.\r\n",
      "HTTP request sent, awaiting response... 200 OK\r\n",
      "Length: 1533740 (1.5M) [binary/octet-stream]\r\n",
      "Saving to: './data/green_tripdata_2023-02.parquet.1'\r\n",
      "\r\n",
      "green_tripdata_2023 100%[===================>]   1.46M  3.60MB/s    in 0.4s    \r\n",
      "\r\n",
      "2023-06-19 00:41:02 (3.60 MB/s) - './data/green_tripdata_2023-02.parquet.1' saved [1533740/1533740]\r\n",
      "\r\n"
     ]
    }
   ],
   "source": [
    "!cd hw3_Orchestrate\n",
    "!mkdir data\n",
    "!wget -P ./data https://d37ci6vzurychx.cloudfront.net/trip-data/green_tripdata_2023-01.parquet\n",
    "!wget -P ./data https://d37ci6vzurychx.cloudfront.net/trip-data/green_tripdata_2023-02.parquet"
   ],
   "metadata": {
    "collapsed": false
   }
  },
  {
   "cell_type": "code",
   "execution_count": null,
   "outputs": [
    {
     "name": "stdout",
     "output_type": "stream",
     "text": [
      "\r\n",
      " ___ ___ ___ ___ ___ ___ _____ \r\n",
      "| _ \\ _ \\ __| __| __/ __|_   _| \r\n",
      "|  _/   / _|| _|| _| (__  | |  \r\n",
      "|_| |_|_\\___|_| |___\\___| |_|  \r\n",
      "\r\n",
      "Configure Prefect to communicate with the server with:\r\n",
      "\r\n",
      "    prefect config set PREFECT_API_URL=http://127.0.0.1:4200/api\r\n",
      "\r\n",
      "View the API reference documentation at http://127.0.0.1:4200/docs\r\n",
      "\r\n",
      "Check out the dashboard at http://127.0.0.1:4200\r\n",
      "\r\n",
      "\r\n",
      "\r\n",
      "12:33:56.351 | \u001B[31mERROR\u001B[0m   | prefect.server - Scheduler service failed!\r\n",
      "Traceback (most recent call last):\r\n",
      "  File \"/Users/evanhofmeister/opt/anaconda3/lib/python3.9/site-packages/prefect/server/api/server.py\", line 494, in on_service_exit\r\n",
      "    task.result()\r\n",
      "  File \"/Users/evanhofmeister/opt/anaconda3/lib/python3.9/site-packages/prefect/server/services/loop_service.py\", line 70, in start\r\n",
      "    await self._on_start()\r\n",
      "  File \"/Users/evanhofmeister/opt/anaconda3/lib/python3.9/site-packages/prefect/server/database/dependencies.py\", line 118, in async_wrapper\r\n",
      "    inject(kwargs)\r\n",
      "  File \"/Users/evanhofmeister/opt/anaconda3/lib/python3.9/site-packages/prefect/server/database/dependencies.py\", line 114, in inject\r\n",
      "    kwargs[\"db\"] = provide_database_interface()\r\n",
      "  File \"/Users/evanhofmeister/opt/anaconda3/lib/python3.9/site-packages/prefect/server/database/dependencies.py\", line 81, in provide_database_interface\r\n",
      "    orm = AioSqliteORMConfiguration()\r\n",
      "  File \"/Users/evanhofmeister/opt/anaconda3/lib/python3.9/site-packages/prefect/server/database/orm_models.py\", line 1400, in __init__\r\n",
      "    self._create_orm_models(\r\n",
      "  File \"/Users/evanhofmeister/opt/anaconda3/lib/python3.9/site-packages/prefect/server/database/orm_models.py\", line 1550, in _create_orm_models\r\n",
      "    class Variable(variable_mixin, self.Base):\r\n",
      "  File \"/Users/evanhofmeister/opt/anaconda3/lib/python3.9/site-packages/sqlalchemy/orm/decl_api.py\", line 193, in __init__\r\n",
      "    _as_declarative(reg, cls, dict_)\r\n",
      "  File \"/Users/evanhofmeister/opt/anaconda3/lib/python3.9/site-packages/sqlalchemy/orm/decl_base.py\", line 247, in _as_declarative\r\n",
      "    return _MapperConfig.setup_mapping(registry, cls, dict_, None, {})\r\n",
      "  File \"/Users/evanhofmeister/opt/anaconda3/lib/python3.9/site-packages/sqlalchemy/orm/decl_base.py\", line 328, in setup_mapping\r\n",
      "    return _ClassScanMapperConfig(\r\n",
      "  File \"/Users/evanhofmeister/opt/anaconda3/lib/python3.9/site-packages/sqlalchemy/orm/decl_base.py\", line 563, in __init__\r\n",
      "    self._scan_attributes()\r\n",
      "  File \"/Users/evanhofmeister/opt/anaconda3/lib/python3.9/site-packages/sqlalchemy/orm/decl_base.py\", line 785, in _scan_attributes\r\n",
      "    locally_collected_columns = self._produce_column_copies(\r\n",
      "  File \"/Users/evanhofmeister/opt/anaconda3/lib/python3.9/site-packages/sqlalchemy/orm/decl_base.py\", line 1388, in _produce_column_copies\r\n",
      "    collected_annotation = self._collect_annotation(\r\n",
      "  File \"/Users/evanhofmeister/opt/anaconda3/lib/python3.9/site-packages/sqlalchemy/orm/decl_base.py\", line 1277, in _collect_annotation\r\n",
      "    extracted = _extract_mapped_subtype(\r\n",
      "  File \"/Users/evanhofmeister/opt/anaconda3/lib/python3.9/site-packages/sqlalchemy/orm/util.py\", line 2356, in _extract_mapped_subtype\r\n",
      "    raise sa_exc.ArgumentError(\r\n",
      "sqlalchemy.exc.ArgumentError: Type annotation for \"Variable.name\" can't be correctly interpreted for Annotated Declarative Table form.  ORM annotations should normally make use of the ``Mapped[]`` generic type, or other ORM-compatible generic type, as a container for the actual type, which indicates the intent that the attribute is mapped. Class variables that are not intended to be mapped by the ORM should use ClassVar[].  To allow Annotated Declarative to disregard legacy annotations which don't use Mapped[] to pass, set \"__allow_unmapped__ = True\" on the class or a superclass this class. (Background on this error at: \u001B[94mhttps://sqlalche.me/e/20/zlpr)\u001B[0m\r\n",
      "12:33:56.360 | \u001B[31mERROR\u001B[0m   | prefect.server - RecentDeploymentsScheduler service failed!\r\n",
      "Traceback (most recent call last):\r\n",
      "  File \"/Users/evanhofmeister/opt/anaconda3/lib/python3.9/site-packages/prefect/server/api/server.py\", line 494, in on_service_exit\r\n",
      "    task.result()\r\n",
      "  File \"/Users/evanhofmeister/opt/anaconda3/lib/python3.9/site-packages/prefect/server/services/loop_service.py\", line 70, in start\r\n",
      "    await self._on_start()\r\n",
      "  File \"/Users/evanhofmeister/opt/anaconda3/lib/python3.9/site-packages/prefect/server/database/dependencies.py\", line 118, in async_wrapper\r\n",
      "    inject(kwargs)\r\n",
      "  File \"/Users/evanhofmeister/opt/anaconda3/lib/python3.9/site-packages/prefect/server/database/dependencies.py\", line 114, in inject\r\n",
      "    kwargs[\"db\"] = provide_database_interface()\r\n",
      "  File \"/Users/evanhofmeister/opt/anaconda3/lib/python3.9/site-packages/prefect/server/database/dependencies.py\", line 81, in provide_database_interface\r\n",
      "    orm = AioSqliteORMConfiguration()\r\n",
      "  File \"/Users/evanhofmeister/opt/anaconda3/lib/python3.9/site-packages/prefect/server/database/orm_models.py\", line 1400, in __init__\r\n",
      "    self._create_orm_models(\r\n",
      "  File \"/Users/evanhofmeister/opt/anaconda3/lib/python3.9/site-packages/prefect/server/database/orm_models.py\", line 1550, in _create_orm_models\r\n",
      "    class Variable(variable_mixin, self.Base):\r\n",
      "  File \"/Users/evanhofmeister/opt/anaconda3/lib/python3.9/site-packages/sqlalchemy/orm/decl_api.py\", line 193, in __init__\r\n",
      "    _as_declarative(reg, cls, dict_)\r\n",
      "  File \"/Users/evanhofmeister/opt/anaconda3/lib/python3.9/site-packages/sqlalchemy/orm/decl_base.py\", line 247, in _as_declarative\r\n",
      "    return _MapperConfig.setup_mapping(registry, cls, dict_, None, {})\r\n",
      "  File \"/Users/evanhofmeister/opt/anaconda3/lib/python3.9/site-packages/sqlalchemy/orm/decl_base.py\", line 328, in setup_mapping\r\n",
      "    return _ClassScanMapperConfig(\r\n",
      "  File \"/Users/evanhofmeister/opt/anaconda3/lib/python3.9/site-packages/sqlalchemy/orm/decl_base.py\", line 563, in __init__\r\n",
      "    self._scan_attributes()\r\n",
      "  File \"/Users/evanhofmeister/opt/anaconda3/lib/python3.9/site-packages/sqlalchemy/orm/decl_base.py\", line 785, in _scan_attributes\r\n",
      "    locally_collected_columns = self._produce_column_copies(\r\n",
      "  File \"/Users/evanhofmeister/opt/anaconda3/lib/python3.9/site-packages/sqlalchemy/orm/decl_base.py\", line 1388, in _produce_column_copies\r\n",
      "    collected_annotation = self._collect_annotation(\r\n",
      "  File \"/Users/evanhofmeister/opt/anaconda3/lib/python3.9/site-packages/sqlalchemy/orm/decl_base.py\", line 1277, in _collect_annotation\r\n",
      "    extracted = _extract_mapped_subtype(\r\n",
      "  File \"/Users/evanhofmeister/opt/anaconda3/lib/python3.9/site-packages/sqlalchemy/orm/util.py\", line 2356, in _extract_mapped_subtype\r\n",
      "    raise sa_exc.ArgumentError(\r\n",
      "sqlalchemy.exc.ArgumentError: Type annotation for \"Variable.name\" can't be correctly interpreted for Annotated Declarative Table form.  ORM annotations should normally make use of the ``Mapped[]`` generic type, or other ORM-compatible generic type, as a container for the actual type, which indicates the intent that the attribute is mapped. Class variables that are not intended to be mapped by the ORM should use ClassVar[].  To allow Annotated Declarative to disregard legacy annotations which don't use Mapped[] to pass, set \"__allow_unmapped__ = True\" on the class or a superclass this class. (Background on this error at: \u001B[94mhttps://sqlalche.me/e/20/zlpr)\u001B[0m\r\n",
      "12:33:56.361 | \u001B[31mERROR\u001B[0m   | prefect.server - MarkLateRuns service failed!\r\n",
      "Traceback (most recent call last):\r\n",
      "  File \"/Users/evanhofmeister/opt/anaconda3/lib/python3.9/site-packages/prefect/server/api/server.py\", line 494, in on_service_exit\r\n",
      "    task.result()\r\n",
      "  File \"/Users/evanhofmeister/opt/anaconda3/lib/python3.9/site-packages/prefect/server/services/loop_service.py\", line 70, in start\r\n",
      "    await self._on_start()\r\n",
      "  File \"/Users/evanhofmeister/opt/anaconda3/lib/python3.9/site-packages/prefect/server/database/dependencies.py\", line 118, in async_wrapper\r\n",
      "    inject(kwargs)\r\n",
      "  File \"/Users/evanhofmeister/opt/anaconda3/lib/python3.9/site-packages/prefect/server/database/dependencies.py\", line 114, in inject\r\n",
      "    kwargs[\"db\"] = provide_database_interface()\r\n",
      "  File \"/Users/evanhofmeister/opt/anaconda3/lib/python3.9/site-packages/prefect/server/database/dependencies.py\", line 81, in provide_database_interface\r\n",
      "    orm = AioSqliteORMConfiguration()\r\n",
      "  File \"/Users/evanhofmeister/opt/anaconda3/lib/python3.9/site-packages/prefect/server/database/orm_models.py\", line 1400, in __init__\r\n",
      "    self._create_orm_models(\r\n",
      "  File \"/Users/evanhofmeister/opt/anaconda3/lib/python3.9/site-packages/prefect/server/database/orm_models.py\", line 1550, in _create_orm_models\r\n",
      "    class Variable(variable_mixin, self.Base):\r\n",
      "  File \"/Users/evanhofmeister/opt/anaconda3/lib/python3.9/site-packages/sqlalchemy/orm/decl_api.py\", line 193, in __init__\r\n",
      "    _as_declarative(reg, cls, dict_)\r\n",
      "  File \"/Users/evanhofmeister/opt/anaconda3/lib/python3.9/site-packages/sqlalchemy/orm/decl_base.py\", line 247, in _as_declarative\r\n",
      "    return _MapperConfig.setup_mapping(registry, cls, dict_, None, {})\r\n",
      "  File \"/Users/evanhofmeister/opt/anaconda3/lib/python3.9/site-packages/sqlalchemy/orm/decl_base.py\", line 328, in setup_mapping\r\n",
      "    return _ClassScanMapperConfig(\r\n",
      "  File \"/Users/evanhofmeister/opt/anaconda3/lib/python3.9/site-packages/sqlalchemy/orm/decl_base.py\", line 563, in __init__\r\n",
      "    self._scan_attributes()\r\n",
      "  File \"/Users/evanhofmeister/opt/anaconda3/lib/python3.9/site-packages/sqlalchemy/orm/decl_base.py\", line 785, in _scan_attributes\r\n",
      "    locally_collected_columns = self._produce_column_copies(\r\n",
      "  File \"/Users/evanhofmeister/opt/anaconda3/lib/python3.9/site-packages/sqlalchemy/orm/decl_base.py\", line 1388, in _produce_column_copies\r\n",
      "    collected_annotation = self._collect_annotation(\r\n",
      "  File \"/Users/evanhofmeister/opt/anaconda3/lib/python3.9/site-packages/sqlalchemy/orm/decl_base.py\", line 1277, in _collect_annotation\r\n",
      "    extracted = _extract_mapped_subtype(\r\n",
      "  File \"/Users/evanhofmeister/opt/anaconda3/lib/python3.9/site-packages/sqlalchemy/orm/util.py\", line 2356, in _extract_mapped_subtype\r\n",
      "    raise sa_exc.ArgumentError(\r\n",
      "sqlalchemy.exc.ArgumentError: Type annotation for \"Variable.name\" can't be correctly interpreted for Annotated Declarative Table form.  ORM annotations should normally make use of the ``Mapped[]`` generic type, or other ORM-compatible generic type, as a container for the actual type, which indicates the intent that the attribute is mapped. Class variables that are not intended to be mapped by the ORM should use ClassVar[].  To allow Annotated Declarative to disregard legacy annotations which don't use Mapped[] to pass, set \"__allow_unmapped__ = True\" on the class or a superclass this class. (Background on this error at: \u001B[94mhttps://sqlalche.me/e/20/zlpr)\u001B[0m\r\n",
      "12:33:56.362 | \u001B[31mERROR\u001B[0m   | prefect.server - FailExpiredPauses service failed!\r\n",
      "Traceback (most recent call last):\r\n",
      "  File \"/Users/evanhofmeister/opt/anaconda3/lib/python3.9/site-packages/prefect/server/api/server.py\", line 494, in on_service_exit\r\n",
      "    task.result()\r\n",
      "  File \"/Users/evanhofmeister/opt/anaconda3/lib/python3.9/site-packages/prefect/server/services/loop_service.py\", line 70, in start\r\n",
      "    await self._on_start()\r\n",
      "  File \"/Users/evanhofmeister/opt/anaconda3/lib/python3.9/site-packages/prefect/server/database/dependencies.py\", line 118, in async_wrapper\r\n",
      "    inject(kwargs)\r\n",
      "  File \"/Users/evanhofmeister/opt/anaconda3/lib/python3.9/site-packages/prefect/server/database/dependencies.py\", line 114, in inject\r\n",
      "    kwargs[\"db\"] = provide_database_interface()\r\n",
      "  File \"/Users/evanhofmeister/opt/anaconda3/lib/python3.9/site-packages/prefect/server/database/dependencies.py\", line 81, in provide_database_interface\r\n",
      "    orm = AioSqliteORMConfiguration()\r\n",
      "  File \"/Users/evanhofmeister/opt/anaconda3/lib/python3.9/site-packages/prefect/server/database/orm_models.py\", line 1400, in __init__\r\n",
      "    self._create_orm_models(\r\n",
      "  File \"/Users/evanhofmeister/opt/anaconda3/lib/python3.9/site-packages/prefect/server/database/orm_models.py\", line 1550, in _create_orm_models\r\n",
      "    class Variable(variable_mixin, self.Base):\r\n",
      "  File \"/Users/evanhofmeister/opt/anaconda3/lib/python3.9/site-packages/sqlalchemy/orm/decl_api.py\", line 193, in __init__\r\n",
      "    _as_declarative(reg, cls, dict_)\r\n",
      "  File \"/Users/evanhofmeister/opt/anaconda3/lib/python3.9/site-packages/sqlalchemy/orm/decl_base.py\", line 247, in _as_declarative\r\n",
      "    return _MapperConfig.setup_mapping(registry, cls, dict_, None, {})\r\n",
      "  File \"/Users/evanhofmeister/opt/anaconda3/lib/python3.9/site-packages/sqlalchemy/orm/decl_base.py\", line 328, in setup_mapping\r\n",
      "    return _ClassScanMapperConfig(\r\n",
      "  File \"/Users/evanhofmeister/opt/anaconda3/lib/python3.9/site-packages/sqlalchemy/orm/decl_base.py\", line 563, in __init__\r\n",
      "    self._scan_attributes()\r\n",
      "  File \"/Users/evanhofmeister/opt/anaconda3/lib/python3.9/site-packages/sqlalchemy/orm/decl_base.py\", line 785, in _scan_attributes\r\n",
      "    locally_collected_columns = self._produce_column_copies(\r\n",
      "  File \"/Users/evanhofmeister/opt/anaconda3/lib/python3.9/site-packages/sqlalchemy/orm/decl_base.py\", line 1388, in _produce_column_copies\r\n",
      "    collected_annotation = self._collect_annotation(\r\n",
      "  File \"/Users/evanhofmeister/opt/anaconda3/lib/python3.9/site-packages/sqlalchemy/orm/decl_base.py\", line 1277, in _collect_annotation\r\n",
      "    extracted = _extract_mapped_subtype(\r\n",
      "  File \"/Users/evanhofmeister/opt/anaconda3/lib/python3.9/site-packages/sqlalchemy/orm/util.py\", line 2356, in _extract_mapped_subtype\r\n",
      "    raise sa_exc.ArgumentError(\r\n",
      "sqlalchemy.exc.ArgumentError: Type annotation for \"Variable.name\" can't be correctly interpreted for Annotated Declarative Table form.  ORM annotations should normally make use of the ``Mapped[]`` generic type, or other ORM-compatible generic type, as a container for the actual type, which indicates the intent that the attribute is mapped. Class variables that are not intended to be mapped by the ORM should use ClassVar[].  To allow Annotated Declarative to disregard legacy annotations which don't use Mapped[] to pass, set \"__allow_unmapped__ = True\" on the class or a superclass this class. (Background on this error at: \u001B[94mhttps://sqlalche.me/e/20/zlpr)\u001B[0m\r\n",
      "12:33:56.363 | \u001B[31mERROR\u001B[0m   | prefect.server - CancellationCleanup service failed!\r\n",
      "Traceback (most recent call last):\r\n",
      "  File \"/Users/evanhofmeister/opt/anaconda3/lib/python3.9/site-packages/prefect/server/api/server.py\", line 494, in on_service_exit\r\n",
      "    task.result()\r\n",
      "  File \"/Users/evanhofmeister/opt/anaconda3/lib/python3.9/site-packages/prefect/server/services/loop_service.py\", line 70, in start\r\n",
      "    await self._on_start()\r\n",
      "  File \"/Users/evanhofmeister/opt/anaconda3/lib/python3.9/site-packages/prefect/server/database/dependencies.py\", line 118, in async_wrapper\r\n",
      "    inject(kwargs)\r\n",
      "  File \"/Users/evanhofmeister/opt/anaconda3/lib/python3.9/site-packages/prefect/server/database/dependencies.py\", line 114, in inject\r\n",
      "    kwargs[\"db\"] = provide_database_interface()\r\n",
      "  File \"/Users/evanhofmeister/opt/anaconda3/lib/python3.9/site-packages/prefect/server/database/dependencies.py\", line 81, in provide_database_interface\r\n",
      "    orm = AioSqliteORMConfiguration()\r\n",
      "  File \"/Users/evanhofmeister/opt/anaconda3/lib/python3.9/site-packages/prefect/server/database/orm_models.py\", line 1400, in __init__\r\n",
      "    self._create_orm_models(\r\n",
      "  File \"/Users/evanhofmeister/opt/anaconda3/lib/python3.9/site-packages/prefect/server/database/orm_models.py\", line 1550, in _create_orm_models\r\n",
      "    class Variable(variable_mixin, self.Base):\r\n",
      "  File \"/Users/evanhofmeister/opt/anaconda3/lib/python3.9/site-packages/sqlalchemy/orm/decl_api.py\", line 193, in __init__\r\n",
      "    _as_declarative(reg, cls, dict_)\r\n",
      "  File \"/Users/evanhofmeister/opt/anaconda3/lib/python3.9/site-packages/sqlalchemy/orm/decl_base.py\", line 247, in _as_declarative\r\n",
      "    return _MapperConfig.setup_mapping(registry, cls, dict_, None, {})\r\n",
      "  File \"/Users/evanhofmeister/opt/anaconda3/lib/python3.9/site-packages/sqlalchemy/orm/decl_base.py\", line 328, in setup_mapping\r\n",
      "    return _ClassScanMapperConfig(\r\n",
      "  File \"/Users/evanhofmeister/opt/anaconda3/lib/python3.9/site-packages/sqlalchemy/orm/decl_base.py\", line 563, in __init__\r\n",
      "    self._scan_attributes()\r\n",
      "  File \"/Users/evanhofmeister/opt/anaconda3/lib/python3.9/site-packages/sqlalchemy/orm/decl_base.py\", line 785, in _scan_attributes\r\n",
      "    locally_collected_columns = self._produce_column_copies(\r\n",
      "  File \"/Users/evanhofmeister/opt/anaconda3/lib/python3.9/site-packages/sqlalchemy/orm/decl_base.py\", line 1388, in _produce_column_copies\r\n",
      "    collected_annotation = self._collect_annotation(\r\n",
      "  File \"/Users/evanhofmeister/opt/anaconda3/lib/python3.9/site-packages/sqlalchemy/orm/decl_base.py\", line 1277, in _collect_annotation\r\n",
      "    extracted = _extract_mapped_subtype(\r\n",
      "  File \"/Users/evanhofmeister/opt/anaconda3/lib/python3.9/site-packages/sqlalchemy/orm/util.py\", line 2356, in _extract_mapped_subtype\r\n",
      "    raise sa_exc.ArgumentError(\r\n",
      "sqlalchemy.exc.ArgumentError: Type annotation for \"Variable.name\" can't be correctly interpreted for Annotated Declarative Table form.  ORM annotations should normally make use of the ``Mapped[]`` generic type, or other ORM-compatible generic type, as a container for the actual type, which indicates the intent that the attribute is mapped. Class variables that are not intended to be mapped by the ORM should use ClassVar[].  To allow Annotated Declarative to disregard legacy annotations which don't use Mapped[] to pass, set \"__allow_unmapped__ = True\" on the class or a superclass this class. (Background on this error at: \u001B[94mhttps://sqlalche.me/e/20/zlpr)\u001B[0m\r\n",
      "12:33:56.364 | \u001B[31mERROR\u001B[0m   | prefect.server - Telemetry service failed!\r\n",
      "Traceback (most recent call last):\r\n",
      "  File \"/Users/evanhofmeister/opt/anaconda3/lib/python3.9/site-packages/prefect/server/api/server.py\", line 494, in on_service_exit\r\n",
      "    task.result()\r\n",
      "  File \"/Users/evanhofmeister/opt/anaconda3/lib/python3.9/site-packages/prefect/server/services/loop_service.py\", line 70, in start\r\n",
      "    await self._on_start()\r\n",
      "  File \"/Users/evanhofmeister/opt/anaconda3/lib/python3.9/site-packages/prefect/server/database/dependencies.py\", line 118, in async_wrapper\r\n",
      "    inject(kwargs)\r\n",
      "  File \"/Users/evanhofmeister/opt/anaconda3/lib/python3.9/site-packages/prefect/server/database/dependencies.py\", line 114, in inject\r\n",
      "    kwargs[\"db\"] = provide_database_interface()\r\n",
      "  File \"/Users/evanhofmeister/opt/anaconda3/lib/python3.9/site-packages/prefect/server/database/dependencies.py\", line 81, in provide_database_interface\r\n",
      "    orm = AioSqliteORMConfiguration()\r\n",
      "  File \"/Users/evanhofmeister/opt/anaconda3/lib/python3.9/site-packages/prefect/server/database/orm_models.py\", line 1400, in __init__\r\n",
      "    self._create_orm_models(\r\n",
      "  File \"/Users/evanhofmeister/opt/anaconda3/lib/python3.9/site-packages/prefect/server/database/orm_models.py\", line 1550, in _create_orm_models\r\n",
      "    class Variable(variable_mixin, self.Base):\r\n",
      "  File \"/Users/evanhofmeister/opt/anaconda3/lib/python3.9/site-packages/sqlalchemy/orm/decl_api.py\", line 193, in __init__\r\n",
      "    _as_declarative(reg, cls, dict_)\r\n",
      "  File \"/Users/evanhofmeister/opt/anaconda3/lib/python3.9/site-packages/sqlalchemy/orm/decl_base.py\", line 247, in _as_declarative\r\n",
      "    return _MapperConfig.setup_mapping(registry, cls, dict_, None, {})\r\n",
      "  File \"/Users/evanhofmeister/opt/anaconda3/lib/python3.9/site-packages/sqlalchemy/orm/decl_base.py\", line 328, in setup_mapping\r\n",
      "    return _ClassScanMapperConfig(\r\n",
      "  File \"/Users/evanhofmeister/opt/anaconda3/lib/python3.9/site-packages/sqlalchemy/orm/decl_base.py\", line 563, in __init__\r\n",
      "    self._scan_attributes()\r\n",
      "  File \"/Users/evanhofmeister/opt/anaconda3/lib/python3.9/site-packages/sqlalchemy/orm/decl_base.py\", line 785, in _scan_attributes\r\n",
      "    locally_collected_columns = self._produce_column_copies(\r\n",
      "  File \"/Users/evanhofmeister/opt/anaconda3/lib/python3.9/site-packages/sqlalchemy/orm/decl_base.py\", line 1388, in _produce_column_copies\r\n",
      "    collected_annotation = self._collect_annotation(\r\n",
      "  File \"/Users/evanhofmeister/opt/anaconda3/lib/python3.9/site-packages/sqlalchemy/orm/decl_base.py\", line 1277, in _collect_annotation\r\n",
      "    extracted = _extract_mapped_subtype(\r\n",
      "  File \"/Users/evanhofmeister/opt/anaconda3/lib/python3.9/site-packages/sqlalchemy/orm/util.py\", line 2356, in _extract_mapped_subtype\r\n",
      "    raise sa_exc.ArgumentError(\r\n",
      "sqlalchemy.exc.ArgumentError: Type annotation for \"Variable.name\" can't be correctly interpreted for Annotated Declarative Table form.  ORM annotations should normally make use of the ``Mapped[]`` generic type, or other ORM-compatible generic type, as a container for the actual type, which indicates the intent that the attribute is mapped. Class variables that are not intended to be mapped by the ORM should use ClassVar[].  To allow Annotated Declarative to disregard legacy annotations which don't use Mapped[] to pass, set \"__allow_unmapped__ = True\" on the class or a superclass this class. (Background on this error at: \u001B[94mhttps://sqlalche.me/e/20/zlpr)\u001B[0m\r\n",
      "12:33:56.365 | \u001B[31mERROR\u001B[0m   | prefect.server - FlowRunNotifications service failed!\r\n",
      "Traceback (most recent call last):\r\n",
      "  File \"/Users/evanhofmeister/opt/anaconda3/lib/python3.9/site-packages/prefect/server/api/server.py\", line 494, in on_service_exit\r\n",
      "    task.result()\r\n",
      "  File \"/Users/evanhofmeister/opt/anaconda3/lib/python3.9/site-packages/prefect/server/services/loop_service.py\", line 70, in start\r\n",
      "    await self._on_start()\r\n",
      "  File \"/Users/evanhofmeister/opt/anaconda3/lib/python3.9/site-packages/prefect/server/database/dependencies.py\", line 118, in async_wrapper\r\n",
      "    inject(kwargs)\r\n",
      "  File \"/Users/evanhofmeister/opt/anaconda3/lib/python3.9/site-packages/prefect/server/database/dependencies.py\", line 114, in inject\r\n",
      "    kwargs[\"db\"] = provide_database_interface()\r\n",
      "  File \"/Users/evanhofmeister/opt/anaconda3/lib/python3.9/site-packages/prefect/server/database/dependencies.py\", line 81, in provide_database_interface\r\n",
      "    orm = AioSqliteORMConfiguration()\r\n",
      "  File \"/Users/evanhofmeister/opt/anaconda3/lib/python3.9/site-packages/prefect/server/database/orm_models.py\", line 1400, in __init__\r\n",
      "    self._create_orm_models(\r\n",
      "  File \"/Users/evanhofmeister/opt/anaconda3/lib/python3.9/site-packages/prefect/server/database/orm_models.py\", line 1550, in _create_orm_models\r\n",
      "    class Variable(variable_mixin, self.Base):\r\n",
      "  File \"/Users/evanhofmeister/opt/anaconda3/lib/python3.9/site-packages/sqlalchemy/orm/decl_api.py\", line 193, in __init__\r\n",
      "    _as_declarative(reg, cls, dict_)\r\n",
      "  File \"/Users/evanhofmeister/opt/anaconda3/lib/python3.9/site-packages/sqlalchemy/orm/decl_base.py\", line 247, in _as_declarative\r\n",
      "    return _MapperConfig.setup_mapping(registry, cls, dict_, None, {})\r\n",
      "  File \"/Users/evanhofmeister/opt/anaconda3/lib/python3.9/site-packages/sqlalchemy/orm/decl_base.py\", line 328, in setup_mapping\r\n",
      "    return _ClassScanMapperConfig(\r\n",
      "  File \"/Users/evanhofmeister/opt/anaconda3/lib/python3.9/site-packages/sqlalchemy/orm/decl_base.py\", line 563, in __init__\r\n",
      "    self._scan_attributes()\r\n",
      "  File \"/Users/evanhofmeister/opt/anaconda3/lib/python3.9/site-packages/sqlalchemy/orm/decl_base.py\", line 785, in _scan_attributes\r\n",
      "    locally_collected_columns = self._produce_column_copies(\r\n",
      "  File \"/Users/evanhofmeister/opt/anaconda3/lib/python3.9/site-packages/sqlalchemy/orm/decl_base.py\", line 1388, in _produce_column_copies\r\n",
      "    collected_annotation = self._collect_annotation(\r\n",
      "  File \"/Users/evanhofmeister/opt/anaconda3/lib/python3.9/site-packages/sqlalchemy/orm/decl_base.py\", line 1277, in _collect_annotation\r\n",
      "    extracted = _extract_mapped_subtype(\r\n",
      "  File \"/Users/evanhofmeister/opt/anaconda3/lib/python3.9/site-packages/sqlalchemy/orm/util.py\", line 2356, in _extract_mapped_subtype\r\n",
      "    raise sa_exc.ArgumentError(\r\n",
      "sqlalchemy.exc.ArgumentError: Type annotation for \"Variable.name\" can't be correctly interpreted for Annotated Declarative Table form.  ORM annotations should normally make use of the ``Mapped[]`` generic type, or other ORM-compatible generic type, as a container for the actual type, which indicates the intent that the attribute is mapped. Class variables that are not intended to be mapped by the ORM should use ClassVar[].  To allow Annotated Declarative to disregard legacy annotations which don't use Mapped[] to pass, set \"__allow_unmapped__ = True\" on the class or a superclass this class. (Background on this error at: \u001B[94mhttps://sqlalche.me/e/20/zlpr)\u001B[0m\r\n",
      "12:34:37.678 | \u001B[31mERROR\u001B[0m   | prefect.server - Encountered exception in request:\r\n",
      "Traceback (most recent call last):\r\n",
      "  File \"/Users/evanhofmeister/opt/anaconda3/lib/python3.9/site-packages/starlette/middleware/errors.py\", line 162, in __call__\r\n",
      "    await self.app(scope, receive, _send)\r\n",
      "  File \"/Users/evanhofmeister/opt/anaconda3/lib/python3.9/site-packages/starlette/middleware/gzip.py\", line 24, in __call__\r\n",
      "    await responder(scope, receive, send)\r\n",
      "  File \"/Users/evanhofmeister/opt/anaconda3/lib/python3.9/site-packages/starlette/middleware/gzip.py\", line 44, in __call__\r\n",
      "    await self.app(scope, receive, self.send_with_gzip)\r\n",
      "  File \"/Users/evanhofmeister/opt/anaconda3/lib/python3.9/site-packages/starlette/middleware/exceptions.py\", line 62, in __call__\r\n",
      "    await wrap_app_handling_exceptions(self.app, conn)(scope, receive, send)\r\n",
      "  File \"/Users/evanhofmeister/opt/anaconda3/lib/python3.9/site-packages/starlette/_exception_handler.py\", line 57, in wrapped_app\r\n",
      "    raise exc\r\n",
      "  File \"/Users/evanhofmeister/opt/anaconda3/lib/python3.9/site-packages/starlette/_exception_handler.py\", line 46, in wrapped_app\r\n",
      "    await app(scope, receive, sender)\r\n",
      "  File \"/Users/evanhofmeister/opt/anaconda3/lib/python3.9/site-packages/fastapi/middleware/asyncexitstack.py\", line 21, in __call__\r\n",
      "    raise e\r\n",
      "  File \"/Users/evanhofmeister/opt/anaconda3/lib/python3.9/site-packages/fastapi/middleware/asyncexitstack.py\", line 18, in __call__\r\n",
      "    await self.app(scope, receive, send)\r\n",
      "  File \"/Users/evanhofmeister/opt/anaconda3/lib/python3.9/site-packages/starlette/routing.py\", line 727, in __call__\r\n",
      "    await route.handle(scope, receive, send)\r\n",
      "  File \"/Users/evanhofmeister/opt/anaconda3/lib/python3.9/site-packages/starlette/routing.py\", line 285, in handle\r\n",
      "    await self.app(scope, receive, send)\r\n",
      "  File \"/Users/evanhofmeister/opt/anaconda3/lib/python3.9/site-packages/starlette/routing.py\", line 74, in app\r\n",
      "    await wrap_app_handling_exceptions(app, request)(scope, receive, send)\r\n",
      "  File \"/Users/evanhofmeister/opt/anaconda3/lib/python3.9/site-packages/starlette/_exception_handler.py\", line 57, in wrapped_app\r\n",
      "    raise exc\r\n",
      "  File \"/Users/evanhofmeister/opt/anaconda3/lib/python3.9/site-packages/starlette/_exception_handler.py\", line 46, in wrapped_app\r\n",
      "    await app(scope, receive, sender)\r\n",
      "  File \"/Users/evanhofmeister/opt/anaconda3/lib/python3.9/site-packages/starlette/routing.py\", line 69, in app\r\n",
      "    response = await func(request)\r\n",
      "  File \"/Users/evanhofmeister/opt/anaconda3/lib/python3.9/site-packages/prefect/server/utilities/server.py\", line 103, in handle_response_scoped_depends\r\n",
      "    response = await default_handler(request)\r\n",
      "  File \"/Users/evanhofmeister/opt/anaconda3/lib/python3.9/site-packages/fastapi/routing.py\", line 227, in app\r\n",
      "    solved_result = await solve_dependencies(\r\n",
      "  File \"/Users/evanhofmeister/opt/anaconda3/lib/python3.9/site-packages/fastapi/dependencies/utils.py\", line 624, in solve_dependencies\r\n",
      "    solved = await run_in_threadpool(call, **sub_values)\r\n",
      "  File \"/Users/evanhofmeister/opt/anaconda3/lib/python3.9/site-packages/starlette/concurrency.py\", line 41, in run_in_threadpool\r\n",
      "    return await anyio.to_thread.run_sync(func, *args)\r\n",
      "  File \"/Users/evanhofmeister/opt/anaconda3/lib/python3.9/site-packages/anyio/to_thread.py\", line 28, in run_sync\r\n",
      "    return await get_asynclib().run_sync_in_worker_thread(func, *args, cancellable=cancellable,\r\n",
      "  File \"/Users/evanhofmeister/opt/anaconda3/lib/python3.9/site-packages/anyio/_backends/_asyncio.py\", line 818, in run_sync_in_worker_thread\r\n",
      "    return await future\r\n",
      "  File \"/Users/evanhofmeister/opt/anaconda3/lib/python3.9/site-packages/anyio/_backends/_asyncio.py\", line 754, in run\r\n",
      "    result = context.run(func, *args)\r\n",
      "  File \"/Users/evanhofmeister/opt/anaconda3/lib/python3.9/site-packages/prefect/server/database/dependencies.py\", line 81, in provide_database_interface\r\n",
      "    orm = AioSqliteORMConfiguration()\r\n",
      "  File \"/Users/evanhofmeister/opt/anaconda3/lib/python3.9/site-packages/prefect/server/database/orm_models.py\", line 1400, in __init__\r\n",
      "    self._create_orm_models(\r\n",
      "  File \"/Users/evanhofmeister/opt/anaconda3/lib/python3.9/site-packages/prefect/server/database/orm_models.py\", line 1550, in _create_orm_models\r\n",
      "    class Variable(variable_mixin, self.Base):\r\n",
      "  File \"/Users/evanhofmeister/opt/anaconda3/lib/python3.9/site-packages/sqlalchemy/orm/decl_api.py\", line 193, in __init__\r\n",
      "    _as_declarative(reg, cls, dict_)\r\n",
      "  File \"/Users/evanhofmeister/opt/anaconda3/lib/python3.9/site-packages/sqlalchemy/orm/decl_base.py\", line 247, in _as_declarative\r\n",
      "    return _MapperConfig.setup_mapping(registry, cls, dict_, None, {})\r\n",
      "  File \"/Users/evanhofmeister/opt/anaconda3/lib/python3.9/site-packages/sqlalchemy/orm/decl_base.py\", line 328, in setup_mapping\r\n",
      "    return _ClassScanMapperConfig(\r\n",
      "  File \"/Users/evanhofmeister/opt/anaconda3/lib/python3.9/site-packages/sqlalchemy/orm/decl_base.py\", line 563, in __init__\r\n",
      "    self._scan_attributes()\r\n",
      "  File \"/Users/evanhofmeister/opt/anaconda3/lib/python3.9/site-packages/sqlalchemy/orm/decl_base.py\", line 785, in _scan_attributes\r\n",
      "    locally_collected_columns = self._produce_column_copies(\r\n",
      "  File \"/Users/evanhofmeister/opt/anaconda3/lib/python3.9/site-packages/sqlalchemy/orm/decl_base.py\", line 1388, in _produce_column_copies\r\n",
      "    collected_annotation = self._collect_annotation(\r\n",
      "  File \"/Users/evanhofmeister/opt/anaconda3/lib/python3.9/site-packages/sqlalchemy/orm/decl_base.py\", line 1277, in _collect_annotation\r\n",
      "    extracted = _extract_mapped_subtype(\r\n",
      "  File \"/Users/evanhofmeister/opt/anaconda3/lib/python3.9/site-packages/sqlalchemy/orm/util.py\", line 2356, in _extract_mapped_subtype\r\n",
      "    raise sa_exc.ArgumentError(\r\n",
      "sqlalchemy.exc.ArgumentError: Type annotation for \"Variable.name\" can't be correctly interpreted for Annotated Declarative Table form.  ORM annotations should normally make use of the ``Mapped[]`` generic type, or other ORM-compatible generic type, as a container for the actual type, which indicates the intent that the attribute is mapped. Class variables that are not intended to be mapped by the ORM should use ClassVar[].  To allow Annotated Declarative to disregard legacy annotations which don't use Mapped[] to pass, set \"__allow_unmapped__ = True\" on the class or a superclass this class. (Background on this error at: \u001B[94mhttps://sqlalche.me/e/20/zlpr)\u001B[0m\r\n",
      "Exception in ASGI application\r\n",
      "Traceback (most recent call last):\r\n",
      "  File \"/Users/evanhofmeister/opt/anaconda3/lib/python3.9/site-packages/uvicorn/protocols/http/h11_impl.py\", line 429, in run_asgi\r\n",
      "    result = await app(  # type: ignore[func-returns-value]\r\n",
      "  File \"/Users/evanhofmeister/opt/anaconda3/lib/python3.9/site-packages/uvicorn/middleware/proxy_headers.py\", line 78, in __call__\r\n",
      "    return await self.app(scope, receive, send)\r\n",
      "  File \"/Users/evanhofmeister/opt/anaconda3/lib/python3.9/site-packages/uvicorn/middleware/message_logger.py\", line 86, in __call__\r\n",
      "    raise exc from None\r\n",
      "  File \"/Users/evanhofmeister/opt/anaconda3/lib/python3.9/site-packages/uvicorn/middleware/message_logger.py\", line 82, in __call__\r\n",
      "    await self.app(scope, inner_receive, inner_send)\r\n",
      "  File \"/Users/evanhofmeister/opt/anaconda3/lib/python3.9/site-packages/fastapi/applications.py\", line 276, in __call__\r\n",
      "    await super().__call__(scope, receive, send)\r\n",
      "  File \"/Users/evanhofmeister/opt/anaconda3/lib/python3.9/site-packages/starlette/applications.py\", line 122, in __call__\r\n",
      "    await self.middleware_stack(scope, receive, send)\r\n",
      "  File \"/Users/evanhofmeister/opt/anaconda3/lib/python3.9/site-packages/starlette/middleware/errors.py\", line 184, in __call__\r\n",
      "    raise exc\r\n",
      "  File \"/Users/evanhofmeister/opt/anaconda3/lib/python3.9/site-packages/starlette/middleware/errors.py\", line 162, in __call__\r\n",
      "    await self.app(scope, receive, _send)\r\n",
      "  File \"/Users/evanhofmeister/opt/anaconda3/lib/python3.9/site-packages/prefect/server/api/server.py\", line 117, in __call__\r\n",
      "    await self.app(scope, receive, send)\r\n",
      "  File \"/Users/evanhofmeister/opt/anaconda3/lib/python3.9/site-packages/starlette/middleware/cors.py\", line 91, in __call__\r\n",
      "    await self.simple_response(scope, receive, send, request_headers=headers)\r\n",
      "  File \"/Users/evanhofmeister/opt/anaconda3/lib/python3.9/site-packages/starlette/middleware/cors.py\", line 146, in simple_response\r\n",
      "    await self.app(scope, receive, send)\r\n",
      "  File \"/Users/evanhofmeister/opt/anaconda3/lib/python3.9/site-packages/starlette/middleware/exceptions.py\", line 62, in __call__\r\n",
      "    await wrap_app_handling_exceptions(self.app, conn)(scope, receive, send)\r\n",
      "  File \"/Users/evanhofmeister/opt/anaconda3/lib/python3.9/site-packages/starlette/_exception_handler.py\", line 57, in wrapped_app\r\n",
      "    raise exc\r\n",
      "  File \"/Users/evanhofmeister/opt/anaconda3/lib/python3.9/site-packages/starlette/_exception_handler.py\", line 46, in wrapped_app\r\n",
      "    await app(scope, receive, sender)\r\n",
      "  File \"/Users/evanhofmeister/opt/anaconda3/lib/python3.9/site-packages/fastapi/middleware/asyncexitstack.py\", line 21, in __call__\r\n",
      "    raise e\r\n",
      "  File \"/Users/evanhofmeister/opt/anaconda3/lib/python3.9/site-packages/fastapi/middleware/asyncexitstack.py\", line 18, in __call__\r\n",
      "    await self.app(scope, receive, send)\r\n",
      "  File \"/Users/evanhofmeister/opt/anaconda3/lib/python3.9/site-packages/starlette/routing.py\", line 727, in __call__\r\n",
      "    await route.handle(scope, receive, send)\r\n",
      "  File \"/Users/evanhofmeister/opt/anaconda3/lib/python3.9/site-packages/starlette/routing.py\", line 452, in handle\r\n",
      "    await self.app(scope, receive, send)\r\n",
      "  File \"/Users/evanhofmeister/opt/anaconda3/lib/python3.9/site-packages/fastapi/applications.py\", line 276, in __call__\r\n",
      "    await super().__call__(scope, receive, send)\r\n",
      "  File \"/Users/evanhofmeister/opt/anaconda3/lib/python3.9/site-packages/starlette/applications.py\", line 122, in __call__\r\n",
      "    await self.middleware_stack(scope, receive, send)\r\n",
      "  File \"/Users/evanhofmeister/opt/anaconda3/lib/python3.9/site-packages/starlette/middleware/errors.py\", line 184, in __call__\r\n",
      "    raise exc\r\n",
      "  File \"/Users/evanhofmeister/opt/anaconda3/lib/python3.9/site-packages/starlette/middleware/errors.py\", line 162, in __call__\r\n",
      "    await self.app(scope, receive, _send)\r\n",
      "  File \"/Users/evanhofmeister/opt/anaconda3/lib/python3.9/site-packages/starlette/middleware/gzip.py\", line 24, in __call__\r\n",
      "    await responder(scope, receive, send)\r\n",
      "  File \"/Users/evanhofmeister/opt/anaconda3/lib/python3.9/site-packages/starlette/middleware/gzip.py\", line 44, in __call__\r\n",
      "    await self.app(scope, receive, self.send_with_gzip)\r\n",
      "  File \"/Users/evanhofmeister/opt/anaconda3/lib/python3.9/site-packages/starlette/middleware/exceptions.py\", line 62, in __call__\r\n",
      "    await wrap_app_handling_exceptions(self.app, conn)(scope, receive, send)\r\n",
      "  File \"/Users/evanhofmeister/opt/anaconda3/lib/python3.9/site-packages/starlette/_exception_handler.py\", line 57, in wrapped_app\r\n",
      "    raise exc\r\n",
      "  File \"/Users/evanhofmeister/opt/anaconda3/lib/python3.9/site-packages/starlette/_exception_handler.py\", line 46, in wrapped_app\r\n",
      "    await app(scope, receive, sender)\r\n",
      "  File \"/Users/evanhofmeister/opt/anaconda3/lib/python3.9/site-packages/fastapi/middleware/asyncexitstack.py\", line 21, in __call__\r\n",
      "    raise e\r\n",
      "  File \"/Users/evanhofmeister/opt/anaconda3/lib/python3.9/site-packages/fastapi/middleware/asyncexitstack.py\", line 18, in __call__\r\n",
      "    await self.app(scope, receive, send)\r\n",
      "  File \"/Users/evanhofmeister/opt/anaconda3/lib/python3.9/site-packages/starlette/routing.py\", line 727, in __call__\r\n",
      "    await route.handle(scope, receive, send)\r\n",
      "  File \"/Users/evanhofmeister/opt/anaconda3/lib/python3.9/site-packages/starlette/routing.py\", line 285, in handle\r\n",
      "    await self.app(scope, receive, send)\r\n",
      "  File \"/Users/evanhofmeister/opt/anaconda3/lib/python3.9/site-packages/starlette/routing.py\", line 74, in app\r\n",
      "    await wrap_app_handling_exceptions(app, request)(scope, receive, send)\r\n",
      "  File \"/Users/evanhofmeister/opt/anaconda3/lib/python3.9/site-packages/starlette/_exception_handler.py\", line 57, in wrapped_app\r\n",
      "    raise exc\r\n",
      "  File \"/Users/evanhofmeister/opt/anaconda3/lib/python3.9/site-packages/starlette/_exception_handler.py\", line 46, in wrapped_app\r\n",
      "    await app(scope, receive, sender)\r\n",
      "  File \"/Users/evanhofmeister/opt/anaconda3/lib/python3.9/site-packages/starlette/routing.py\", line 69, in app\r\n",
      "    response = await func(request)\r\n",
      "  File \"/Users/evanhofmeister/opt/anaconda3/lib/python3.9/site-packages/prefect/server/utilities/server.py\", line 103, in handle_response_scoped_depends\r\n",
      "    response = await default_handler(request)\r\n",
      "  File \"/Users/evanhofmeister/opt/anaconda3/lib/python3.9/site-packages/fastapi/routing.py\", line 227, in app\r\n",
      "    solved_result = await solve_dependencies(\r\n",
      "  File \"/Users/evanhofmeister/opt/anaconda3/lib/python3.9/site-packages/fastapi/dependencies/utils.py\", line 624, in solve_dependencies\r\n",
      "    solved = await run_in_threadpool(call, **sub_values)\r\n",
      "  File \"/Users/evanhofmeister/opt/anaconda3/lib/python3.9/site-packages/starlette/concurrency.py\", line 41, in run_in_threadpool\r\n",
      "    return await anyio.to_thread.run_sync(func, *args)\r\n",
      "  File \"/Users/evanhofmeister/opt/anaconda3/lib/python3.9/site-packages/anyio/to_thread.py\", line 28, in run_sync\r\n",
      "    return await get_asynclib().run_sync_in_worker_thread(func, *args, cancellable=cancellable,\r\n",
      "  File \"/Users/evanhofmeister/opt/anaconda3/lib/python3.9/site-packages/anyio/_backends/_asyncio.py\", line 818, in run_sync_in_worker_thread\r\n",
      "    return await future\r\n",
      "  File \"/Users/evanhofmeister/opt/anaconda3/lib/python3.9/site-packages/anyio/_backends/_asyncio.py\", line 754, in run\r\n",
      "    result = context.run(func, *args)\r\n",
      "  File \"/Users/evanhofmeister/opt/anaconda3/lib/python3.9/site-packages/prefect/server/database/dependencies.py\", line 81, in provide_database_interface\r\n",
      "    orm = AioSqliteORMConfiguration()\r\n",
      "  File \"/Users/evanhofmeister/opt/anaconda3/lib/python3.9/site-packages/prefect/server/database/orm_models.py\", line 1400, in __init__\r\n",
      "    self._create_orm_models(\r\n",
      "  File \"/Users/evanhofmeister/opt/anaconda3/lib/python3.9/site-packages/prefect/server/database/orm_models.py\", line 1550, in _create_orm_models\r\n",
      "    class Variable(variable_mixin, self.Base):\r\n",
      "  File \"/Users/evanhofmeister/opt/anaconda3/lib/python3.9/site-packages/sqlalchemy/orm/decl_api.py\", line 193, in __init__\r\n",
      "    _as_declarative(reg, cls, dict_)\r\n",
      "  File \"/Users/evanhofmeister/opt/anaconda3/lib/python3.9/site-packages/sqlalchemy/orm/decl_base.py\", line 247, in _as_declarative\r\n",
      "    return _MapperConfig.setup_mapping(registry, cls, dict_, None, {})\r\n",
      "  File \"/Users/evanhofmeister/opt/anaconda3/lib/python3.9/site-packages/sqlalchemy/orm/decl_base.py\", line 328, in setup_mapping\r\n",
      "    return _ClassScanMapperConfig(\r\n",
      "  File \"/Users/evanhofmeister/opt/anaconda3/lib/python3.9/site-packages/sqlalchemy/orm/decl_base.py\", line 563, in __init__\r\n",
      "    self._scan_attributes()\r\n",
      "  File \"/Users/evanhofmeister/opt/anaconda3/lib/python3.9/site-packages/sqlalchemy/orm/decl_base.py\", line 785, in _scan_attributes\r\n",
      "    locally_collected_columns = self._produce_column_copies(\r\n",
      "  File \"/Users/evanhofmeister/opt/anaconda3/lib/python3.9/site-packages/sqlalchemy/orm/decl_base.py\", line 1388, in _produce_column_copies\r\n",
      "    collected_annotation = self._collect_annotation(\r\n",
      "  File \"/Users/evanhofmeister/opt/anaconda3/lib/python3.9/site-packages/sqlalchemy/orm/decl_base.py\", line 1277, in _collect_annotation\r\n",
      "    extracted = _extract_mapped_subtype(\r\n",
      "  File \"/Users/evanhofmeister/opt/anaconda3/lib/python3.9/site-packages/sqlalchemy/orm/util.py\", line 2356, in _extract_mapped_subtype\r\n",
      "    raise sa_exc.ArgumentError(\r\n",
      "sqlalchemy.exc.ArgumentError: Type annotation for \"Variable.name\" can't be correctly interpreted for Annotated Declarative Table form.  ORM annotations should normally make use of the ``Mapped[]`` generic type, or other ORM-compatible generic type, as a container for the actual type, which indicates the intent that the attribute is mapped. Class variables that are not intended to be mapped by the ORM should use ClassVar[].  To allow Annotated Declarative to disregard legacy annotations which don't use Mapped[] to pass, set \"__allow_unmapped__ = True\" on the class or a superclass this class. (Background on this error at: https://sqlalche.me/e/20/zlpr)\r\n",
      "12:34:37.757 | \u001B[31mERROR\u001B[0m   | prefect.server - Encountered exception in request:\r\n",
      "Traceback (most recent call last):\r\n",
      "  File \"/Users/evanhofmeister/opt/anaconda3/lib/python3.9/site-packages/starlette/middleware/errors.py\", line 162, in __call__\r\n",
      "    await self.app(scope, receive, _send)\r\n",
      "  File \"/Users/evanhofmeister/opt/anaconda3/lib/python3.9/site-packages/starlette/middleware/gzip.py\", line 24, in __call__\r\n",
      "    await responder(scope, receive, send)\r\n",
      "  File \"/Users/evanhofmeister/opt/anaconda3/lib/python3.9/site-packages/starlette/middleware/gzip.py\", line 44, in __call__\r\n",
      "    await self.app(scope, receive, self.send_with_gzip)\r\n",
      "  File \"/Users/evanhofmeister/opt/anaconda3/lib/python3.9/site-packages/starlette/middleware/exceptions.py\", line 62, in __call__\r\n",
      "    await wrap_app_handling_exceptions(self.app, conn)(scope, receive, send)\r\n",
      "  File \"/Users/evanhofmeister/opt/anaconda3/lib/python3.9/site-packages/starlette/_exception_handler.py\", line 57, in wrapped_app\r\n",
      "    raise exc\r\n",
      "  File \"/Users/evanhofmeister/opt/anaconda3/lib/python3.9/site-packages/starlette/_exception_handler.py\", line 46, in wrapped_app\r\n",
      "    await app(scope, receive, sender)\r\n",
      "  File \"/Users/evanhofmeister/opt/anaconda3/lib/python3.9/site-packages/fastapi/middleware/asyncexitstack.py\", line 21, in __call__\r\n",
      "    raise e\r\n",
      "  File \"/Users/evanhofmeister/opt/anaconda3/lib/python3.9/site-packages/fastapi/middleware/asyncexitstack.py\", line 18, in __call__\r\n",
      "    await self.app(scope, receive, send)\r\n",
      "  File \"/Users/evanhofmeister/opt/anaconda3/lib/python3.9/site-packages/starlette/routing.py\", line 727, in __call__\r\n",
      "    await route.handle(scope, receive, send)\r\n",
      "  File \"/Users/evanhofmeister/opt/anaconda3/lib/python3.9/site-packages/starlette/routing.py\", line 285, in handle\r\n",
      "    await self.app(scope, receive, send)\r\n",
      "  File \"/Users/evanhofmeister/opt/anaconda3/lib/python3.9/site-packages/starlette/routing.py\", line 74, in app\r\n",
      "    await wrap_app_handling_exceptions(app, request)(scope, receive, send)\r\n",
      "  File \"/Users/evanhofmeister/opt/anaconda3/lib/python3.9/site-packages/starlette/_exception_handler.py\", line 57, in wrapped_app\r\n",
      "    raise exc\r\n",
      "  File \"/Users/evanhofmeister/opt/anaconda3/lib/python3.9/site-packages/starlette/_exception_handler.py\", line 46, in wrapped_app\r\n",
      "    await app(scope, receive, sender)\r\n",
      "  File \"/Users/evanhofmeister/opt/anaconda3/lib/python3.9/site-packages/starlette/routing.py\", line 69, in app\r\n",
      "    response = await func(request)\r\n",
      "  File \"/Users/evanhofmeister/opt/anaconda3/lib/python3.9/site-packages/prefect/server/utilities/server.py\", line 103, in handle_response_scoped_depends\r\n",
      "    response = await default_handler(request)\r\n",
      "  File \"/Users/evanhofmeister/opt/anaconda3/lib/python3.9/site-packages/fastapi/routing.py\", line 227, in app\r\n",
      "    solved_result = await solve_dependencies(\r\n",
      "  File \"/Users/evanhofmeister/opt/anaconda3/lib/python3.9/site-packages/fastapi/dependencies/utils.py\", line 624, in solve_dependencies\r\n",
      "    solved = await run_in_threadpool(call, **sub_values)\r\n",
      "  File \"/Users/evanhofmeister/opt/anaconda3/lib/python3.9/site-packages/starlette/concurrency.py\", line 41, in run_in_threadpool\r\n",
      "    return await anyio.to_thread.run_sync(func, *args)\r\n",
      "  File \"/Users/evanhofmeister/opt/anaconda3/lib/python3.9/site-packages/anyio/to_thread.py\", line 28, in run_sync\r\n",
      "    return await get_asynclib().run_sync_in_worker_thread(func, *args, cancellable=cancellable,\r\n",
      "  File \"/Users/evanhofmeister/opt/anaconda3/lib/python3.9/site-packages/anyio/_backends/_asyncio.py\", line 818, in run_sync_in_worker_thread\r\n",
      "    return await future\r\n",
      "  File \"/Users/evanhofmeister/opt/anaconda3/lib/python3.9/site-packages/anyio/_backends/_asyncio.py\", line 754, in run\r\n",
      "    result = context.run(func, *args)\r\n",
      "  File \"/Users/evanhofmeister/opt/anaconda3/lib/python3.9/site-packages/prefect/server/database/dependencies.py\", line 81, in provide_database_interface\r\n",
      "    orm = AioSqliteORMConfiguration()\r\n",
      "  File \"/Users/evanhofmeister/opt/anaconda3/lib/python3.9/site-packages/prefect/server/database/orm_models.py\", line 1400, in __init__\r\n",
      "    self._create_orm_models(\r\n",
      "  File \"/Users/evanhofmeister/opt/anaconda3/lib/python3.9/site-packages/prefect/server/database/orm_models.py\", line 1550, in _create_orm_models\r\n",
      "    class Variable(variable_mixin, self.Base):\r\n",
      "  File \"/Users/evanhofmeister/opt/anaconda3/lib/python3.9/site-packages/sqlalchemy/orm/decl_api.py\", line 193, in __init__\r\n",
      "    _as_declarative(reg, cls, dict_)\r\n",
      "  File \"/Users/evanhofmeister/opt/anaconda3/lib/python3.9/site-packages/sqlalchemy/orm/decl_base.py\", line 247, in _as_declarative\r\n",
      "    return _MapperConfig.setup_mapping(registry, cls, dict_, None, {})\r\n",
      "  File \"/Users/evanhofmeister/opt/anaconda3/lib/python3.9/site-packages/sqlalchemy/orm/decl_base.py\", line 328, in setup_mapping\r\n",
      "    return _ClassScanMapperConfig(\r\n",
      "  File \"/Users/evanhofmeister/opt/anaconda3/lib/python3.9/site-packages/sqlalchemy/orm/decl_base.py\", line 563, in __init__\r\n",
      "    self._scan_attributes()\r\n",
      "  File \"/Users/evanhofmeister/opt/anaconda3/lib/python3.9/site-packages/sqlalchemy/orm/decl_base.py\", line 785, in _scan_attributes\r\n",
      "    locally_collected_columns = self._produce_column_copies(\r\n",
      "  File \"/Users/evanhofmeister/opt/anaconda3/lib/python3.9/site-packages/sqlalchemy/orm/decl_base.py\", line 1388, in _produce_column_copies\r\n",
      "    collected_annotation = self._collect_annotation(\r\n",
      "  File \"/Users/evanhofmeister/opt/anaconda3/lib/python3.9/site-packages/sqlalchemy/orm/decl_base.py\", line 1277, in _collect_annotation\r\n",
      "    extracted = _extract_mapped_subtype(\r\n",
      "  File \"/Users/evanhofmeister/opt/anaconda3/lib/python3.9/site-packages/sqlalchemy/orm/util.py\", line 2356, in _extract_mapped_subtype\r\n",
      "    raise sa_exc.ArgumentError(\r\n",
      "sqlalchemy.exc.ArgumentError: Type annotation for \"Variable.name\" can't be correctly interpreted for Annotated Declarative Table form.  ORM annotations should normally make use of the ``Mapped[]`` generic type, or other ORM-compatible generic type, as a container for the actual type, which indicates the intent that the attribute is mapped. Class variables that are not intended to be mapped by the ORM should use ClassVar[].  To allow Annotated Declarative to disregard legacy annotations which don't use Mapped[] to pass, set \"__allow_unmapped__ = True\" on the class or a superclass this class. (Background on this error at: \u001B[94mhttps://sqlalche.me/e/20/zlpr)\u001B[0m\r\n",
      "Exception in ASGI application\r\n",
      "Traceback (most recent call last):\r\n",
      "  File \"/Users/evanhofmeister/opt/anaconda3/lib/python3.9/site-packages/uvicorn/protocols/http/h11_impl.py\", line 429, in run_asgi\r\n",
      "    result = await app(  # type: ignore[func-returns-value]\r\n",
      "  File \"/Users/evanhofmeister/opt/anaconda3/lib/python3.9/site-packages/uvicorn/middleware/proxy_headers.py\", line 78, in __call__\r\n",
      "    return await self.app(scope, receive, send)\r\n",
      "  File \"/Users/evanhofmeister/opt/anaconda3/lib/python3.9/site-packages/uvicorn/middleware/message_logger.py\", line 86, in __call__\r\n",
      "    raise exc from None\r\n",
      "  File \"/Users/evanhofmeister/opt/anaconda3/lib/python3.9/site-packages/uvicorn/middleware/message_logger.py\", line 82, in __call__\r\n",
      "    await self.app(scope, inner_receive, inner_send)\r\n",
      "  File \"/Users/evanhofmeister/opt/anaconda3/lib/python3.9/site-packages/fastapi/applications.py\", line 276, in __call__\r\n",
      "    await super().__call__(scope, receive, send)\r\n",
      "  File \"/Users/evanhofmeister/opt/anaconda3/lib/python3.9/site-packages/starlette/applications.py\", line 122, in __call__\r\n",
      "    await self.middleware_stack(scope, receive, send)\r\n",
      "  File \"/Users/evanhofmeister/opt/anaconda3/lib/python3.9/site-packages/starlette/middleware/errors.py\", line 184, in __call__\r\n",
      "    raise exc\r\n",
      "  File \"/Users/evanhofmeister/opt/anaconda3/lib/python3.9/site-packages/starlette/middleware/errors.py\", line 162, in __call__\r\n",
      "    await self.app(scope, receive, _send)\r\n",
      "  File \"/Users/evanhofmeister/opt/anaconda3/lib/python3.9/site-packages/prefect/server/api/server.py\", line 117, in __call__\r\n",
      "    await self.app(scope, receive, send)\r\n",
      "  File \"/Users/evanhofmeister/opt/anaconda3/lib/python3.9/site-packages/starlette/middleware/cors.py\", line 91, in __call__\r\n",
      "    await self.simple_response(scope, receive, send, request_headers=headers)\r\n",
      "  File \"/Users/evanhofmeister/opt/anaconda3/lib/python3.9/site-packages/starlette/middleware/cors.py\", line 146, in simple_response\r\n",
      "    await self.app(scope, receive, send)\r\n",
      "  File \"/Users/evanhofmeister/opt/anaconda3/lib/python3.9/site-packages/starlette/middleware/exceptions.py\", line 62, in __call__\r\n",
      "    await wrap_app_handling_exceptions(self.app, conn)(scope, receive, send)\r\n",
      "  File \"/Users/evanhofmeister/opt/anaconda3/lib/python3.9/site-packages/starlette/_exception_handler.py\", line 57, in wrapped_app\r\n",
      "    raise exc\r\n",
      "  File \"/Users/evanhofmeister/opt/anaconda3/lib/python3.9/site-packages/starlette/_exception_handler.py\", line 46, in wrapped_app\r\n",
      "    await app(scope, receive, sender)\r\n",
      "  File \"/Users/evanhofmeister/opt/anaconda3/lib/python3.9/site-packages/fastapi/middleware/asyncexitstack.py\", line 21, in __call__\r\n",
      "    raise e\r\n",
      "  File \"/Users/evanhofmeister/opt/anaconda3/lib/python3.9/site-packages/fastapi/middleware/asyncexitstack.py\", line 18, in __call__\r\n",
      "    await self.app(scope, receive, send)\r\n",
      "  File \"/Users/evanhofmeister/opt/anaconda3/lib/python3.9/site-packages/starlette/routing.py\", line 727, in __call__\r\n",
      "    await route.handle(scope, receive, send)\r\n",
      "  File \"/Users/evanhofmeister/opt/anaconda3/lib/python3.9/site-packages/starlette/routing.py\", line 452, in handle\r\n",
      "    await self.app(scope, receive, send)\r\n",
      "  File \"/Users/evanhofmeister/opt/anaconda3/lib/python3.9/site-packages/fastapi/applications.py\", line 276, in __call__\r\n",
      "    await super().__call__(scope, receive, send)\r\n",
      "  File \"/Users/evanhofmeister/opt/anaconda3/lib/python3.9/site-packages/starlette/applications.py\", line 122, in __call__\r\n",
      "    await self.middleware_stack(scope, receive, send)\r\n",
      "  File \"/Users/evanhofmeister/opt/anaconda3/lib/python3.9/site-packages/starlette/middleware/errors.py\", line 184, in __call__\r\n",
      "    raise exc\r\n",
      "  File \"/Users/evanhofmeister/opt/anaconda3/lib/python3.9/site-packages/starlette/middleware/errors.py\", line 162, in __call__\r\n",
      "    await self.app(scope, receive, _send)\r\n",
      "  File \"/Users/evanhofmeister/opt/anaconda3/lib/python3.9/site-packages/starlette/middleware/gzip.py\", line 24, in __call__\r\n",
      "    await responder(scope, receive, send)\r\n",
      "  File \"/Users/evanhofmeister/opt/anaconda3/lib/python3.9/site-packages/starlette/middleware/gzip.py\", line 44, in __call__\r\n",
      "    await self.app(scope, receive, self.send_with_gzip)\r\n",
      "  File \"/Users/evanhofmeister/opt/anaconda3/lib/python3.9/site-packages/starlette/middleware/exceptions.py\", line 62, in __call__\r\n",
      "    await wrap_app_handling_exceptions(self.app, conn)(scope, receive, send)\r\n",
      "  File \"/Users/evanhofmeister/opt/anaconda3/lib/python3.9/site-packages/starlette/_exception_handler.py\", line 57, in wrapped_app\r\n",
      "    raise exc\r\n",
      "  File \"/Users/evanhofmeister/opt/anaconda3/lib/python3.9/site-packages/starlette/_exception_handler.py\", line 46, in wrapped_app\r\n",
      "    await app(scope, receive, sender)\r\n",
      "  File \"/Users/evanhofmeister/opt/anaconda3/lib/python3.9/site-packages/fastapi/middleware/asyncexitstack.py\", line 21, in __call__\r\n",
      "    raise e\r\n",
      "  File \"/Users/evanhofmeister/opt/anaconda3/lib/python3.9/site-packages/fastapi/middleware/asyncexitstack.py\", line 18, in __call__\r\n",
      "    await self.app(scope, receive, send)\r\n",
      "  File \"/Users/evanhofmeister/opt/anaconda3/lib/python3.9/site-packages/starlette/routing.py\", line 727, in __call__\r\n",
      "    await route.handle(scope, receive, send)\r\n",
      "  File \"/Users/evanhofmeister/opt/anaconda3/lib/python3.9/site-packages/starlette/routing.py\", line 285, in handle\r\n",
      "    await self.app(scope, receive, send)\r\n",
      "  File \"/Users/evanhofmeister/opt/anaconda3/lib/python3.9/site-packages/starlette/routing.py\", line 74, in app\r\n",
      "    await wrap_app_handling_exceptions(app, request)(scope, receive, send)\r\n",
      "  File \"/Users/evanhofmeister/opt/anaconda3/lib/python3.9/site-packages/starlette/_exception_handler.py\", line 57, in wrapped_app\r\n",
      "    raise exc\r\n",
      "  File \"/Users/evanhofmeister/opt/anaconda3/lib/python3.9/site-packages/starlette/_exception_handler.py\", line 46, in wrapped_app\r\n",
      "    await app(scope, receive, sender)\r\n",
      "  File \"/Users/evanhofmeister/opt/anaconda3/lib/python3.9/site-packages/starlette/routing.py\", line 69, in app\r\n",
      "    response = await func(request)\r\n",
      "  File \"/Users/evanhofmeister/opt/anaconda3/lib/python3.9/site-packages/prefect/server/utilities/server.py\", line 103, in handle_response_scoped_depends\r\n",
      "    response = await default_handler(request)\r\n",
      "  File \"/Users/evanhofmeister/opt/anaconda3/lib/python3.9/site-packages/fastapi/routing.py\", line 227, in app\r\n",
      "    solved_result = await solve_dependencies(\r\n",
      "  File \"/Users/evanhofmeister/opt/anaconda3/lib/python3.9/site-packages/fastapi/dependencies/utils.py\", line 624, in solve_dependencies\r\n",
      "    solved = await run_in_threadpool(call, **sub_values)\r\n",
      "  File \"/Users/evanhofmeister/opt/anaconda3/lib/python3.9/site-packages/starlette/concurrency.py\", line 41, in run_in_threadpool\r\n",
      "    return await anyio.to_thread.run_sync(func, *args)\r\n",
      "  File \"/Users/evanhofmeister/opt/anaconda3/lib/python3.9/site-packages/anyio/to_thread.py\", line 28, in run_sync\r\n",
      "    return await get_asynclib().run_sync_in_worker_thread(func, *args, cancellable=cancellable,\r\n",
      "  File \"/Users/evanhofmeister/opt/anaconda3/lib/python3.9/site-packages/anyio/_backends/_asyncio.py\", line 818, in run_sync_in_worker_thread\r\n",
      "    return await future\r\n",
      "  File \"/Users/evanhofmeister/opt/anaconda3/lib/python3.9/site-packages/anyio/_backends/_asyncio.py\", line 754, in run\r\n",
      "    result = context.run(func, *args)\r\n",
      "  File \"/Users/evanhofmeister/opt/anaconda3/lib/python3.9/site-packages/prefect/server/database/dependencies.py\", line 81, in provide_database_interface\r\n",
      "    orm = AioSqliteORMConfiguration()\r\n",
      "  File \"/Users/evanhofmeister/opt/anaconda3/lib/python3.9/site-packages/prefect/server/database/orm_models.py\", line 1400, in __init__\r\n",
      "    self._create_orm_models(\r\n",
      "  File \"/Users/evanhofmeister/opt/anaconda3/lib/python3.9/site-packages/prefect/server/database/orm_models.py\", line 1550, in _create_orm_models\r\n",
      "    class Variable(variable_mixin, self.Base):\r\n",
      "  File \"/Users/evanhofmeister/opt/anaconda3/lib/python3.9/site-packages/sqlalchemy/orm/decl_api.py\", line 193, in __init__\r\n",
      "    _as_declarative(reg, cls, dict_)\r\n",
      "  File \"/Users/evanhofmeister/opt/anaconda3/lib/python3.9/site-packages/sqlalchemy/orm/decl_base.py\", line 247, in _as_declarative\r\n",
      "    return _MapperConfig.setup_mapping(registry, cls, dict_, None, {})\r\n",
      "  File \"/Users/evanhofmeister/opt/anaconda3/lib/python3.9/site-packages/sqlalchemy/orm/decl_base.py\", line 328, in setup_mapping\r\n",
      "    return _ClassScanMapperConfig(\r\n",
      "  File \"/Users/evanhofmeister/opt/anaconda3/lib/python3.9/site-packages/sqlalchemy/orm/decl_base.py\", line 563, in __init__\r\n",
      "    self._scan_attributes()\r\n",
      "  File \"/Users/evanhofmeister/opt/anaconda3/lib/python3.9/site-packages/sqlalchemy/orm/decl_base.py\", line 785, in _scan_attributes\r\n",
      "    locally_collected_columns = self._produce_column_copies(\r\n",
      "  File \"/Users/evanhofmeister/opt/anaconda3/lib/python3.9/site-packages/sqlalchemy/orm/decl_base.py\", line 1388, in _produce_column_copies\r\n",
      "    collected_annotation = self._collect_annotation(\r\n",
      "  File \"/Users/evanhofmeister/opt/anaconda3/lib/python3.9/site-packages/sqlalchemy/orm/decl_base.py\", line 1277, in _collect_annotation\r\n",
      "    extracted = _extract_mapped_subtype(\r\n",
      "  File \"/Users/evanhofmeister/opt/anaconda3/lib/python3.9/site-packages/sqlalchemy/orm/util.py\", line 2356, in _extract_mapped_subtype\r\n",
      "    raise sa_exc.ArgumentError(\r\n",
      "sqlalchemy.exc.ArgumentError: Type annotation for \"Variable.name\" can't be correctly interpreted for Annotated Declarative Table form.  ORM annotations should normally make use of the ``Mapped[]`` generic type, or other ORM-compatible generic type, as a container for the actual type, which indicates the intent that the attribute is mapped. Class variables that are not intended to be mapped by the ORM should use ClassVar[].  To allow Annotated Declarative to disregard legacy annotations which don't use Mapped[] to pass, set \"__allow_unmapped__ = True\" on the class or a superclass this class. (Background on this error at: https://sqlalche.me/e/20/zlpr)\r\n",
      "12:34:37.759 | \u001B[31mERROR\u001B[0m   | prefect.server - Encountered exception in request:\r\n",
      "Traceback (most recent call last):\r\n",
      "  File \"/Users/evanhofmeister/opt/anaconda3/lib/python3.9/site-packages/starlette/middleware/errors.py\", line 162, in __call__\r\n",
      "    await self.app(scope, receive, _send)\r\n",
      "  File \"/Users/evanhofmeister/opt/anaconda3/lib/python3.9/site-packages/starlette/middleware/gzip.py\", line 24, in __call__\r\n",
      "    await responder(scope, receive, send)\r\n",
      "  File \"/Users/evanhofmeister/opt/anaconda3/lib/python3.9/site-packages/starlette/middleware/gzip.py\", line 44, in __call__\r\n",
      "    await self.app(scope, receive, self.send_with_gzip)\r\n",
      "  File \"/Users/evanhofmeister/opt/anaconda3/lib/python3.9/site-packages/starlette/middleware/exceptions.py\", line 62, in __call__\r\n",
      "    await wrap_app_handling_exceptions(self.app, conn)(scope, receive, send)\r\n",
      "  File \"/Users/evanhofmeister/opt/anaconda3/lib/python3.9/site-packages/starlette/_exception_handler.py\", line 57, in wrapped_app\r\n",
      "    raise exc\r\n",
      "  File \"/Users/evanhofmeister/opt/anaconda3/lib/python3.9/site-packages/starlette/_exception_handler.py\", line 46, in wrapped_app\r\n",
      "    await app(scope, receive, sender)\r\n",
      "  File \"/Users/evanhofmeister/opt/anaconda3/lib/python3.9/site-packages/fastapi/middleware/asyncexitstack.py\", line 21, in __call__\r\n",
      "    raise e\r\n",
      "  File \"/Users/evanhofmeister/opt/anaconda3/lib/python3.9/site-packages/fastapi/middleware/asyncexitstack.py\", line 18, in __call__\r\n",
      "    await self.app(scope, receive, send)\r\n",
      "  File \"/Users/evanhofmeister/opt/anaconda3/lib/python3.9/site-packages/starlette/routing.py\", line 727, in __call__\r\n",
      "    await route.handle(scope, receive, send)\r\n",
      "  File \"/Users/evanhofmeister/opt/anaconda3/lib/python3.9/site-packages/starlette/routing.py\", line 285, in handle\r\n",
      "    await self.app(scope, receive, send)\r\n",
      "  File \"/Users/evanhofmeister/opt/anaconda3/lib/python3.9/site-packages/starlette/routing.py\", line 74, in app\r\n",
      "    await wrap_app_handling_exceptions(app, request)(scope, receive, send)\r\n",
      "  File \"/Users/evanhofmeister/opt/anaconda3/lib/python3.9/site-packages/starlette/_exception_handler.py\", line 57, in wrapped_app\r\n",
      "    raise exc\r\n",
      "  File \"/Users/evanhofmeister/opt/anaconda3/lib/python3.9/site-packages/starlette/_exception_handler.py\", line 46, in wrapped_app\r\n",
      "    await app(scope, receive, sender)\r\n",
      "  File \"/Users/evanhofmeister/opt/anaconda3/lib/python3.9/site-packages/starlette/routing.py\", line 69, in app\r\n",
      "    response = await func(request)\r\n",
      "  File \"/Users/evanhofmeister/opt/anaconda3/lib/python3.9/site-packages/prefect/server/utilities/server.py\", line 103, in handle_response_scoped_depends\r\n",
      "    response = await default_handler(request)\r\n",
      "  File \"/Users/evanhofmeister/opt/anaconda3/lib/python3.9/site-packages/fastapi/routing.py\", line 227, in app\r\n",
      "    solved_result = await solve_dependencies(\r\n",
      "  File \"/Users/evanhofmeister/opt/anaconda3/lib/python3.9/site-packages/fastapi/dependencies/utils.py\", line 624, in solve_dependencies\r\n",
      "    solved = await run_in_threadpool(call, **sub_values)\r\n",
      "  File \"/Users/evanhofmeister/opt/anaconda3/lib/python3.9/site-packages/starlette/concurrency.py\", line 41, in run_in_threadpool\r\n",
      "    return await anyio.to_thread.run_sync(func, *args)\r\n",
      "  File \"/Users/evanhofmeister/opt/anaconda3/lib/python3.9/site-packages/anyio/to_thread.py\", line 28, in run_sync\r\n",
      "    return await get_asynclib().run_sync_in_worker_thread(func, *args, cancellable=cancellable,\r\n",
      "  File \"/Users/evanhofmeister/opt/anaconda3/lib/python3.9/site-packages/anyio/_backends/_asyncio.py\", line 818, in run_sync_in_worker_thread\r\n",
      "    return await future\r\n",
      "  File \"/Users/evanhofmeister/opt/anaconda3/lib/python3.9/site-packages/anyio/_backends/_asyncio.py\", line 754, in run\r\n",
      "    result = context.run(func, *args)\r\n",
      "  File \"/Users/evanhofmeister/opt/anaconda3/lib/python3.9/site-packages/prefect/server/database/dependencies.py\", line 81, in provide_database_interface\r\n",
      "    orm = AioSqliteORMConfiguration()\r\n",
      "  File \"/Users/evanhofmeister/opt/anaconda3/lib/python3.9/site-packages/prefect/server/database/orm_models.py\", line 1400, in __init__\r\n",
      "    self._create_orm_models(\r\n",
      "  File \"/Users/evanhofmeister/opt/anaconda3/lib/python3.9/site-packages/prefect/server/database/orm_models.py\", line 1550, in _create_orm_models\r\n",
      "    class Variable(variable_mixin, self.Base):\r\n",
      "  File \"/Users/evanhofmeister/opt/anaconda3/lib/python3.9/site-packages/sqlalchemy/orm/decl_api.py\", line 193, in __init__\r\n",
      "    _as_declarative(reg, cls, dict_)\r\n",
      "  File \"/Users/evanhofmeister/opt/anaconda3/lib/python3.9/site-packages/sqlalchemy/orm/decl_base.py\", line 247, in _as_declarative\r\n",
      "    return _MapperConfig.setup_mapping(registry, cls, dict_, None, {})\r\n",
      "  File \"/Users/evanhofmeister/opt/anaconda3/lib/python3.9/site-packages/sqlalchemy/orm/decl_base.py\", line 328, in setup_mapping\r\n",
      "    return _ClassScanMapperConfig(\r\n",
      "  File \"/Users/evanhofmeister/opt/anaconda3/lib/python3.9/site-packages/sqlalchemy/orm/decl_base.py\", line 563, in __init__\r\n",
      "    self._scan_attributes()\r\n",
      "  File \"/Users/evanhofmeister/opt/anaconda3/lib/python3.9/site-packages/sqlalchemy/orm/decl_base.py\", line 785, in _scan_attributes\r\n",
      "    locally_collected_columns = self._produce_column_copies(\r\n",
      "  File \"/Users/evanhofmeister/opt/anaconda3/lib/python3.9/site-packages/sqlalchemy/orm/decl_base.py\", line 1388, in _produce_column_copies\r\n",
      "    collected_annotation = self._collect_annotation(\r\n",
      "  File \"/Users/evanhofmeister/opt/anaconda3/lib/python3.9/site-packages/sqlalchemy/orm/decl_base.py\", line 1277, in _collect_annotation\r\n",
      "    extracted = _extract_mapped_subtype(\r\n",
      "  File \"/Users/evanhofmeister/opt/anaconda3/lib/python3.9/site-packages/sqlalchemy/orm/util.py\", line 2356, in _extract_mapped_subtype\r\n",
      "    raise sa_exc.ArgumentError(\r\n",
      "sqlalchemy.exc.ArgumentError: Type annotation for \"Variable.name\" can't be correctly interpreted for Annotated Declarative Table form.  ORM annotations should normally make use of the ``Mapped[]`` generic type, or other ORM-compatible generic type, as a container for the actual type, which indicates the intent that the attribute is mapped. Class variables that are not intended to be mapped by the ORM should use ClassVar[].  To allow Annotated Declarative to disregard legacy annotations which don't use Mapped[] to pass, set \"__allow_unmapped__ = True\" on the class or a superclass this class. (Background on this error at: \u001B[94mhttps://sqlalche.me/e/20/zlpr)\u001B[0m\r\n",
      "Exception in ASGI application\r\n",
      "Traceback (most recent call last):\r\n",
      "  File \"/Users/evanhofmeister/opt/anaconda3/lib/python3.9/site-packages/uvicorn/protocols/http/h11_impl.py\", line 429, in run_asgi\r\n",
      "    result = await app(  # type: ignore[func-returns-value]\r\n",
      "  File \"/Users/evanhofmeister/opt/anaconda3/lib/python3.9/site-packages/uvicorn/middleware/proxy_headers.py\", line 78, in __call__\r\n",
      "    return await self.app(scope, receive, send)\r\n",
      "  File \"/Users/evanhofmeister/opt/anaconda3/lib/python3.9/site-packages/uvicorn/middleware/message_logger.py\", line 86, in __call__\r\n",
      "    raise exc from None\r\n",
      "  File \"/Users/evanhofmeister/opt/anaconda3/lib/python3.9/site-packages/uvicorn/middleware/message_logger.py\", line 82, in __call__\r\n",
      "    await self.app(scope, inner_receive, inner_send)\r\n",
      "  File \"/Users/evanhofmeister/opt/anaconda3/lib/python3.9/site-packages/fastapi/applications.py\", line 276, in __call__\r\n",
      "    await super().__call__(scope, receive, send)\r\n",
      "  File \"/Users/evanhofmeister/opt/anaconda3/lib/python3.9/site-packages/starlette/applications.py\", line 122, in __call__\r\n",
      "    await self.middleware_stack(scope, receive, send)\r\n",
      "  File \"/Users/evanhofmeister/opt/anaconda3/lib/python3.9/site-packages/starlette/middleware/errors.py\", line 184, in __call__\r\n",
      "    raise exc\r\n",
      "  File \"/Users/evanhofmeister/opt/anaconda3/lib/python3.9/site-packages/starlette/middleware/errors.py\", line 162, in __call__\r\n",
      "    await self.app(scope, receive, _send)\r\n",
      "  File \"/Users/evanhofmeister/opt/anaconda3/lib/python3.9/site-packages/prefect/server/api/server.py\", line 117, in __call__\r\n",
      "    await self.app(scope, receive, send)\r\n",
      "  File \"/Users/evanhofmeister/opt/anaconda3/lib/python3.9/site-packages/starlette/middleware/cors.py\", line 91, in __call__\r\n",
      "    await self.simple_response(scope, receive, send, request_headers=headers)\r\n",
      "  File \"/Users/evanhofmeister/opt/anaconda3/lib/python3.9/site-packages/starlette/middleware/cors.py\", line 146, in simple_response\r\n",
      "    await self.app(scope, receive, send)\r\n",
      "  File \"/Users/evanhofmeister/opt/anaconda3/lib/python3.9/site-packages/starlette/middleware/exceptions.py\", line 62, in __call__\r\n",
      "    await wrap_app_handling_exceptions(self.app, conn)(scope, receive, send)\r\n",
      "  File \"/Users/evanhofmeister/opt/anaconda3/lib/python3.9/site-packages/starlette/_exception_handler.py\", line 57, in wrapped_app\r\n",
      "    raise exc\r\n",
      "  File \"/Users/evanhofmeister/opt/anaconda3/lib/python3.9/site-packages/starlette/_exception_handler.py\", line 46, in wrapped_app\r\n",
      "    await app(scope, receive, sender)\r\n",
      "  File \"/Users/evanhofmeister/opt/anaconda3/lib/python3.9/site-packages/fastapi/middleware/asyncexitstack.py\", line 21, in __call__\r\n",
      "    raise e\r\n",
      "  File \"/Users/evanhofmeister/opt/anaconda3/lib/python3.9/site-packages/fastapi/middleware/asyncexitstack.py\", line 18, in __call__\r\n",
      "    await self.app(scope, receive, send)\r\n",
      "  File \"/Users/evanhofmeister/opt/anaconda3/lib/python3.9/site-packages/starlette/routing.py\", line 727, in __call__\r\n",
      "    await route.handle(scope, receive, send)\r\n",
      "  File \"/Users/evanhofmeister/opt/anaconda3/lib/python3.9/site-packages/starlette/routing.py\", line 452, in handle\r\n",
      "    await self.app(scope, receive, send)\r\n",
      "  File \"/Users/evanhofmeister/opt/anaconda3/lib/python3.9/site-packages/fastapi/applications.py\", line 276, in __call__\r\n",
      "    await super().__call__(scope, receive, send)\r\n",
      "  File \"/Users/evanhofmeister/opt/anaconda3/lib/python3.9/site-packages/starlette/applications.py\", line 122, in __call__\r\n",
      "    await self.middleware_stack(scope, receive, send)\r\n",
      "  File \"/Users/evanhofmeister/opt/anaconda3/lib/python3.9/site-packages/starlette/middleware/errors.py\", line 184, in __call__\r\n",
      "    raise exc\r\n",
      "  File \"/Users/evanhofmeister/opt/anaconda3/lib/python3.9/site-packages/starlette/middleware/errors.py\", line 162, in __call__\r\n",
      "    await self.app(scope, receive, _send)\r\n",
      "  File \"/Users/evanhofmeister/opt/anaconda3/lib/python3.9/site-packages/starlette/middleware/gzip.py\", line 24, in __call__\r\n",
      "    await responder(scope, receive, send)\r\n",
      "  File \"/Users/evanhofmeister/opt/anaconda3/lib/python3.9/site-packages/starlette/middleware/gzip.py\", line 44, in __call__\r\n",
      "    await self.app(scope, receive, self.send_with_gzip)\r\n",
      "  File \"/Users/evanhofmeister/opt/anaconda3/lib/python3.9/site-packages/starlette/middleware/exceptions.py\", line 62, in __call__\r\n",
      "    await wrap_app_handling_exceptions(self.app, conn)(scope, receive, send)\r\n",
      "  File \"/Users/evanhofmeister/opt/anaconda3/lib/python3.9/site-packages/starlette/_exception_handler.py\", line 57, in wrapped_app\r\n",
      "    raise exc\r\n",
      "  File \"/Users/evanhofmeister/opt/anaconda3/lib/python3.9/site-packages/starlette/_exception_handler.py\", line 46, in wrapped_app\r\n",
      "    await app(scope, receive, sender)\r\n",
      "  File \"/Users/evanhofmeister/opt/anaconda3/lib/python3.9/site-packages/fastapi/middleware/asyncexitstack.py\", line 21, in __call__\r\n",
      "    raise e\r\n",
      "  File \"/Users/evanhofmeister/opt/anaconda3/lib/python3.9/site-packages/fastapi/middleware/asyncexitstack.py\", line 18, in __call__\r\n",
      "    await self.app(scope, receive, send)\r\n",
      "  File \"/Users/evanhofmeister/opt/anaconda3/lib/python3.9/site-packages/starlette/routing.py\", line 727, in __call__\r\n",
      "    await route.handle(scope, receive, send)\r\n",
      "  File \"/Users/evanhofmeister/opt/anaconda3/lib/python3.9/site-packages/starlette/routing.py\", line 285, in handle\r\n",
      "    await self.app(scope, receive, send)\r\n",
      "  File \"/Users/evanhofmeister/opt/anaconda3/lib/python3.9/site-packages/starlette/routing.py\", line 74, in app\r\n",
      "    await wrap_app_handling_exceptions(app, request)(scope, receive, send)\r\n",
      "  File \"/Users/evanhofmeister/opt/anaconda3/lib/python3.9/site-packages/starlette/_exception_handler.py\", line 57, in wrapped_app\r\n",
      "    raise exc\r\n",
      "  File \"/Users/evanhofmeister/opt/anaconda3/lib/python3.9/site-packages/starlette/_exception_handler.py\", line 46, in wrapped_app\r\n",
      "    await app(scope, receive, sender)\r\n",
      "  File \"/Users/evanhofmeister/opt/anaconda3/lib/python3.9/site-packages/starlette/routing.py\", line 69, in app\r\n",
      "    response = await func(request)\r\n",
      "  File \"/Users/evanhofmeister/opt/anaconda3/lib/python3.9/site-packages/prefect/server/utilities/server.py\", line 103, in handle_response_scoped_depends\r\n",
      "    response = await default_handler(request)\r\n",
      "  File \"/Users/evanhofmeister/opt/anaconda3/lib/python3.9/site-packages/fastapi/routing.py\", line 227, in app\r\n",
      "    solved_result = await solve_dependencies(\r\n",
      "  File \"/Users/evanhofmeister/opt/anaconda3/lib/python3.9/site-packages/fastapi/dependencies/utils.py\", line 624, in solve_dependencies\r\n",
      "    solved = await run_in_threadpool(call, **sub_values)\r\n",
      "  File \"/Users/evanhofmeister/opt/anaconda3/lib/python3.9/site-packages/starlette/concurrency.py\", line 41, in run_in_threadpool\r\n",
      "    return await anyio.to_thread.run_sync(func, *args)\r\n",
      "  File \"/Users/evanhofmeister/opt/anaconda3/lib/python3.9/site-packages/anyio/to_thread.py\", line 28, in run_sync\r\n",
      "    return await get_asynclib().run_sync_in_worker_thread(func, *args, cancellable=cancellable,\r\n",
      "  File \"/Users/evanhofmeister/opt/anaconda3/lib/python3.9/site-packages/anyio/_backends/_asyncio.py\", line 818, in run_sync_in_worker_thread\r\n",
      "    return await future\r\n",
      "  File \"/Users/evanhofmeister/opt/anaconda3/lib/python3.9/site-packages/anyio/_backends/_asyncio.py\", line 754, in run\r\n",
      "    result = context.run(func, *args)\r\n",
      "  File \"/Users/evanhofmeister/opt/anaconda3/lib/python3.9/site-packages/prefect/server/database/dependencies.py\", line 81, in provide_database_interface\r\n",
      "    orm = AioSqliteORMConfiguration()\r\n",
      "  File \"/Users/evanhofmeister/opt/anaconda3/lib/python3.9/site-packages/prefect/server/database/orm_models.py\", line 1400, in __init__\r\n",
      "    self._create_orm_models(\r\n",
      "  File \"/Users/evanhofmeister/opt/anaconda3/lib/python3.9/site-packages/prefect/server/database/orm_models.py\", line 1550, in _create_orm_models\r\n",
      "    class Variable(variable_mixin, self.Base):\r\n",
      "  File \"/Users/evanhofmeister/opt/anaconda3/lib/python3.9/site-packages/sqlalchemy/orm/decl_api.py\", line 193, in __init__\r\n",
      "    _as_declarative(reg, cls, dict_)\r\n",
      "  File \"/Users/evanhofmeister/opt/anaconda3/lib/python3.9/site-packages/sqlalchemy/orm/decl_base.py\", line 247, in _as_declarative\r\n",
      "    return _MapperConfig.setup_mapping(registry, cls, dict_, None, {})\r\n",
      "  File \"/Users/evanhofmeister/opt/anaconda3/lib/python3.9/site-packages/sqlalchemy/orm/decl_base.py\", line 328, in setup_mapping\r\n",
      "    return _ClassScanMapperConfig(\r\n",
      "  File \"/Users/evanhofmeister/opt/anaconda3/lib/python3.9/site-packages/sqlalchemy/orm/decl_base.py\", line 563, in __init__\r\n",
      "    self._scan_attributes()\r\n",
      "  File \"/Users/evanhofmeister/opt/anaconda3/lib/python3.9/site-packages/sqlalchemy/orm/decl_base.py\", line 785, in _scan_attributes\r\n",
      "    locally_collected_columns = self._produce_column_copies(\r\n",
      "  File \"/Users/evanhofmeister/opt/anaconda3/lib/python3.9/site-packages/sqlalchemy/orm/decl_base.py\", line 1388, in _produce_column_copies\r\n",
      "    collected_annotation = self._collect_annotation(\r\n",
      "  File \"/Users/evanhofmeister/opt/anaconda3/lib/python3.9/site-packages/sqlalchemy/orm/decl_base.py\", line 1277, in _collect_annotation\r\n",
      "    extracted = _extract_mapped_subtype(\r\n",
      "  File \"/Users/evanhofmeister/opt/anaconda3/lib/python3.9/site-packages/sqlalchemy/orm/util.py\", line 2356, in _extract_mapped_subtype\r\n",
      "    raise sa_exc.ArgumentError(\r\n",
      "sqlalchemy.exc.ArgumentError: Type annotation for \"Variable.name\" can't be correctly interpreted for Annotated Declarative Table form.  ORM annotations should normally make use of the ``Mapped[]`` generic type, or other ORM-compatible generic type, as a container for the actual type, which indicates the intent that the attribute is mapped. Class variables that are not intended to be mapped by the ORM should use ClassVar[].  To allow Annotated Declarative to disregard legacy annotations which don't use Mapped[] to pass, set \"__allow_unmapped__ = True\" on the class or a superclass this class. (Background on this error at: https://sqlalche.me/e/20/zlpr)\r\n",
      "12:34:37.915 | \u001B[31mERROR\u001B[0m   | prefect.server - Encountered exception in request:\r\n",
      "Traceback (most recent call last):\r\n",
      "  File \"/Users/evanhofmeister/opt/anaconda3/lib/python3.9/site-packages/starlette/middleware/errors.py\", line 162, in __call__\r\n",
      "    await self.app(scope, receive, _send)\r\n",
      "  File \"/Users/evanhofmeister/opt/anaconda3/lib/python3.9/site-packages/starlette/middleware/gzip.py\", line 24, in __call__\r\n",
      "    await responder(scope, receive, send)\r\n",
      "  File \"/Users/evanhofmeister/opt/anaconda3/lib/python3.9/site-packages/starlette/middleware/gzip.py\", line 44, in __call__\r\n",
      "    await self.app(scope, receive, self.send_with_gzip)\r\n",
      "  File \"/Users/evanhofmeister/opt/anaconda3/lib/python3.9/site-packages/starlette/middleware/exceptions.py\", line 62, in __call__\r\n",
      "    await wrap_app_handling_exceptions(self.app, conn)(scope, receive, send)\r\n",
      "  File \"/Users/evanhofmeister/opt/anaconda3/lib/python3.9/site-packages/starlette/_exception_handler.py\", line 57, in wrapped_app\r\n",
      "    raise exc\r\n",
      "  File \"/Users/evanhofmeister/opt/anaconda3/lib/python3.9/site-packages/starlette/_exception_handler.py\", line 46, in wrapped_app\r\n",
      "    await app(scope, receive, sender)\r\n",
      "  File \"/Users/evanhofmeister/opt/anaconda3/lib/python3.9/site-packages/fastapi/middleware/asyncexitstack.py\", line 21, in __call__\r\n",
      "    raise e\r\n",
      "  File \"/Users/evanhofmeister/opt/anaconda3/lib/python3.9/site-packages/fastapi/middleware/asyncexitstack.py\", line 18, in __call__\r\n",
      "    await self.app(scope, receive, send)\r\n",
      "  File \"/Users/evanhofmeister/opt/anaconda3/lib/python3.9/site-packages/starlette/routing.py\", line 727, in __call__\r\n",
      "    await route.handle(scope, receive, send)\r\n",
      "  File \"/Users/evanhofmeister/opt/anaconda3/lib/python3.9/site-packages/starlette/routing.py\", line 285, in handle\r\n",
      "    await self.app(scope, receive, send)\r\n",
      "  File \"/Users/evanhofmeister/opt/anaconda3/lib/python3.9/site-packages/starlette/routing.py\", line 74, in app\r\n",
      "    await wrap_app_handling_exceptions(app, request)(scope, receive, send)\r\n",
      "  File \"/Users/evanhofmeister/opt/anaconda3/lib/python3.9/site-packages/starlette/_exception_handler.py\", line 57, in wrapped_app\r\n",
      "    raise exc\r\n",
      "  File \"/Users/evanhofmeister/opt/anaconda3/lib/python3.9/site-packages/starlette/_exception_handler.py\", line 46, in wrapped_app\r\n",
      "    await app(scope, receive, sender)\r\n",
      "  File \"/Users/evanhofmeister/opt/anaconda3/lib/python3.9/site-packages/starlette/routing.py\", line 69, in app\r\n",
      "    response = await func(request)\r\n",
      "  File \"/Users/evanhofmeister/opt/anaconda3/lib/python3.9/site-packages/prefect/server/utilities/server.py\", line 103, in handle_response_scoped_depends\r\n",
      "    response = await default_handler(request)\r\n",
      "  File \"/Users/evanhofmeister/opt/anaconda3/lib/python3.9/site-packages/fastapi/routing.py\", line 227, in app\r\n",
      "    solved_result = await solve_dependencies(\r\n",
      "  File \"/Users/evanhofmeister/opt/anaconda3/lib/python3.9/site-packages/fastapi/dependencies/utils.py\", line 624, in solve_dependencies\r\n",
      "    solved = await run_in_threadpool(call, **sub_values)\r\n",
      "  File \"/Users/evanhofmeister/opt/anaconda3/lib/python3.9/site-packages/starlette/concurrency.py\", line 41, in run_in_threadpool\r\n",
      "    return await anyio.to_thread.run_sync(func, *args)\r\n",
      "  File \"/Users/evanhofmeister/opt/anaconda3/lib/python3.9/site-packages/anyio/to_thread.py\", line 28, in run_sync\r\n",
      "    return await get_asynclib().run_sync_in_worker_thread(func, *args, cancellable=cancellable,\r\n",
      "  File \"/Users/evanhofmeister/opt/anaconda3/lib/python3.9/site-packages/anyio/_backends/_asyncio.py\", line 818, in run_sync_in_worker_thread\r\n",
      "    return await future\r\n",
      "  File \"/Users/evanhofmeister/opt/anaconda3/lib/python3.9/site-packages/anyio/_backends/_asyncio.py\", line 754, in run\r\n",
      "    result = context.run(func, *args)\r\n",
      "  File \"/Users/evanhofmeister/opt/anaconda3/lib/python3.9/site-packages/prefect/server/database/dependencies.py\", line 81, in provide_database_interface\r\n",
      "    orm = AioSqliteORMConfiguration()\r\n",
      "  File \"/Users/evanhofmeister/opt/anaconda3/lib/python3.9/site-packages/prefect/server/database/orm_models.py\", line 1400, in __init__\r\n",
      "    self._create_orm_models(\r\n",
      "  File \"/Users/evanhofmeister/opt/anaconda3/lib/python3.9/site-packages/prefect/server/database/orm_models.py\", line 1550, in _create_orm_models\r\n",
      "    class Variable(variable_mixin, self.Base):\r\n",
      "  File \"/Users/evanhofmeister/opt/anaconda3/lib/python3.9/site-packages/sqlalchemy/orm/decl_api.py\", line 193, in __init__\r\n",
      "    _as_declarative(reg, cls, dict_)\r\n",
      "  File \"/Users/evanhofmeister/opt/anaconda3/lib/python3.9/site-packages/sqlalchemy/orm/decl_base.py\", line 247, in _as_declarative\r\n",
      "    return _MapperConfig.setup_mapping(registry, cls, dict_, None, {})\r\n",
      "  File \"/Users/evanhofmeister/opt/anaconda3/lib/python3.9/site-packages/sqlalchemy/orm/decl_base.py\", line 328, in setup_mapping\r\n",
      "    return _ClassScanMapperConfig(\r\n",
      "  File \"/Users/evanhofmeister/opt/anaconda3/lib/python3.9/site-packages/sqlalchemy/orm/decl_base.py\", line 563, in __init__\r\n",
      "    self._scan_attributes()\r\n",
      "  File \"/Users/evanhofmeister/opt/anaconda3/lib/python3.9/site-packages/sqlalchemy/orm/decl_base.py\", line 785, in _scan_attributes\r\n",
      "    locally_collected_columns = self._produce_column_copies(\r\n",
      "  File \"/Users/evanhofmeister/opt/anaconda3/lib/python3.9/site-packages/sqlalchemy/orm/decl_base.py\", line 1388, in _produce_column_copies\r\n",
      "    collected_annotation = self._collect_annotation(\r\n",
      "  File \"/Users/evanhofmeister/opt/anaconda3/lib/python3.9/site-packages/sqlalchemy/orm/decl_base.py\", line 1277, in _collect_annotation\r\n",
      "    extracted = _extract_mapped_subtype(\r\n",
      "  File \"/Users/evanhofmeister/opt/anaconda3/lib/python3.9/site-packages/sqlalchemy/orm/util.py\", line 2356, in _extract_mapped_subtype\r\n",
      "    raise sa_exc.ArgumentError(\r\n",
      "sqlalchemy.exc.ArgumentError: Type annotation for \"Variable.name\" can't be correctly interpreted for Annotated Declarative Table form.  ORM annotations should normally make use of the ``Mapped[]`` generic type, or other ORM-compatible generic type, as a container for the actual type, which indicates the intent that the attribute is mapped. Class variables that are not intended to be mapped by the ORM should use ClassVar[].  To allow Annotated Declarative to disregard legacy annotations which don't use Mapped[] to pass, set \"__allow_unmapped__ = True\" on the class or a superclass this class. (Background on this error at: \u001B[94mhttps://sqlalche.me/e/20/zlpr)\u001B[0m\r\n",
      "Exception in ASGI application\r\n",
      "Traceback (most recent call last):\r\n",
      "  File \"/Users/evanhofmeister/opt/anaconda3/lib/python3.9/site-packages/uvicorn/protocols/http/h11_impl.py\", line 429, in run_asgi\r\n",
      "    result = await app(  # type: ignore[func-returns-value]\r\n",
      "  File \"/Users/evanhofmeister/opt/anaconda3/lib/python3.9/site-packages/uvicorn/middleware/proxy_headers.py\", line 78, in __call__\r\n",
      "    return await self.app(scope, receive, send)\r\n",
      "  File \"/Users/evanhofmeister/opt/anaconda3/lib/python3.9/site-packages/uvicorn/middleware/message_logger.py\", line 86, in __call__\r\n",
      "    raise exc from None\r\n",
      "  File \"/Users/evanhofmeister/opt/anaconda3/lib/python3.9/site-packages/uvicorn/middleware/message_logger.py\", line 82, in __call__\r\n",
      "    await self.app(scope, inner_receive, inner_send)\r\n",
      "  File \"/Users/evanhofmeister/opt/anaconda3/lib/python3.9/site-packages/fastapi/applications.py\", line 276, in __call__\r\n",
      "    await super().__call__(scope, receive, send)\r\n",
      "  File \"/Users/evanhofmeister/opt/anaconda3/lib/python3.9/site-packages/starlette/applications.py\", line 122, in __call__\r\n",
      "    await self.middleware_stack(scope, receive, send)\r\n",
      "  File \"/Users/evanhofmeister/opt/anaconda3/lib/python3.9/site-packages/starlette/middleware/errors.py\", line 184, in __call__\r\n",
      "    raise exc\r\n",
      "  File \"/Users/evanhofmeister/opt/anaconda3/lib/python3.9/site-packages/starlette/middleware/errors.py\", line 162, in __call__\r\n",
      "    await self.app(scope, receive, _send)\r\n",
      "  File \"/Users/evanhofmeister/opt/anaconda3/lib/python3.9/site-packages/prefect/server/api/server.py\", line 117, in __call__\r\n",
      "    await self.app(scope, receive, send)\r\n",
      "  File \"/Users/evanhofmeister/opt/anaconda3/lib/python3.9/site-packages/starlette/middleware/cors.py\", line 91, in __call__\r\n",
      "    await self.simple_response(scope, receive, send, request_headers=headers)\r\n",
      "  File \"/Users/evanhofmeister/opt/anaconda3/lib/python3.9/site-packages/starlette/middleware/cors.py\", line 146, in simple_response\r\n",
      "    await self.app(scope, receive, send)\r\n",
      "  File \"/Users/evanhofmeister/opt/anaconda3/lib/python3.9/site-packages/starlette/middleware/exceptions.py\", line 62, in __call__\r\n",
      "    await wrap_app_handling_exceptions(self.app, conn)(scope, receive, send)\r\n",
      "  File \"/Users/evanhofmeister/opt/anaconda3/lib/python3.9/site-packages/starlette/_exception_handler.py\", line 57, in wrapped_app\r\n",
      "    raise exc\r\n",
      "  File \"/Users/evanhofmeister/opt/anaconda3/lib/python3.9/site-packages/starlette/_exception_handler.py\", line 46, in wrapped_app\r\n",
      "    await app(scope, receive, sender)\r\n",
      "  File \"/Users/evanhofmeister/opt/anaconda3/lib/python3.9/site-packages/fastapi/middleware/asyncexitstack.py\", line 21, in __call__\r\n",
      "    raise e\r\n",
      "  File \"/Users/evanhofmeister/opt/anaconda3/lib/python3.9/site-packages/fastapi/middleware/asyncexitstack.py\", line 18, in __call__\r\n",
      "    await self.app(scope, receive, send)\r\n",
      "  File \"/Users/evanhofmeister/opt/anaconda3/lib/python3.9/site-packages/starlette/routing.py\", line 727, in __call__\r\n",
      "    await route.handle(scope, receive, send)\r\n",
      "  File \"/Users/evanhofmeister/opt/anaconda3/lib/python3.9/site-packages/starlette/routing.py\", line 452, in handle\r\n",
      "    await self.app(scope, receive, send)\r\n",
      "  File \"/Users/evanhofmeister/opt/anaconda3/lib/python3.9/site-packages/fastapi/applications.py\", line 276, in __call__\r\n",
      "    await super().__call__(scope, receive, send)\r\n",
      "  File \"/Users/evanhofmeister/opt/anaconda3/lib/python3.9/site-packages/starlette/applications.py\", line 122, in __call__\r\n",
      "    await self.middleware_stack(scope, receive, send)\r\n",
      "  File \"/Users/evanhofmeister/opt/anaconda3/lib/python3.9/site-packages/starlette/middleware/errors.py\", line 184, in __call__\r\n",
      "    raise exc\r\n",
      "  File \"/Users/evanhofmeister/opt/anaconda3/lib/python3.9/site-packages/starlette/middleware/errors.py\", line 162, in __call__\r\n",
      "    await self.app(scope, receive, _send)\r\n",
      "  File \"/Users/evanhofmeister/opt/anaconda3/lib/python3.9/site-packages/starlette/middleware/gzip.py\", line 24, in __call__\r\n",
      "    await responder(scope, receive, send)\r\n",
      "  File \"/Users/evanhofmeister/opt/anaconda3/lib/python3.9/site-packages/starlette/middleware/gzip.py\", line 44, in __call__\r\n",
      "    await self.app(scope, receive, self.send_with_gzip)\r\n",
      "  File \"/Users/evanhofmeister/opt/anaconda3/lib/python3.9/site-packages/starlette/middleware/exceptions.py\", line 62, in __call__\r\n",
      "    await wrap_app_handling_exceptions(self.app, conn)(scope, receive, send)\r\n",
      "  File \"/Users/evanhofmeister/opt/anaconda3/lib/python3.9/site-packages/starlette/_exception_handler.py\", line 57, in wrapped_app\r\n",
      "    raise exc\r\n",
      "  File \"/Users/evanhofmeister/opt/anaconda3/lib/python3.9/site-packages/starlette/_exception_handler.py\", line 46, in wrapped_app\r\n",
      "    await app(scope, receive, sender)\r\n",
      "  File \"/Users/evanhofmeister/opt/anaconda3/lib/python3.9/site-packages/fastapi/middleware/asyncexitstack.py\", line 21, in __call__\r\n",
      "    raise e\r\n",
      "  File \"/Users/evanhofmeister/opt/anaconda3/lib/python3.9/site-packages/fastapi/middleware/asyncexitstack.py\", line 18, in __call__\r\n",
      "    await self.app(scope, receive, send)\r\n",
      "  File \"/Users/evanhofmeister/opt/anaconda3/lib/python3.9/site-packages/starlette/routing.py\", line 727, in __call__\r\n",
      "    await route.handle(scope, receive, send)\r\n",
      "  File \"/Users/evanhofmeister/opt/anaconda3/lib/python3.9/site-packages/starlette/routing.py\", line 285, in handle\r\n",
      "    await self.app(scope, receive, send)\r\n",
      "  File \"/Users/evanhofmeister/opt/anaconda3/lib/python3.9/site-packages/starlette/routing.py\", line 74, in app\r\n",
      "    await wrap_app_handling_exceptions(app, request)(scope, receive, send)\r\n",
      "  File \"/Users/evanhofmeister/opt/anaconda3/lib/python3.9/site-packages/starlette/_exception_handler.py\", line 57, in wrapped_app\r\n",
      "    raise exc\r\n",
      "  File \"/Users/evanhofmeister/opt/anaconda3/lib/python3.9/site-packages/starlette/_exception_handler.py\", line 46, in wrapped_app\r\n",
      "    await app(scope, receive, sender)\r\n",
      "  File \"/Users/evanhofmeister/opt/anaconda3/lib/python3.9/site-packages/starlette/routing.py\", line 69, in app\r\n",
      "    response = await func(request)\r\n",
      "  File \"/Users/evanhofmeister/opt/anaconda3/lib/python3.9/site-packages/prefect/server/utilities/server.py\", line 103, in handle_response_scoped_depends\r\n",
      "    response = await default_handler(request)\r\n",
      "  File \"/Users/evanhofmeister/opt/anaconda3/lib/python3.9/site-packages/fastapi/routing.py\", line 227, in app\r\n",
      "    solved_result = await solve_dependencies(\r\n",
      "  File \"/Users/evanhofmeister/opt/anaconda3/lib/python3.9/site-packages/fastapi/dependencies/utils.py\", line 624, in solve_dependencies\r\n",
      "    solved = await run_in_threadpool(call, **sub_values)\r\n",
      "  File \"/Users/evanhofmeister/opt/anaconda3/lib/python3.9/site-packages/starlette/concurrency.py\", line 41, in run_in_threadpool\r\n",
      "    return await anyio.to_thread.run_sync(func, *args)\r\n",
      "  File \"/Users/evanhofmeister/opt/anaconda3/lib/python3.9/site-packages/anyio/to_thread.py\", line 28, in run_sync\r\n",
      "    return await get_asynclib().run_sync_in_worker_thread(func, *args, cancellable=cancellable,\r\n",
      "  File \"/Users/evanhofmeister/opt/anaconda3/lib/python3.9/site-packages/anyio/_backends/_asyncio.py\", line 818, in run_sync_in_worker_thread\r\n",
      "    return await future\r\n",
      "  File \"/Users/evanhofmeister/opt/anaconda3/lib/python3.9/site-packages/anyio/_backends/_asyncio.py\", line 754, in run\r\n",
      "    result = context.run(func, *args)\r\n",
      "  File \"/Users/evanhofmeister/opt/anaconda3/lib/python3.9/site-packages/prefect/server/database/dependencies.py\", line 81, in provide_database_interface\r\n",
      "    orm = AioSqliteORMConfiguration()\r\n",
      "  File \"/Users/evanhofmeister/opt/anaconda3/lib/python3.9/site-packages/prefect/server/database/orm_models.py\", line 1400, in __init__\r\n",
      "    self._create_orm_models(\r\n",
      "  File \"/Users/evanhofmeister/opt/anaconda3/lib/python3.9/site-packages/prefect/server/database/orm_models.py\", line 1550, in _create_orm_models\r\n",
      "    class Variable(variable_mixin, self.Base):\r\n",
      "  File \"/Users/evanhofmeister/opt/anaconda3/lib/python3.9/site-packages/sqlalchemy/orm/decl_api.py\", line 193, in __init__\r\n",
      "    _as_declarative(reg, cls, dict_)\r\n",
      "  File \"/Users/evanhofmeister/opt/anaconda3/lib/python3.9/site-packages/sqlalchemy/orm/decl_base.py\", line 247, in _as_declarative\r\n",
      "    return _MapperConfig.setup_mapping(registry, cls, dict_, None, {})\r\n",
      "  File \"/Users/evanhofmeister/opt/anaconda3/lib/python3.9/site-packages/sqlalchemy/orm/decl_base.py\", line 328, in setup_mapping\r\n",
      "    return _ClassScanMapperConfig(\r\n",
      "  File \"/Users/evanhofmeister/opt/anaconda3/lib/python3.9/site-packages/sqlalchemy/orm/decl_base.py\", line 563, in __init__\r\n",
      "    self._scan_attributes()\r\n",
      "  File \"/Users/evanhofmeister/opt/anaconda3/lib/python3.9/site-packages/sqlalchemy/orm/decl_base.py\", line 785, in _scan_attributes\r\n",
      "    locally_collected_columns = self._produce_column_copies(\r\n",
      "  File \"/Users/evanhofmeister/opt/anaconda3/lib/python3.9/site-packages/sqlalchemy/orm/decl_base.py\", line 1388, in _produce_column_copies\r\n",
      "    collected_annotation = self._collect_annotation(\r\n",
      "  File \"/Users/evanhofmeister/opt/anaconda3/lib/python3.9/site-packages/sqlalchemy/orm/decl_base.py\", line 1277, in _collect_annotation\r\n",
      "    extracted = _extract_mapped_subtype(\r\n",
      "  File \"/Users/evanhofmeister/opt/anaconda3/lib/python3.9/site-packages/sqlalchemy/orm/util.py\", line 2356, in _extract_mapped_subtype\r\n",
      "    raise sa_exc.ArgumentError(\r\n",
      "sqlalchemy.exc.ArgumentError: Type annotation for \"Variable.name\" can't be correctly interpreted for Annotated Declarative Table form.  ORM annotations should normally make use of the ``Mapped[]`` generic type, or other ORM-compatible generic type, as a container for the actual type, which indicates the intent that the attribute is mapped. Class variables that are not intended to be mapped by the ORM should use ClassVar[].  To allow Annotated Declarative to disregard legacy annotations which don't use Mapped[] to pass, set \"__allow_unmapped__ = True\" on the class or a superclass this class. (Background on this error at: https://sqlalche.me/e/20/zlpr)\r\n",
      "12:34:37.974 | \u001B[31mERROR\u001B[0m   | prefect.server - Encountered exception in request:\r\n",
      "Traceback (most recent call last):\r\n",
      "  File \"/Users/evanhofmeister/opt/anaconda3/lib/python3.9/site-packages/starlette/middleware/errors.py\", line 162, in __call__\r\n",
      "    await self.app(scope, receive, _send)\r\n",
      "  File \"/Users/evanhofmeister/opt/anaconda3/lib/python3.9/site-packages/starlette/middleware/gzip.py\", line 24, in __call__\r\n",
      "    await responder(scope, receive, send)\r\n",
      "  File \"/Users/evanhofmeister/opt/anaconda3/lib/python3.9/site-packages/starlette/middleware/gzip.py\", line 44, in __call__\r\n",
      "    await self.app(scope, receive, self.send_with_gzip)\r\n",
      "  File \"/Users/evanhofmeister/opt/anaconda3/lib/python3.9/site-packages/starlette/middleware/exceptions.py\", line 62, in __call__\r\n",
      "    await wrap_app_handling_exceptions(self.app, conn)(scope, receive, send)\r\n",
      "  File \"/Users/evanhofmeister/opt/anaconda3/lib/python3.9/site-packages/starlette/_exception_handler.py\", line 57, in wrapped_app\r\n",
      "    raise exc\r\n",
      "  File \"/Users/evanhofmeister/opt/anaconda3/lib/python3.9/site-packages/starlette/_exception_handler.py\", line 46, in wrapped_app\r\n",
      "    await app(scope, receive, sender)\r\n",
      "  File \"/Users/evanhofmeister/opt/anaconda3/lib/python3.9/site-packages/fastapi/middleware/asyncexitstack.py\", line 21, in __call__\r\n",
      "    raise e\r\n",
      "  File \"/Users/evanhofmeister/opt/anaconda3/lib/python3.9/site-packages/fastapi/middleware/asyncexitstack.py\", line 18, in __call__\r\n",
      "    await self.app(scope, receive, send)\r\n",
      "  File \"/Users/evanhofmeister/opt/anaconda3/lib/python3.9/site-packages/starlette/routing.py\", line 727, in __call__\r\n",
      "    await route.handle(scope, receive, send)\r\n",
      "  File \"/Users/evanhofmeister/opt/anaconda3/lib/python3.9/site-packages/starlette/routing.py\", line 285, in handle\r\n",
      "    await self.app(scope, receive, send)\r\n",
      "  File \"/Users/evanhofmeister/opt/anaconda3/lib/python3.9/site-packages/starlette/routing.py\", line 74, in app\r\n",
      "    await wrap_app_handling_exceptions(app, request)(scope, receive, send)\r\n",
      "  File \"/Users/evanhofmeister/opt/anaconda3/lib/python3.9/site-packages/starlette/_exception_handler.py\", line 57, in wrapped_app\r\n",
      "    raise exc\r\n",
      "  File \"/Users/evanhofmeister/opt/anaconda3/lib/python3.9/site-packages/starlette/_exception_handler.py\", line 46, in wrapped_app\r\n",
      "    await app(scope, receive, sender)\r\n",
      "  File \"/Users/evanhofmeister/opt/anaconda3/lib/python3.9/site-packages/starlette/routing.py\", line 69, in app\r\n",
      "    response = await func(request)\r\n",
      "  File \"/Users/evanhofmeister/opt/anaconda3/lib/python3.9/site-packages/prefect/server/utilities/server.py\", line 103, in handle_response_scoped_depends\r\n",
      "    response = await default_handler(request)\r\n",
      "  File \"/Users/evanhofmeister/opt/anaconda3/lib/python3.9/site-packages/fastapi/routing.py\", line 227, in app\r\n",
      "    solved_result = await solve_dependencies(\r\n",
      "  File \"/Users/evanhofmeister/opt/anaconda3/lib/python3.9/site-packages/fastapi/dependencies/utils.py\", line 624, in solve_dependencies\r\n",
      "    solved = await run_in_threadpool(call, **sub_values)\r\n",
      "  File \"/Users/evanhofmeister/opt/anaconda3/lib/python3.9/site-packages/starlette/concurrency.py\", line 41, in run_in_threadpool\r\n",
      "    return await anyio.to_thread.run_sync(func, *args)\r\n",
      "  File \"/Users/evanhofmeister/opt/anaconda3/lib/python3.9/site-packages/anyio/to_thread.py\", line 28, in run_sync\r\n",
      "    return await get_asynclib().run_sync_in_worker_thread(func, *args, cancellable=cancellable,\r\n",
      "  File \"/Users/evanhofmeister/opt/anaconda3/lib/python3.9/site-packages/anyio/_backends/_asyncio.py\", line 818, in run_sync_in_worker_thread\r\n",
      "    return await future\r\n",
      "  File \"/Users/evanhofmeister/opt/anaconda3/lib/python3.9/site-packages/anyio/_backends/_asyncio.py\", line 754, in run\r\n",
      "    result = context.run(func, *args)\r\n",
      "  File \"/Users/evanhofmeister/opt/anaconda3/lib/python3.9/site-packages/prefect/server/database/dependencies.py\", line 81, in provide_database_interface\r\n",
      "    orm = AioSqliteORMConfiguration()\r\n",
      "  File \"/Users/evanhofmeister/opt/anaconda3/lib/python3.9/site-packages/prefect/server/database/orm_models.py\", line 1400, in __init__\r\n",
      "    self._create_orm_models(\r\n",
      "  File \"/Users/evanhofmeister/opt/anaconda3/lib/python3.9/site-packages/prefect/server/database/orm_models.py\", line 1550, in _create_orm_models\r\n",
      "    class Variable(variable_mixin, self.Base):\r\n",
      "  File \"/Users/evanhofmeister/opt/anaconda3/lib/python3.9/site-packages/sqlalchemy/orm/decl_api.py\", line 193, in __init__\r\n",
      "    _as_declarative(reg, cls, dict_)\r\n",
      "  File \"/Users/evanhofmeister/opt/anaconda3/lib/python3.9/site-packages/sqlalchemy/orm/decl_base.py\", line 247, in _as_declarative\r\n",
      "    return _MapperConfig.setup_mapping(registry, cls, dict_, None, {})\r\n",
      "  File \"/Users/evanhofmeister/opt/anaconda3/lib/python3.9/site-packages/sqlalchemy/orm/decl_base.py\", line 328, in setup_mapping\r\n",
      "    return _ClassScanMapperConfig(\r\n",
      "  File \"/Users/evanhofmeister/opt/anaconda3/lib/python3.9/site-packages/sqlalchemy/orm/decl_base.py\", line 563, in __init__\r\n",
      "    self._scan_attributes()\r\n",
      "  File \"/Users/evanhofmeister/opt/anaconda3/lib/python3.9/site-packages/sqlalchemy/orm/decl_base.py\", line 785, in _scan_attributes\r\n",
      "    locally_collected_columns = self._produce_column_copies(\r\n",
      "  File \"/Users/evanhofmeister/opt/anaconda3/lib/python3.9/site-packages/sqlalchemy/orm/decl_base.py\", line 1388, in _produce_column_copies\r\n",
      "    collected_annotation = self._collect_annotation(\r\n",
      "  File \"/Users/evanhofmeister/opt/anaconda3/lib/python3.9/site-packages/sqlalchemy/orm/decl_base.py\", line 1277, in _collect_annotation\r\n",
      "    extracted = _extract_mapped_subtype(\r\n",
      "  File \"/Users/evanhofmeister/opt/anaconda3/lib/python3.9/site-packages/sqlalchemy/orm/util.py\", line 2356, in _extract_mapped_subtype\r\n",
      "    raise sa_exc.ArgumentError(\r\n",
      "sqlalchemy.exc.ArgumentError: Type annotation for \"Variable.name\" can't be correctly interpreted for Annotated Declarative Table form.  ORM annotations should normally make use of the ``Mapped[]`` generic type, or other ORM-compatible generic type, as a container for the actual type, which indicates the intent that the attribute is mapped. Class variables that are not intended to be mapped by the ORM should use ClassVar[].  To allow Annotated Declarative to disregard legacy annotations which don't use Mapped[] to pass, set \"__allow_unmapped__ = True\" on the class or a superclass this class. (Background on this error at: \u001B[94mhttps://sqlalche.me/e/20/zlpr)\u001B[0m\r\n",
      "Exception in ASGI application\r\n",
      "Traceback (most recent call last):\r\n",
      "  File \"/Users/evanhofmeister/opt/anaconda3/lib/python3.9/site-packages/uvicorn/protocols/http/h11_impl.py\", line 429, in run_asgi\r\n",
      "    result = await app(  # type: ignore[func-returns-value]\r\n",
      "  File \"/Users/evanhofmeister/opt/anaconda3/lib/python3.9/site-packages/uvicorn/middleware/proxy_headers.py\", line 78, in __call__\r\n",
      "    return await self.app(scope, receive, send)\r\n",
      "  File \"/Users/evanhofmeister/opt/anaconda3/lib/python3.9/site-packages/uvicorn/middleware/message_logger.py\", line 86, in __call__\r\n",
      "    raise exc from None\r\n",
      "  File \"/Users/evanhofmeister/opt/anaconda3/lib/python3.9/site-packages/uvicorn/middleware/message_logger.py\", line 82, in __call__\r\n",
      "    await self.app(scope, inner_receive, inner_send)\r\n",
      "  File \"/Users/evanhofmeister/opt/anaconda3/lib/python3.9/site-packages/fastapi/applications.py\", line 276, in __call__\r\n",
      "    await super().__call__(scope, receive, send)\r\n",
      "  File \"/Users/evanhofmeister/opt/anaconda3/lib/python3.9/site-packages/starlette/applications.py\", line 122, in __call__\r\n",
      "    await self.middleware_stack(scope, receive, send)\r\n",
      "  File \"/Users/evanhofmeister/opt/anaconda3/lib/python3.9/site-packages/starlette/middleware/errors.py\", line 184, in __call__\r\n",
      "    raise exc\r\n",
      "  File \"/Users/evanhofmeister/opt/anaconda3/lib/python3.9/site-packages/starlette/middleware/errors.py\", line 162, in __call__\r\n",
      "    await self.app(scope, receive, _send)\r\n",
      "  File \"/Users/evanhofmeister/opt/anaconda3/lib/python3.9/site-packages/prefect/server/api/server.py\", line 117, in __call__\r\n",
      "    await self.app(scope, receive, send)\r\n",
      "  File \"/Users/evanhofmeister/opt/anaconda3/lib/python3.9/site-packages/starlette/middleware/cors.py\", line 91, in __call__\r\n",
      "    await self.simple_response(scope, receive, send, request_headers=headers)\r\n",
      "  File \"/Users/evanhofmeister/opt/anaconda3/lib/python3.9/site-packages/starlette/middleware/cors.py\", line 146, in simple_response\r\n",
      "    await self.app(scope, receive, send)\r\n",
      "  File \"/Users/evanhofmeister/opt/anaconda3/lib/python3.9/site-packages/starlette/middleware/exceptions.py\", line 62, in __call__\r\n",
      "    await wrap_app_handling_exceptions(self.app, conn)(scope, receive, send)\r\n",
      "  File \"/Users/evanhofmeister/opt/anaconda3/lib/python3.9/site-packages/starlette/_exception_handler.py\", line 57, in wrapped_app\r\n",
      "    raise exc\r\n",
      "  File \"/Users/evanhofmeister/opt/anaconda3/lib/python3.9/site-packages/starlette/_exception_handler.py\", line 46, in wrapped_app\r\n",
      "    await app(scope, receive, sender)\r\n",
      "  File \"/Users/evanhofmeister/opt/anaconda3/lib/python3.9/site-packages/fastapi/middleware/asyncexitstack.py\", line 21, in __call__\r\n",
      "    raise e\r\n",
      "  File \"/Users/evanhofmeister/opt/anaconda3/lib/python3.9/site-packages/fastapi/middleware/asyncexitstack.py\", line 18, in __call__\r\n",
      "    await self.app(scope, receive, send)\r\n",
      "  File \"/Users/evanhofmeister/opt/anaconda3/lib/python3.9/site-packages/starlette/routing.py\", line 727, in __call__\r\n",
      "    await route.handle(scope, receive, send)\r\n",
      "  File \"/Users/evanhofmeister/opt/anaconda3/lib/python3.9/site-packages/starlette/routing.py\", line 452, in handle\r\n",
      "    await self.app(scope, receive, send)\r\n",
      "  File \"/Users/evanhofmeister/opt/anaconda3/lib/python3.9/site-packages/fastapi/applications.py\", line 276, in __call__\r\n",
      "    await super().__call__(scope, receive, send)\r\n",
      "  File \"/Users/evanhofmeister/opt/anaconda3/lib/python3.9/site-packages/starlette/applications.py\", line 122, in __call__\r\n",
      "    await self.middleware_stack(scope, receive, send)\r\n",
      "  File \"/Users/evanhofmeister/opt/anaconda3/lib/python3.9/site-packages/starlette/middleware/errors.py\", line 184, in __call__\r\n",
      "    raise exc\r\n",
      "  File \"/Users/evanhofmeister/opt/anaconda3/lib/python3.9/site-packages/starlette/middleware/errors.py\", line 162, in __call__\r\n",
      "    await self.app(scope, receive, _send)\r\n",
      "  File \"/Users/evanhofmeister/opt/anaconda3/lib/python3.9/site-packages/starlette/middleware/gzip.py\", line 24, in __call__\r\n",
      "    await responder(scope, receive, send)\r\n",
      "  File \"/Users/evanhofmeister/opt/anaconda3/lib/python3.9/site-packages/starlette/middleware/gzip.py\", line 44, in __call__\r\n",
      "    await self.app(scope, receive, self.send_with_gzip)\r\n",
      "  File \"/Users/evanhofmeister/opt/anaconda3/lib/python3.9/site-packages/starlette/middleware/exceptions.py\", line 62, in __call__\r\n",
      "    await wrap_app_handling_exceptions(self.app, conn)(scope, receive, send)\r\n",
      "  File \"/Users/evanhofmeister/opt/anaconda3/lib/python3.9/site-packages/starlette/_exception_handler.py\", line 57, in wrapped_app\r\n",
      "    raise exc\r\n",
      "  File \"/Users/evanhofmeister/opt/anaconda3/lib/python3.9/site-packages/starlette/_exception_handler.py\", line 46, in wrapped_app\r\n",
      "    await app(scope, receive, sender)\r\n",
      "  File \"/Users/evanhofmeister/opt/anaconda3/lib/python3.9/site-packages/fastapi/middleware/asyncexitstack.py\", line 21, in __call__\r\n",
      "    raise e\r\n",
      "  File \"/Users/evanhofmeister/opt/anaconda3/lib/python3.9/site-packages/fastapi/middleware/asyncexitstack.py\", line 18, in __call__\r\n",
      "    await self.app(scope, receive, send)\r\n",
      "  File \"/Users/evanhofmeister/opt/anaconda3/lib/python3.9/site-packages/starlette/routing.py\", line 727, in __call__\r\n",
      "    await route.handle(scope, receive, send)\r\n",
      "  File \"/Users/evanhofmeister/opt/anaconda3/lib/python3.9/site-packages/starlette/routing.py\", line 285, in handle\r\n",
      "    await self.app(scope, receive, send)\r\n",
      "  File \"/Users/evanhofmeister/opt/anaconda3/lib/python3.9/site-packages/starlette/routing.py\", line 74, in app\r\n",
      "    await wrap_app_handling_exceptions(app, request)(scope, receive, send)\r\n",
      "  File \"/Users/evanhofmeister/opt/anaconda3/lib/python3.9/site-packages/starlette/_exception_handler.py\", line 57, in wrapped_app\r\n",
      "    raise exc\r\n",
      "  File \"/Users/evanhofmeister/opt/anaconda3/lib/python3.9/site-packages/starlette/_exception_handler.py\", line 46, in wrapped_app\r\n",
      "    await app(scope, receive, sender)\r\n",
      "  File \"/Users/evanhofmeister/opt/anaconda3/lib/python3.9/site-packages/starlette/routing.py\", line 69, in app\r\n",
      "    response = await func(request)\r\n",
      "  File \"/Users/evanhofmeister/opt/anaconda3/lib/python3.9/site-packages/prefect/server/utilities/server.py\", line 103, in handle_response_scoped_depends\r\n",
      "    response = await default_handler(request)\r\n",
      "  File \"/Users/evanhofmeister/opt/anaconda3/lib/python3.9/site-packages/fastapi/routing.py\", line 227, in app\r\n",
      "    solved_result = await solve_dependencies(\r\n",
      "  File \"/Users/evanhofmeister/opt/anaconda3/lib/python3.9/site-packages/fastapi/dependencies/utils.py\", line 624, in solve_dependencies\r\n",
      "    solved = await run_in_threadpool(call, **sub_values)\r\n",
      "  File \"/Users/evanhofmeister/opt/anaconda3/lib/python3.9/site-packages/starlette/concurrency.py\", line 41, in run_in_threadpool\r\n",
      "    return await anyio.to_thread.run_sync(func, *args)\r\n",
      "  File \"/Users/evanhofmeister/opt/anaconda3/lib/python3.9/site-packages/anyio/to_thread.py\", line 28, in run_sync\r\n",
      "    return await get_asynclib().run_sync_in_worker_thread(func, *args, cancellable=cancellable,\r\n",
      "  File \"/Users/evanhofmeister/opt/anaconda3/lib/python3.9/site-packages/anyio/_backends/_asyncio.py\", line 818, in run_sync_in_worker_thread\r\n",
      "    return await future\r\n",
      "  File \"/Users/evanhofmeister/opt/anaconda3/lib/python3.9/site-packages/anyio/_backends/_asyncio.py\", line 754, in run\r\n",
      "    result = context.run(func, *args)\r\n",
      "  File \"/Users/evanhofmeister/opt/anaconda3/lib/python3.9/site-packages/prefect/server/database/dependencies.py\", line 81, in provide_database_interface\r\n",
      "    orm = AioSqliteORMConfiguration()\r\n",
      "  File \"/Users/evanhofmeister/opt/anaconda3/lib/python3.9/site-packages/prefect/server/database/orm_models.py\", line 1400, in __init__\r\n",
      "    self._create_orm_models(\r\n",
      "  File \"/Users/evanhofmeister/opt/anaconda3/lib/python3.9/site-packages/prefect/server/database/orm_models.py\", line 1550, in _create_orm_models\r\n",
      "    class Variable(variable_mixin, self.Base):\r\n",
      "  File \"/Users/evanhofmeister/opt/anaconda3/lib/python3.9/site-packages/sqlalchemy/orm/decl_api.py\", line 193, in __init__\r\n",
      "    _as_declarative(reg, cls, dict_)\r\n",
      "  File \"/Users/evanhofmeister/opt/anaconda3/lib/python3.9/site-packages/sqlalchemy/orm/decl_base.py\", line 247, in _as_declarative\r\n",
      "    return _MapperConfig.setup_mapping(registry, cls, dict_, None, {})\r\n",
      "  File \"/Users/evanhofmeister/opt/anaconda3/lib/python3.9/site-packages/sqlalchemy/orm/decl_base.py\", line 328, in setup_mapping\r\n",
      "    return _ClassScanMapperConfig(\r\n",
      "  File \"/Users/evanhofmeister/opt/anaconda3/lib/python3.9/site-packages/sqlalchemy/orm/decl_base.py\", line 563, in __init__\r\n",
      "    self._scan_attributes()\r\n",
      "  File \"/Users/evanhofmeister/opt/anaconda3/lib/python3.9/site-packages/sqlalchemy/orm/decl_base.py\", line 785, in _scan_attributes\r\n",
      "    locally_collected_columns = self._produce_column_copies(\r\n",
      "  File \"/Users/evanhofmeister/opt/anaconda3/lib/python3.9/site-packages/sqlalchemy/orm/decl_base.py\", line 1388, in _produce_column_copies\r\n",
      "    collected_annotation = self._collect_annotation(\r\n",
      "  File \"/Users/evanhofmeister/opt/anaconda3/lib/python3.9/site-packages/sqlalchemy/orm/decl_base.py\", line 1277, in _collect_annotation\r\n",
      "    extracted = _extract_mapped_subtype(\r\n",
      "  File \"/Users/evanhofmeister/opt/anaconda3/lib/python3.9/site-packages/sqlalchemy/orm/util.py\", line 2356, in _extract_mapped_subtype\r\n",
      "    raise sa_exc.ArgumentError(\r\n",
      "sqlalchemy.exc.ArgumentError: Type annotation for \"Variable.name\" can't be correctly interpreted for Annotated Declarative Table form.  ORM annotations should normally make use of the ``Mapped[]`` generic type, or other ORM-compatible generic type, as a container for the actual type, which indicates the intent that the attribute is mapped. Class variables that are not intended to be mapped by the ORM should use ClassVar[].  To allow Annotated Declarative to disregard legacy annotations which don't use Mapped[] to pass, set \"__allow_unmapped__ = True\" on the class or a superclass this class. (Background on this error at: https://sqlalche.me/e/20/zlpr)\r\n",
      "12:34:37.996 | \u001B[31mERROR\u001B[0m   | prefect.server - Encountered exception in request:\r\n",
      "Traceback (most recent call last):\r\n",
      "  File \"/Users/evanhofmeister/opt/anaconda3/lib/python3.9/site-packages/starlette/middleware/errors.py\", line 162, in __call__\r\n",
      "    await self.app(scope, receive, _send)\r\n",
      "  File \"/Users/evanhofmeister/opt/anaconda3/lib/python3.9/site-packages/starlette/middleware/gzip.py\", line 24, in __call__\r\n",
      "    await responder(scope, receive, send)\r\n",
      "  File \"/Users/evanhofmeister/opt/anaconda3/lib/python3.9/site-packages/starlette/middleware/gzip.py\", line 44, in __call__\r\n",
      "    await self.app(scope, receive, self.send_with_gzip)\r\n",
      "  File \"/Users/evanhofmeister/opt/anaconda3/lib/python3.9/site-packages/starlette/middleware/exceptions.py\", line 62, in __call__\r\n",
      "    await wrap_app_handling_exceptions(self.app, conn)(scope, receive, send)\r\n",
      "  File \"/Users/evanhofmeister/opt/anaconda3/lib/python3.9/site-packages/starlette/_exception_handler.py\", line 57, in wrapped_app\r\n",
      "    raise exc\r\n",
      "  File \"/Users/evanhofmeister/opt/anaconda3/lib/python3.9/site-packages/starlette/_exception_handler.py\", line 46, in wrapped_app\r\n",
      "    await app(scope, receive, sender)\r\n",
      "  File \"/Users/evanhofmeister/opt/anaconda3/lib/python3.9/site-packages/fastapi/middleware/asyncexitstack.py\", line 21, in __call__\r\n",
      "    raise e\r\n",
      "  File \"/Users/evanhofmeister/opt/anaconda3/lib/python3.9/site-packages/fastapi/middleware/asyncexitstack.py\", line 18, in __call__\r\n",
      "    await self.app(scope, receive, send)\r\n",
      "  File \"/Users/evanhofmeister/opt/anaconda3/lib/python3.9/site-packages/starlette/routing.py\", line 727, in __call__\r\n",
      "    await route.handle(scope, receive, send)\r\n",
      "  File \"/Users/evanhofmeister/opt/anaconda3/lib/python3.9/site-packages/starlette/routing.py\", line 285, in handle\r\n",
      "    await self.app(scope, receive, send)\r\n",
      "  File \"/Users/evanhofmeister/opt/anaconda3/lib/python3.9/site-packages/starlette/routing.py\", line 74, in app\r\n",
      "    await wrap_app_handling_exceptions(app, request)(scope, receive, send)\r\n",
      "  File \"/Users/evanhofmeister/opt/anaconda3/lib/python3.9/site-packages/starlette/_exception_handler.py\", line 57, in wrapped_app\r\n",
      "    raise exc\r\n",
      "  File \"/Users/evanhofmeister/opt/anaconda3/lib/python3.9/site-packages/starlette/_exception_handler.py\", line 46, in wrapped_app\r\n",
      "    await app(scope, receive, sender)\r\n",
      "  File \"/Users/evanhofmeister/opt/anaconda3/lib/python3.9/site-packages/starlette/routing.py\", line 69, in app\r\n",
      "    response = await func(request)\r\n",
      "  File \"/Users/evanhofmeister/opt/anaconda3/lib/python3.9/site-packages/prefect/server/utilities/server.py\", line 103, in handle_response_scoped_depends\r\n",
      "    response = await default_handler(request)\r\n",
      "  File \"/Users/evanhofmeister/opt/anaconda3/lib/python3.9/site-packages/fastapi/routing.py\", line 227, in app\r\n",
      "    solved_result = await solve_dependencies(\r\n",
      "  File \"/Users/evanhofmeister/opt/anaconda3/lib/python3.9/site-packages/fastapi/dependencies/utils.py\", line 624, in solve_dependencies\r\n",
      "    solved = await run_in_threadpool(call, **sub_values)\r\n",
      "  File \"/Users/evanhofmeister/opt/anaconda3/lib/python3.9/site-packages/starlette/concurrency.py\", line 41, in run_in_threadpool\r\n",
      "    return await anyio.to_thread.run_sync(func, *args)\r\n",
      "  File \"/Users/evanhofmeister/opt/anaconda3/lib/python3.9/site-packages/anyio/to_thread.py\", line 28, in run_sync\r\n",
      "    return await get_asynclib().run_sync_in_worker_thread(func, *args, cancellable=cancellable,\r\n",
      "  File \"/Users/evanhofmeister/opt/anaconda3/lib/python3.9/site-packages/anyio/_backends/_asyncio.py\", line 818, in run_sync_in_worker_thread\r\n",
      "    return await future\r\n",
      "  File \"/Users/evanhofmeister/opt/anaconda3/lib/python3.9/site-packages/anyio/_backends/_asyncio.py\", line 754, in run\r\n",
      "    result = context.run(func, *args)\r\n",
      "  File \"/Users/evanhofmeister/opt/anaconda3/lib/python3.9/site-packages/prefect/server/database/dependencies.py\", line 81, in provide_database_interface\r\n",
      "    orm = AioSqliteORMConfiguration()\r\n",
      "  File \"/Users/evanhofmeister/opt/anaconda3/lib/python3.9/site-packages/prefect/server/database/orm_models.py\", line 1400, in __init__\r\n",
      "    self._create_orm_models(\r\n",
      "  File \"/Users/evanhofmeister/opt/anaconda3/lib/python3.9/site-packages/prefect/server/database/orm_models.py\", line 1550, in _create_orm_models\r\n",
      "    class Variable(variable_mixin, self.Base):\r\n",
      "  File \"/Users/evanhofmeister/opt/anaconda3/lib/python3.9/site-packages/sqlalchemy/orm/decl_api.py\", line 193, in __init__\r\n",
      "    _as_declarative(reg, cls, dict_)\r\n",
      "  File \"/Users/evanhofmeister/opt/anaconda3/lib/python3.9/site-packages/sqlalchemy/orm/decl_base.py\", line 247, in _as_declarative\r\n",
      "    return _MapperConfig.setup_mapping(registry, cls, dict_, None, {})\r\n",
      "  File \"/Users/evanhofmeister/opt/anaconda3/lib/python3.9/site-packages/sqlalchemy/orm/decl_base.py\", line 328, in setup_mapping\r\n",
      "    return _ClassScanMapperConfig(\r\n",
      "  File \"/Users/evanhofmeister/opt/anaconda3/lib/python3.9/site-packages/sqlalchemy/orm/decl_base.py\", line 563, in __init__\r\n",
      "    self._scan_attributes()\r\n",
      "  File \"/Users/evanhofmeister/opt/anaconda3/lib/python3.9/site-packages/sqlalchemy/orm/decl_base.py\", line 785, in _scan_attributes\r\n",
      "    locally_collected_columns = self._produce_column_copies(\r\n",
      "  File \"/Users/evanhofmeister/opt/anaconda3/lib/python3.9/site-packages/sqlalchemy/orm/decl_base.py\", line 1388, in _produce_column_copies\r\n",
      "    collected_annotation = self._collect_annotation(\r\n",
      "  File \"/Users/evanhofmeister/opt/anaconda3/lib/python3.9/site-packages/sqlalchemy/orm/decl_base.py\", line 1277, in _collect_annotation\r\n",
      "    extracted = _extract_mapped_subtype(\r\n",
      "  File \"/Users/evanhofmeister/opt/anaconda3/lib/python3.9/site-packages/sqlalchemy/orm/util.py\", line 2356, in _extract_mapped_subtype\r\n",
      "    raise sa_exc.ArgumentError(\r\n",
      "sqlalchemy.exc.ArgumentError: Type annotation for \"Variable.name\" can't be correctly interpreted for Annotated Declarative Table form.  ORM annotations should normally make use of the ``Mapped[]`` generic type, or other ORM-compatible generic type, as a container for the actual type, which indicates the intent that the attribute is mapped. Class variables that are not intended to be mapped by the ORM should use ClassVar[].  To allow Annotated Declarative to disregard legacy annotations which don't use Mapped[] to pass, set \"__allow_unmapped__ = True\" on the class or a superclass this class. (Background on this error at: \u001B[94mhttps://sqlalche.me/e/20/zlpr)\u001B[0m\r\n",
      "Exception in ASGI application\r\n",
      "Traceback (most recent call last):\r\n",
      "  File \"/Users/evanhofmeister/opt/anaconda3/lib/python3.9/site-packages/uvicorn/protocols/http/h11_impl.py\", line 429, in run_asgi\r\n",
      "    result = await app(  # type: ignore[func-returns-value]\r\n",
      "  File \"/Users/evanhofmeister/opt/anaconda3/lib/python3.9/site-packages/uvicorn/middleware/proxy_headers.py\", line 78, in __call__\r\n",
      "    return await self.app(scope, receive, send)\r\n",
      "  File \"/Users/evanhofmeister/opt/anaconda3/lib/python3.9/site-packages/uvicorn/middleware/message_logger.py\", line 86, in __call__\r\n",
      "    raise exc from None\r\n",
      "  File \"/Users/evanhofmeister/opt/anaconda3/lib/python3.9/site-packages/uvicorn/middleware/message_logger.py\", line 82, in __call__\r\n",
      "    await self.app(scope, inner_receive, inner_send)\r\n",
      "  File \"/Users/evanhofmeister/opt/anaconda3/lib/python3.9/site-packages/fastapi/applications.py\", line 276, in __call__\r\n",
      "    await super().__call__(scope, receive, send)\r\n",
      "  File \"/Users/evanhofmeister/opt/anaconda3/lib/python3.9/site-packages/starlette/applications.py\", line 122, in __call__\r\n",
      "    await self.middleware_stack(scope, receive, send)\r\n",
      "  File \"/Users/evanhofmeister/opt/anaconda3/lib/python3.9/site-packages/starlette/middleware/errors.py\", line 184, in __call__\r\n",
      "    raise exc\r\n",
      "  File \"/Users/evanhofmeister/opt/anaconda3/lib/python3.9/site-packages/starlette/middleware/errors.py\", line 162, in __call__\r\n",
      "    await self.app(scope, receive, _send)\r\n",
      "  File \"/Users/evanhofmeister/opt/anaconda3/lib/python3.9/site-packages/prefect/server/api/server.py\", line 117, in __call__\r\n",
      "    await self.app(scope, receive, send)\r\n",
      "  File \"/Users/evanhofmeister/opt/anaconda3/lib/python3.9/site-packages/starlette/middleware/cors.py\", line 91, in __call__\r\n",
      "    await self.simple_response(scope, receive, send, request_headers=headers)\r\n",
      "  File \"/Users/evanhofmeister/opt/anaconda3/lib/python3.9/site-packages/starlette/middleware/cors.py\", line 146, in simple_response\r\n",
      "    await self.app(scope, receive, send)\r\n",
      "  File \"/Users/evanhofmeister/opt/anaconda3/lib/python3.9/site-packages/starlette/middleware/exceptions.py\", line 62, in __call__\r\n",
      "    await wrap_app_handling_exceptions(self.app, conn)(scope, receive, send)\r\n",
      "  File \"/Users/evanhofmeister/opt/anaconda3/lib/python3.9/site-packages/starlette/_exception_handler.py\", line 57, in wrapped_app\r\n",
      "    raise exc\r\n",
      "  File \"/Users/evanhofmeister/opt/anaconda3/lib/python3.9/site-packages/starlette/_exception_handler.py\", line 46, in wrapped_app\r\n",
      "    await app(scope, receive, sender)\r\n",
      "  File \"/Users/evanhofmeister/opt/anaconda3/lib/python3.9/site-packages/fastapi/middleware/asyncexitstack.py\", line 21, in __call__\r\n",
      "    raise e\r\n",
      "  File \"/Users/evanhofmeister/opt/anaconda3/lib/python3.9/site-packages/fastapi/middleware/asyncexitstack.py\", line 18, in __call__\r\n",
      "    await self.app(scope, receive, send)\r\n",
      "  File \"/Users/evanhofmeister/opt/anaconda3/lib/python3.9/site-packages/starlette/routing.py\", line 727, in __call__\r\n",
      "    await route.handle(scope, receive, send)\r\n",
      "  File \"/Users/evanhofmeister/opt/anaconda3/lib/python3.9/site-packages/starlette/routing.py\", line 452, in handle\r\n",
      "    await self.app(scope, receive, send)\r\n",
      "  File \"/Users/evanhofmeister/opt/anaconda3/lib/python3.9/site-packages/fastapi/applications.py\", line 276, in __call__\r\n",
      "    await super().__call__(scope, receive, send)\r\n",
      "  File \"/Users/evanhofmeister/opt/anaconda3/lib/python3.9/site-packages/starlette/applications.py\", line 122, in __call__\r\n",
      "    await self.middleware_stack(scope, receive, send)\r\n",
      "  File \"/Users/evanhofmeister/opt/anaconda3/lib/python3.9/site-packages/starlette/middleware/errors.py\", line 184, in __call__\r\n",
      "    raise exc\r\n",
      "  File \"/Users/evanhofmeister/opt/anaconda3/lib/python3.9/site-packages/starlette/middleware/errors.py\", line 162, in __call__\r\n",
      "    await self.app(scope, receive, _send)\r\n",
      "  File \"/Users/evanhofmeister/opt/anaconda3/lib/python3.9/site-packages/starlette/middleware/gzip.py\", line 24, in __call__\r\n",
      "    await responder(scope, receive, send)\r\n",
      "  File \"/Users/evanhofmeister/opt/anaconda3/lib/python3.9/site-packages/starlette/middleware/gzip.py\", line 44, in __call__\r\n",
      "    await self.app(scope, receive, self.send_with_gzip)\r\n",
      "  File \"/Users/evanhofmeister/opt/anaconda3/lib/python3.9/site-packages/starlette/middleware/exceptions.py\", line 62, in __call__\r\n",
      "    await wrap_app_handling_exceptions(self.app, conn)(scope, receive, send)\r\n",
      "  File \"/Users/evanhofmeister/opt/anaconda3/lib/python3.9/site-packages/starlette/_exception_handler.py\", line 57, in wrapped_app\r\n",
      "    raise exc\r\n",
      "  File \"/Users/evanhofmeister/opt/anaconda3/lib/python3.9/site-packages/starlette/_exception_handler.py\", line 46, in wrapped_app\r\n",
      "    await app(scope, receive, sender)\r\n",
      "  File \"/Users/evanhofmeister/opt/anaconda3/lib/python3.9/site-packages/fastapi/middleware/asyncexitstack.py\", line 21, in __call__\r\n",
      "    raise e\r\n",
      "  File \"/Users/evanhofmeister/opt/anaconda3/lib/python3.9/site-packages/fastapi/middleware/asyncexitstack.py\", line 18, in __call__\r\n",
      "    await self.app(scope, receive, send)\r\n",
      "  File \"/Users/evanhofmeister/opt/anaconda3/lib/python3.9/site-packages/starlette/routing.py\", line 727, in __call__\r\n",
      "    await route.handle(scope, receive, send)\r\n",
      "  File \"/Users/evanhofmeister/opt/anaconda3/lib/python3.9/site-packages/starlette/routing.py\", line 285, in handle\r\n",
      "    await self.app(scope, receive, send)\r\n",
      "  File \"/Users/evanhofmeister/opt/anaconda3/lib/python3.9/site-packages/starlette/routing.py\", line 74, in app\r\n",
      "    await wrap_app_handling_exceptions(app, request)(scope, receive, send)\r\n",
      "  File \"/Users/evanhofmeister/opt/anaconda3/lib/python3.9/site-packages/starlette/_exception_handler.py\", line 57, in wrapped_app\r\n",
      "    raise exc\r\n",
      "  File \"/Users/evanhofmeister/opt/anaconda3/lib/python3.9/site-packages/starlette/_exception_handler.py\", line 46, in wrapped_app\r\n",
      "    await app(scope, receive, sender)\r\n",
      "  File \"/Users/evanhofmeister/opt/anaconda3/lib/python3.9/site-packages/starlette/routing.py\", line 69, in app\r\n",
      "    response = await func(request)\r\n",
      "  File \"/Users/evanhofmeister/opt/anaconda3/lib/python3.9/site-packages/prefect/server/utilities/server.py\", line 103, in handle_response_scoped_depends\r\n",
      "    response = await default_handler(request)\r\n",
      "  File \"/Users/evanhofmeister/opt/anaconda3/lib/python3.9/site-packages/fastapi/routing.py\", line 227, in app\r\n",
      "    solved_result = await solve_dependencies(\r\n",
      "  File \"/Users/evanhofmeister/opt/anaconda3/lib/python3.9/site-packages/fastapi/dependencies/utils.py\", line 624, in solve_dependencies\r\n",
      "    solved = await run_in_threadpool(call, **sub_values)\r\n",
      "  File \"/Users/evanhofmeister/opt/anaconda3/lib/python3.9/site-packages/starlette/concurrency.py\", line 41, in run_in_threadpool\r\n",
      "    return await anyio.to_thread.run_sync(func, *args)\r\n",
      "  File \"/Users/evanhofmeister/opt/anaconda3/lib/python3.9/site-packages/anyio/to_thread.py\", line 28, in run_sync\r\n",
      "    return await get_asynclib().run_sync_in_worker_thread(func, *args, cancellable=cancellable,\r\n",
      "  File \"/Users/evanhofmeister/opt/anaconda3/lib/python3.9/site-packages/anyio/_backends/_asyncio.py\", line 818, in run_sync_in_worker_thread\r\n",
      "    return await future\r\n",
      "  File \"/Users/evanhofmeister/opt/anaconda3/lib/python3.9/site-packages/anyio/_backends/_asyncio.py\", line 754, in run\r\n",
      "    result = context.run(func, *args)\r\n",
      "  File \"/Users/evanhofmeister/opt/anaconda3/lib/python3.9/site-packages/prefect/server/database/dependencies.py\", line 81, in provide_database_interface\r\n",
      "    orm = AioSqliteORMConfiguration()\r\n",
      "  File \"/Users/evanhofmeister/opt/anaconda3/lib/python3.9/site-packages/prefect/server/database/orm_models.py\", line 1400, in __init__\r\n",
      "    self._create_orm_models(\r\n",
      "  File \"/Users/evanhofmeister/opt/anaconda3/lib/python3.9/site-packages/prefect/server/database/orm_models.py\", line 1550, in _create_orm_models\r\n",
      "    class Variable(variable_mixin, self.Base):\r\n",
      "  File \"/Users/evanhofmeister/opt/anaconda3/lib/python3.9/site-packages/sqlalchemy/orm/decl_api.py\", line 193, in __init__\r\n",
      "    _as_declarative(reg, cls, dict_)\r\n",
      "  File \"/Users/evanhofmeister/opt/anaconda3/lib/python3.9/site-packages/sqlalchemy/orm/decl_base.py\", line 247, in _as_declarative\r\n",
      "    return _MapperConfig.setup_mapping(registry, cls, dict_, None, {})\r\n",
      "  File \"/Users/evanhofmeister/opt/anaconda3/lib/python3.9/site-packages/sqlalchemy/orm/decl_base.py\", line 328, in setup_mapping\r\n",
      "    return _ClassScanMapperConfig(\r\n",
      "  File \"/Users/evanhofmeister/opt/anaconda3/lib/python3.9/site-packages/sqlalchemy/orm/decl_base.py\", line 563, in __init__\r\n",
      "    self._scan_attributes()\r\n",
      "  File \"/Users/evanhofmeister/opt/anaconda3/lib/python3.9/site-packages/sqlalchemy/orm/decl_base.py\", line 785, in _scan_attributes\r\n",
      "    locally_collected_columns = self._produce_column_copies(\r\n",
      "  File \"/Users/evanhofmeister/opt/anaconda3/lib/python3.9/site-packages/sqlalchemy/orm/decl_base.py\", line 1388, in _produce_column_copies\r\n",
      "    collected_annotation = self._collect_annotation(\r\n",
      "  File \"/Users/evanhofmeister/opt/anaconda3/lib/python3.9/site-packages/sqlalchemy/orm/decl_base.py\", line 1277, in _collect_annotation\r\n",
      "    extracted = _extract_mapped_subtype(\r\n",
      "  File \"/Users/evanhofmeister/opt/anaconda3/lib/python3.9/site-packages/sqlalchemy/orm/util.py\", line 2356, in _extract_mapped_subtype\r\n",
      "    raise sa_exc.ArgumentError(\r\n",
      "sqlalchemy.exc.ArgumentError: Type annotation for \"Variable.name\" can't be correctly interpreted for Annotated Declarative Table form.  ORM annotations should normally make use of the ``Mapped[]`` generic type, or other ORM-compatible generic type, as a container for the actual type, which indicates the intent that the attribute is mapped. Class variables that are not intended to be mapped by the ORM should use ClassVar[].  To allow Annotated Declarative to disregard legacy annotations which don't use Mapped[] to pass, set \"__allow_unmapped__ = True\" on the class or a superclass this class. (Background on this error at: https://sqlalche.me/e/20/zlpr)\r\n",
      "12:34:37.999 | \u001B[31mERROR\u001B[0m   | prefect.server - Encountered exception in request:\r\n",
      "Traceback (most recent call last):\r\n",
      "  File \"/Users/evanhofmeister/opt/anaconda3/lib/python3.9/site-packages/starlette/middleware/errors.py\", line 162, in __call__\r\n",
      "    await self.app(scope, receive, _send)\r\n",
      "  File \"/Users/evanhofmeister/opt/anaconda3/lib/python3.9/site-packages/starlette/middleware/gzip.py\", line 24, in __call__\r\n",
      "    await responder(scope, receive, send)\r\n",
      "  File \"/Users/evanhofmeister/opt/anaconda3/lib/python3.9/site-packages/starlette/middleware/gzip.py\", line 44, in __call__\r\n",
      "    await self.app(scope, receive, self.send_with_gzip)\r\n",
      "  File \"/Users/evanhofmeister/opt/anaconda3/lib/python3.9/site-packages/starlette/middleware/exceptions.py\", line 62, in __call__\r\n",
      "    await wrap_app_handling_exceptions(self.app, conn)(scope, receive, send)\r\n",
      "  File \"/Users/evanhofmeister/opt/anaconda3/lib/python3.9/site-packages/starlette/_exception_handler.py\", line 57, in wrapped_app\r\n",
      "    raise exc\r\n",
      "  File \"/Users/evanhofmeister/opt/anaconda3/lib/python3.9/site-packages/starlette/_exception_handler.py\", line 46, in wrapped_app\r\n",
      "    await app(scope, receive, sender)\r\n",
      "  File \"/Users/evanhofmeister/opt/anaconda3/lib/python3.9/site-packages/fastapi/middleware/asyncexitstack.py\", line 21, in __call__\r\n",
      "    raise e\r\n",
      "  File \"/Users/evanhofmeister/opt/anaconda3/lib/python3.9/site-packages/fastapi/middleware/asyncexitstack.py\", line 18, in __call__\r\n",
      "    await self.app(scope, receive, send)\r\n",
      "  File \"/Users/evanhofmeister/opt/anaconda3/lib/python3.9/site-packages/starlette/routing.py\", line 727, in __call__\r\n",
      "    await route.handle(scope, receive, send)\r\n",
      "  File \"/Users/evanhofmeister/opt/anaconda3/lib/python3.9/site-packages/starlette/routing.py\", line 285, in handle\r\n",
      "    await self.app(scope, receive, send)\r\n",
      "  File \"/Users/evanhofmeister/opt/anaconda3/lib/python3.9/site-packages/starlette/routing.py\", line 74, in app\r\n",
      "    await wrap_app_handling_exceptions(app, request)(scope, receive, send)\r\n",
      "  File \"/Users/evanhofmeister/opt/anaconda3/lib/python3.9/site-packages/starlette/_exception_handler.py\", line 57, in wrapped_app\r\n",
      "    raise exc\r\n",
      "  File \"/Users/evanhofmeister/opt/anaconda3/lib/python3.9/site-packages/starlette/_exception_handler.py\", line 46, in wrapped_app\r\n",
      "    await app(scope, receive, sender)\r\n",
      "  File \"/Users/evanhofmeister/opt/anaconda3/lib/python3.9/site-packages/starlette/routing.py\", line 69, in app\r\n",
      "    response = await func(request)\r\n",
      "  File \"/Users/evanhofmeister/opt/anaconda3/lib/python3.9/site-packages/prefect/server/utilities/server.py\", line 103, in handle_response_scoped_depends\r\n",
      "    response = await default_handler(request)\r\n",
      "  File \"/Users/evanhofmeister/opt/anaconda3/lib/python3.9/site-packages/fastapi/routing.py\", line 227, in app\r\n",
      "    solved_result = await solve_dependencies(\r\n",
      "  File \"/Users/evanhofmeister/opt/anaconda3/lib/python3.9/site-packages/fastapi/dependencies/utils.py\", line 624, in solve_dependencies\r\n",
      "    solved = await run_in_threadpool(call, **sub_values)\r\n",
      "  File \"/Users/evanhofmeister/opt/anaconda3/lib/python3.9/site-packages/starlette/concurrency.py\", line 41, in run_in_threadpool\r\n",
      "    return await anyio.to_thread.run_sync(func, *args)\r\n",
      "  File \"/Users/evanhofmeister/opt/anaconda3/lib/python3.9/site-packages/anyio/to_thread.py\", line 28, in run_sync\r\n",
      "    return await get_asynclib().run_sync_in_worker_thread(func, *args, cancellable=cancellable,\r\n",
      "  File \"/Users/evanhofmeister/opt/anaconda3/lib/python3.9/site-packages/anyio/_backends/_asyncio.py\", line 818, in run_sync_in_worker_thread\r\n",
      "    return await future\r\n",
      "  File \"/Users/evanhofmeister/opt/anaconda3/lib/python3.9/site-packages/anyio/_backends/_asyncio.py\", line 754, in run\r\n",
      "    result = context.run(func, *args)\r\n",
      "  File \"/Users/evanhofmeister/opt/anaconda3/lib/python3.9/site-packages/prefect/server/database/dependencies.py\", line 81, in provide_database_interface\r\n",
      "    orm = AioSqliteORMConfiguration()\r\n",
      "  File \"/Users/evanhofmeister/opt/anaconda3/lib/python3.9/site-packages/prefect/server/database/orm_models.py\", line 1400, in __init__\r\n",
      "    self._create_orm_models(\r\n",
      "  File \"/Users/evanhofmeister/opt/anaconda3/lib/python3.9/site-packages/prefect/server/database/orm_models.py\", line 1550, in _create_orm_models\r\n",
      "    class Variable(variable_mixin, self.Base):\r\n",
      "  File \"/Users/evanhofmeister/opt/anaconda3/lib/python3.9/site-packages/sqlalchemy/orm/decl_api.py\", line 193, in __init__\r\n",
      "    _as_declarative(reg, cls, dict_)\r\n",
      "  File \"/Users/evanhofmeister/opt/anaconda3/lib/python3.9/site-packages/sqlalchemy/orm/decl_base.py\", line 247, in _as_declarative\r\n",
      "    return _MapperConfig.setup_mapping(registry, cls, dict_, None, {})\r\n",
      "  File \"/Users/evanhofmeister/opt/anaconda3/lib/python3.9/site-packages/sqlalchemy/orm/decl_base.py\", line 328, in setup_mapping\r\n",
      "    return _ClassScanMapperConfig(\r\n",
      "  File \"/Users/evanhofmeister/opt/anaconda3/lib/python3.9/site-packages/sqlalchemy/orm/decl_base.py\", line 563, in __init__\r\n",
      "    self._scan_attributes()\r\n",
      "  File \"/Users/evanhofmeister/opt/anaconda3/lib/python3.9/site-packages/sqlalchemy/orm/decl_base.py\", line 785, in _scan_attributes\r\n",
      "    locally_collected_columns = self._produce_column_copies(\r\n",
      "  File \"/Users/evanhofmeister/opt/anaconda3/lib/python3.9/site-packages/sqlalchemy/orm/decl_base.py\", line 1388, in _produce_column_copies\r\n",
      "    collected_annotation = self._collect_annotation(\r\n",
      "  File \"/Users/evanhofmeister/opt/anaconda3/lib/python3.9/site-packages/sqlalchemy/orm/decl_base.py\", line 1277, in _collect_annotation\r\n",
      "    extracted = _extract_mapped_subtype(\r\n",
      "  File \"/Users/evanhofmeister/opt/anaconda3/lib/python3.9/site-packages/sqlalchemy/orm/util.py\", line 2356, in _extract_mapped_subtype\r\n",
      "    raise sa_exc.ArgumentError(\r\n",
      "sqlalchemy.exc.ArgumentError: Type annotation for \"Variable.name\" can't be correctly interpreted for Annotated Declarative Table form.  ORM annotations should normally make use of the ``Mapped[]`` generic type, or other ORM-compatible generic type, as a container for the actual type, which indicates the intent that the attribute is mapped. Class variables that are not intended to be mapped by the ORM should use ClassVar[].  To allow Annotated Declarative to disregard legacy annotations which don't use Mapped[] to pass, set \"__allow_unmapped__ = True\" on the class or a superclass this class. (Background on this error at: \u001B[94mhttps://sqlalche.me/e/20/zlpr)\u001B[0m\r\n",
      "Exception in ASGI application\r\n",
      "Traceback (most recent call last):\r\n",
      "  File \"/Users/evanhofmeister/opt/anaconda3/lib/python3.9/site-packages/uvicorn/protocols/http/h11_impl.py\", line 429, in run_asgi\r\n",
      "    result = await app(  # type: ignore[func-returns-value]\r\n",
      "  File \"/Users/evanhofmeister/opt/anaconda3/lib/python3.9/site-packages/uvicorn/middleware/proxy_headers.py\", line 78, in __call__\r\n",
      "    return await self.app(scope, receive, send)\r\n",
      "  File \"/Users/evanhofmeister/opt/anaconda3/lib/python3.9/site-packages/uvicorn/middleware/message_logger.py\", line 86, in __call__\r\n",
      "    raise exc from None\r\n",
      "  File \"/Users/evanhofmeister/opt/anaconda3/lib/python3.9/site-packages/uvicorn/middleware/message_logger.py\", line 82, in __call__\r\n",
      "    await self.app(scope, inner_receive, inner_send)\r\n",
      "  File \"/Users/evanhofmeister/opt/anaconda3/lib/python3.9/site-packages/fastapi/applications.py\", line 276, in __call__\r\n",
      "    await super().__call__(scope, receive, send)\r\n",
      "  File \"/Users/evanhofmeister/opt/anaconda3/lib/python3.9/site-packages/starlette/applications.py\", line 122, in __call__\r\n",
      "    await self.middleware_stack(scope, receive, send)\r\n",
      "  File \"/Users/evanhofmeister/opt/anaconda3/lib/python3.9/site-packages/starlette/middleware/errors.py\", line 184, in __call__\r\n",
      "    raise exc\r\n",
      "  File \"/Users/evanhofmeister/opt/anaconda3/lib/python3.9/site-packages/starlette/middleware/errors.py\", line 162, in __call__\r\n",
      "    await self.app(scope, receive, _send)\r\n",
      "  File \"/Users/evanhofmeister/opt/anaconda3/lib/python3.9/site-packages/prefect/server/api/server.py\", line 117, in __call__\r\n",
      "    await self.app(scope, receive, send)\r\n",
      "  File \"/Users/evanhofmeister/opt/anaconda3/lib/python3.9/site-packages/starlette/middleware/cors.py\", line 91, in __call__\r\n",
      "    await self.simple_response(scope, receive, send, request_headers=headers)\r\n",
      "  File \"/Users/evanhofmeister/opt/anaconda3/lib/python3.9/site-packages/starlette/middleware/cors.py\", line 146, in simple_response\r\n",
      "    await self.app(scope, receive, send)\r\n",
      "  File \"/Users/evanhofmeister/opt/anaconda3/lib/python3.9/site-packages/starlette/middleware/exceptions.py\", line 62, in __call__\r\n",
      "    await wrap_app_handling_exceptions(self.app, conn)(scope, receive, send)\r\n",
      "  File \"/Users/evanhofmeister/opt/anaconda3/lib/python3.9/site-packages/starlette/_exception_handler.py\", line 57, in wrapped_app\r\n",
      "    raise exc\r\n",
      "  File \"/Users/evanhofmeister/opt/anaconda3/lib/python3.9/site-packages/starlette/_exception_handler.py\", line 46, in wrapped_app\r\n",
      "    await app(scope, receive, sender)\r\n",
      "  File \"/Users/evanhofmeister/opt/anaconda3/lib/python3.9/site-packages/fastapi/middleware/asyncexitstack.py\", line 21, in __call__\r\n",
      "    raise e\r\n",
      "  File \"/Users/evanhofmeister/opt/anaconda3/lib/python3.9/site-packages/fastapi/middleware/asyncexitstack.py\", line 18, in __call__\r\n",
      "    await self.app(scope, receive, send)\r\n",
      "  File \"/Users/evanhofmeister/opt/anaconda3/lib/python3.9/site-packages/starlette/routing.py\", line 727, in __call__\r\n",
      "    await route.handle(scope, receive, send)\r\n",
      "  File \"/Users/evanhofmeister/opt/anaconda3/lib/python3.9/site-packages/starlette/routing.py\", line 452, in handle\r\n",
      "    await self.app(scope, receive, send)\r\n",
      "  File \"/Users/evanhofmeister/opt/anaconda3/lib/python3.9/site-packages/fastapi/applications.py\", line 276, in __call__\r\n",
      "    await super().__call__(scope, receive, send)\r\n",
      "  File \"/Users/evanhofmeister/opt/anaconda3/lib/python3.9/site-packages/starlette/applications.py\", line 122, in __call__\r\n",
      "    await self.middleware_stack(scope, receive, send)\r\n",
      "  File \"/Users/evanhofmeister/opt/anaconda3/lib/python3.9/site-packages/starlette/middleware/errors.py\", line 184, in __call__\r\n",
      "    raise exc\r\n",
      "  File \"/Users/evanhofmeister/opt/anaconda3/lib/python3.9/site-packages/starlette/middleware/errors.py\", line 162, in __call__\r\n",
      "    await self.app(scope, receive, _send)\r\n",
      "  File \"/Users/evanhofmeister/opt/anaconda3/lib/python3.9/site-packages/starlette/middleware/gzip.py\", line 24, in __call__\r\n",
      "    await responder(scope, receive, send)\r\n",
      "  File \"/Users/evanhofmeister/opt/anaconda3/lib/python3.9/site-packages/starlette/middleware/gzip.py\", line 44, in __call__\r\n",
      "    await self.app(scope, receive, self.send_with_gzip)\r\n",
      "  File \"/Users/evanhofmeister/opt/anaconda3/lib/python3.9/site-packages/starlette/middleware/exceptions.py\", line 62, in __call__\r\n",
      "    await wrap_app_handling_exceptions(self.app, conn)(scope, receive, send)\r\n",
      "  File \"/Users/evanhofmeister/opt/anaconda3/lib/python3.9/site-packages/starlette/_exception_handler.py\", line 57, in wrapped_app\r\n",
      "    raise exc\r\n",
      "  File \"/Users/evanhofmeister/opt/anaconda3/lib/python3.9/site-packages/starlette/_exception_handler.py\", line 46, in wrapped_app\r\n",
      "    await app(scope, receive, sender)\r\n",
      "  File \"/Users/evanhofmeister/opt/anaconda3/lib/python3.9/site-packages/fastapi/middleware/asyncexitstack.py\", line 21, in __call__\r\n",
      "    raise e\r\n",
      "  File \"/Users/evanhofmeister/opt/anaconda3/lib/python3.9/site-packages/fastapi/middleware/asyncexitstack.py\", line 18, in __call__\r\n",
      "    await self.app(scope, receive, send)\r\n",
      "  File \"/Users/evanhofmeister/opt/anaconda3/lib/python3.9/site-packages/starlette/routing.py\", line 727, in __call__\r\n",
      "    await route.handle(scope, receive, send)\r\n",
      "  File \"/Users/evanhofmeister/opt/anaconda3/lib/python3.9/site-packages/starlette/routing.py\", line 285, in handle\r\n",
      "    await self.app(scope, receive, send)\r\n",
      "  File \"/Users/evanhofmeister/opt/anaconda3/lib/python3.9/site-packages/starlette/routing.py\", line 74, in app\r\n",
      "    await wrap_app_handling_exceptions(app, request)(scope, receive, send)\r\n",
      "  File \"/Users/evanhofmeister/opt/anaconda3/lib/python3.9/site-packages/starlette/_exception_handler.py\", line 57, in wrapped_app\r\n",
      "    raise exc\r\n",
      "  File \"/Users/evanhofmeister/opt/anaconda3/lib/python3.9/site-packages/starlette/_exception_handler.py\", line 46, in wrapped_app\r\n",
      "    await app(scope, receive, sender)\r\n",
      "  File \"/Users/evanhofmeister/opt/anaconda3/lib/python3.9/site-packages/starlette/routing.py\", line 69, in app\r\n",
      "    response = await func(request)\r\n",
      "  File \"/Users/evanhofmeister/opt/anaconda3/lib/python3.9/site-packages/prefect/server/utilities/server.py\", line 103, in handle_response_scoped_depends\r\n",
      "    response = await default_handler(request)\r\n",
      "  File \"/Users/evanhofmeister/opt/anaconda3/lib/python3.9/site-packages/fastapi/routing.py\", line 227, in app\r\n",
      "    solved_result = await solve_dependencies(\r\n",
      "  File \"/Users/evanhofmeister/opt/anaconda3/lib/python3.9/site-packages/fastapi/dependencies/utils.py\", line 624, in solve_dependencies\r\n",
      "    solved = await run_in_threadpool(call, **sub_values)\r\n",
      "  File \"/Users/evanhofmeister/opt/anaconda3/lib/python3.9/site-packages/starlette/concurrency.py\", line 41, in run_in_threadpool\r\n",
      "    return await anyio.to_thread.run_sync(func, *args)\r\n",
      "  File \"/Users/evanhofmeister/opt/anaconda3/lib/python3.9/site-packages/anyio/to_thread.py\", line 28, in run_sync\r\n",
      "    return await get_asynclib().run_sync_in_worker_thread(func, *args, cancellable=cancellable,\r\n",
      "  File \"/Users/evanhofmeister/opt/anaconda3/lib/python3.9/site-packages/anyio/_backends/_asyncio.py\", line 818, in run_sync_in_worker_thread\r\n",
      "    return await future\r\n",
      "  File \"/Users/evanhofmeister/opt/anaconda3/lib/python3.9/site-packages/anyio/_backends/_asyncio.py\", line 754, in run\r\n",
      "    result = context.run(func, *args)\r\n",
      "  File \"/Users/evanhofmeister/opt/anaconda3/lib/python3.9/site-packages/prefect/server/database/dependencies.py\", line 81, in provide_database_interface\r\n",
      "    orm = AioSqliteORMConfiguration()\r\n",
      "  File \"/Users/evanhofmeister/opt/anaconda3/lib/python3.9/site-packages/prefect/server/database/orm_models.py\", line 1400, in __init__\r\n",
      "    self._create_orm_models(\r\n",
      "  File \"/Users/evanhofmeister/opt/anaconda3/lib/python3.9/site-packages/prefect/server/database/orm_models.py\", line 1550, in _create_orm_models\r\n",
      "    class Variable(variable_mixin, self.Base):\r\n",
      "  File \"/Users/evanhofmeister/opt/anaconda3/lib/python3.9/site-packages/sqlalchemy/orm/decl_api.py\", line 193, in __init__\r\n",
      "    _as_declarative(reg, cls, dict_)\r\n",
      "  File \"/Users/evanhofmeister/opt/anaconda3/lib/python3.9/site-packages/sqlalchemy/orm/decl_base.py\", line 247, in _as_declarative\r\n",
      "    return _MapperConfig.setup_mapping(registry, cls, dict_, None, {})\r\n",
      "  File \"/Users/evanhofmeister/opt/anaconda3/lib/python3.9/site-packages/sqlalchemy/orm/decl_base.py\", line 328, in setup_mapping\r\n",
      "    return _ClassScanMapperConfig(\r\n",
      "  File \"/Users/evanhofmeister/opt/anaconda3/lib/python3.9/site-packages/sqlalchemy/orm/decl_base.py\", line 563, in __init__\r\n",
      "    self._scan_attributes()\r\n",
      "  File \"/Users/evanhofmeister/opt/anaconda3/lib/python3.9/site-packages/sqlalchemy/orm/decl_base.py\", line 785, in _scan_attributes\r\n",
      "    locally_collected_columns = self._produce_column_copies(\r\n",
      "  File \"/Users/evanhofmeister/opt/anaconda3/lib/python3.9/site-packages/sqlalchemy/orm/decl_base.py\", line 1388, in _produce_column_copies\r\n",
      "    collected_annotation = self._collect_annotation(\r\n",
      "  File \"/Users/evanhofmeister/opt/anaconda3/lib/python3.9/site-packages/sqlalchemy/orm/decl_base.py\", line 1277, in _collect_annotation\r\n",
      "    extracted = _extract_mapped_subtype(\r\n",
      "  File \"/Users/evanhofmeister/opt/anaconda3/lib/python3.9/site-packages/sqlalchemy/orm/util.py\", line 2356, in _extract_mapped_subtype\r\n",
      "    raise sa_exc.ArgumentError(\r\n",
      "sqlalchemy.exc.ArgumentError: Type annotation for \"Variable.name\" can't be correctly interpreted for Annotated Declarative Table form.  ORM annotations should normally make use of the ``Mapped[]`` generic type, or other ORM-compatible generic type, as a container for the actual type, which indicates the intent that the attribute is mapped. Class variables that are not intended to be mapped by the ORM should use ClassVar[].  To allow Annotated Declarative to disregard legacy annotations which don't use Mapped[] to pass, set \"__allow_unmapped__ = True\" on the class or a superclass this class. (Background on this error at: https://sqlalche.me/e/20/zlpr)\r\n",
      "12:34:38.002 | \u001B[31mERROR\u001B[0m   | prefect.server - Encountered exception in request:\r\n",
      "Traceback (most recent call last):\r\n",
      "  File \"/Users/evanhofmeister/opt/anaconda3/lib/python3.9/site-packages/starlette/middleware/errors.py\", line 162, in __call__\r\n",
      "    await self.app(scope, receive, _send)\r\n",
      "  File \"/Users/evanhofmeister/opt/anaconda3/lib/python3.9/site-packages/starlette/middleware/gzip.py\", line 24, in __call__\r\n",
      "    await responder(scope, receive, send)\r\n",
      "  File \"/Users/evanhofmeister/opt/anaconda3/lib/python3.9/site-packages/starlette/middleware/gzip.py\", line 44, in __call__\r\n",
      "    await self.app(scope, receive, self.send_with_gzip)\r\n",
      "  File \"/Users/evanhofmeister/opt/anaconda3/lib/python3.9/site-packages/starlette/middleware/exceptions.py\", line 62, in __call__\r\n",
      "    await wrap_app_handling_exceptions(self.app, conn)(scope, receive, send)\r\n",
      "  File \"/Users/evanhofmeister/opt/anaconda3/lib/python3.9/site-packages/starlette/_exception_handler.py\", line 57, in wrapped_app\r\n",
      "    raise exc\r\n",
      "  File \"/Users/evanhofmeister/opt/anaconda3/lib/python3.9/site-packages/starlette/_exception_handler.py\", line 46, in wrapped_app\r\n",
      "    await app(scope, receive, sender)\r\n",
      "  File \"/Users/evanhofmeister/opt/anaconda3/lib/python3.9/site-packages/fastapi/middleware/asyncexitstack.py\", line 21, in __call__\r\n",
      "    raise e\r\n",
      "  File \"/Users/evanhofmeister/opt/anaconda3/lib/python3.9/site-packages/fastapi/middleware/asyncexitstack.py\", line 18, in __call__\r\n",
      "    await self.app(scope, receive, send)\r\n",
      "  File \"/Users/evanhofmeister/opt/anaconda3/lib/python3.9/site-packages/starlette/routing.py\", line 727, in __call__\r\n",
      "    await route.handle(scope, receive, send)\r\n",
      "  File \"/Users/evanhofmeister/opt/anaconda3/lib/python3.9/site-packages/starlette/routing.py\", line 285, in handle\r\n",
      "    await self.app(scope, receive, send)\r\n",
      "  File \"/Users/evanhofmeister/opt/anaconda3/lib/python3.9/site-packages/starlette/routing.py\", line 74, in app\r\n",
      "    await wrap_app_handling_exceptions(app, request)(scope, receive, send)\r\n",
      "  File \"/Users/evanhofmeister/opt/anaconda3/lib/python3.9/site-packages/starlette/_exception_handler.py\", line 57, in wrapped_app\r\n",
      "    raise exc\r\n",
      "  File \"/Users/evanhofmeister/opt/anaconda3/lib/python3.9/site-packages/starlette/_exception_handler.py\", line 46, in wrapped_app\r\n",
      "    await app(scope, receive, sender)\r\n",
      "  File \"/Users/evanhofmeister/opt/anaconda3/lib/python3.9/site-packages/starlette/routing.py\", line 69, in app\r\n",
      "    response = await func(request)\r\n",
      "  File \"/Users/evanhofmeister/opt/anaconda3/lib/python3.9/site-packages/prefect/server/utilities/server.py\", line 103, in handle_response_scoped_depends\r\n",
      "    response = await default_handler(request)\r\n",
      "  File \"/Users/evanhofmeister/opt/anaconda3/lib/python3.9/site-packages/fastapi/routing.py\", line 227, in app\r\n",
      "    solved_result = await solve_dependencies(\r\n",
      "  File \"/Users/evanhofmeister/opt/anaconda3/lib/python3.9/site-packages/fastapi/dependencies/utils.py\", line 624, in solve_dependencies\r\n",
      "    solved = await run_in_threadpool(call, **sub_values)\r\n",
      "  File \"/Users/evanhofmeister/opt/anaconda3/lib/python3.9/site-packages/starlette/concurrency.py\", line 41, in run_in_threadpool\r\n",
      "    return await anyio.to_thread.run_sync(func, *args)\r\n",
      "  File \"/Users/evanhofmeister/opt/anaconda3/lib/python3.9/site-packages/anyio/to_thread.py\", line 28, in run_sync\r\n",
      "    return await get_asynclib().run_sync_in_worker_thread(func, *args, cancellable=cancellable,\r\n",
      "  File \"/Users/evanhofmeister/opt/anaconda3/lib/python3.9/site-packages/anyio/_backends/_asyncio.py\", line 818, in run_sync_in_worker_thread\r\n",
      "    return await future\r\n",
      "  File \"/Users/evanhofmeister/opt/anaconda3/lib/python3.9/site-packages/anyio/_backends/_asyncio.py\", line 754, in run\r\n",
      "    result = context.run(func, *args)\r\n",
      "  File \"/Users/evanhofmeister/opt/anaconda3/lib/python3.9/site-packages/prefect/server/database/dependencies.py\", line 81, in provide_database_interface\r\n",
      "    orm = AioSqliteORMConfiguration()\r\n",
      "  File \"/Users/evanhofmeister/opt/anaconda3/lib/python3.9/site-packages/prefect/server/database/orm_models.py\", line 1400, in __init__\r\n",
      "    self._create_orm_models(\r\n",
      "  File \"/Users/evanhofmeister/opt/anaconda3/lib/python3.9/site-packages/prefect/server/database/orm_models.py\", line 1550, in _create_orm_models\r\n",
      "    class Variable(variable_mixin, self.Base):\r\n",
      "  File \"/Users/evanhofmeister/opt/anaconda3/lib/python3.9/site-packages/sqlalchemy/orm/decl_api.py\", line 193, in __init__\r\n",
      "    _as_declarative(reg, cls, dict_)\r\n",
      "  File \"/Users/evanhofmeister/opt/anaconda3/lib/python3.9/site-packages/sqlalchemy/orm/decl_base.py\", line 247, in _as_declarative\r\n",
      "    return _MapperConfig.setup_mapping(registry, cls, dict_, None, {})\r\n",
      "  File \"/Users/evanhofmeister/opt/anaconda3/lib/python3.9/site-packages/sqlalchemy/orm/decl_base.py\", line 328, in setup_mapping\r\n",
      "    return _ClassScanMapperConfig(\r\n",
      "  File \"/Users/evanhofmeister/opt/anaconda3/lib/python3.9/site-packages/sqlalchemy/orm/decl_base.py\", line 563, in __init__\r\n",
      "    self._scan_attributes()\r\n",
      "  File \"/Users/evanhofmeister/opt/anaconda3/lib/python3.9/site-packages/sqlalchemy/orm/decl_base.py\", line 785, in _scan_attributes\r\n",
      "    locally_collected_columns = self._produce_column_copies(\r\n",
      "  File \"/Users/evanhofmeister/opt/anaconda3/lib/python3.9/site-packages/sqlalchemy/orm/decl_base.py\", line 1388, in _produce_column_copies\r\n",
      "    collected_annotation = self._collect_annotation(\r\n",
      "  File \"/Users/evanhofmeister/opt/anaconda3/lib/python3.9/site-packages/sqlalchemy/orm/decl_base.py\", line 1277, in _collect_annotation\r\n",
      "    extracted = _extract_mapped_subtype(\r\n",
      "  File \"/Users/evanhofmeister/opt/anaconda3/lib/python3.9/site-packages/sqlalchemy/orm/util.py\", line 2356, in _extract_mapped_subtype\r\n",
      "    raise sa_exc.ArgumentError(\r\n",
      "sqlalchemy.exc.ArgumentError: Type annotation for \"Variable.name\" can't be correctly interpreted for Annotated Declarative Table form.  ORM annotations should normally make use of the ``Mapped[]`` generic type, or other ORM-compatible generic type, as a container for the actual type, which indicates the intent that the attribute is mapped. Class variables that are not intended to be mapped by the ORM should use ClassVar[].  To allow Annotated Declarative to disregard legacy annotations which don't use Mapped[] to pass, set \"__allow_unmapped__ = True\" on the class or a superclass this class. (Background on this error at: \u001B[94mhttps://sqlalche.me/e/20/zlpr)\u001B[0m\r\n",
      "Exception in ASGI application\r\n",
      "Traceback (most recent call last):\r\n",
      "  File \"/Users/evanhofmeister/opt/anaconda3/lib/python3.9/site-packages/uvicorn/protocols/http/h11_impl.py\", line 429, in run_asgi\r\n",
      "    result = await app(  # type: ignore[func-returns-value]\r\n",
      "  File \"/Users/evanhofmeister/opt/anaconda3/lib/python3.9/site-packages/uvicorn/middleware/proxy_headers.py\", line 78, in __call__\r\n",
      "    return await self.app(scope, receive, send)\r\n",
      "  File \"/Users/evanhofmeister/opt/anaconda3/lib/python3.9/site-packages/uvicorn/middleware/message_logger.py\", line 86, in __call__\r\n",
      "    raise exc from None\r\n",
      "  File \"/Users/evanhofmeister/opt/anaconda3/lib/python3.9/site-packages/uvicorn/middleware/message_logger.py\", line 82, in __call__\r\n",
      "    await self.app(scope, inner_receive, inner_send)\r\n",
      "  File \"/Users/evanhofmeister/opt/anaconda3/lib/python3.9/site-packages/fastapi/applications.py\", line 276, in __call__\r\n",
      "    await super().__call__(scope, receive, send)\r\n",
      "  File \"/Users/evanhofmeister/opt/anaconda3/lib/python3.9/site-packages/starlette/applications.py\", line 122, in __call__\r\n",
      "    await self.middleware_stack(scope, receive, send)\r\n",
      "  File \"/Users/evanhofmeister/opt/anaconda3/lib/python3.9/site-packages/starlette/middleware/errors.py\", line 184, in __call__\r\n",
      "    raise exc\r\n",
      "  File \"/Users/evanhofmeister/opt/anaconda3/lib/python3.9/site-packages/starlette/middleware/errors.py\", line 162, in __call__\r\n",
      "    await self.app(scope, receive, _send)\r\n",
      "  File \"/Users/evanhofmeister/opt/anaconda3/lib/python3.9/site-packages/prefect/server/api/server.py\", line 117, in __call__\r\n",
      "    await self.app(scope, receive, send)\r\n",
      "  File \"/Users/evanhofmeister/opt/anaconda3/lib/python3.9/site-packages/starlette/middleware/cors.py\", line 91, in __call__\r\n",
      "    await self.simple_response(scope, receive, send, request_headers=headers)\r\n",
      "  File \"/Users/evanhofmeister/opt/anaconda3/lib/python3.9/site-packages/starlette/middleware/cors.py\", line 146, in simple_response\r\n",
      "    await self.app(scope, receive, send)\r\n",
      "  File \"/Users/evanhofmeister/opt/anaconda3/lib/python3.9/site-packages/starlette/middleware/exceptions.py\", line 62, in __call__\r\n",
      "    await wrap_app_handling_exceptions(self.app, conn)(scope, receive, send)\r\n",
      "  File \"/Users/evanhofmeister/opt/anaconda3/lib/python3.9/site-packages/starlette/_exception_handler.py\", line 57, in wrapped_app\r\n",
      "    raise exc\r\n",
      "  File \"/Users/evanhofmeister/opt/anaconda3/lib/python3.9/site-packages/starlette/_exception_handler.py\", line 46, in wrapped_app\r\n",
      "    await app(scope, receive, sender)\r\n",
      "  File \"/Users/evanhofmeister/opt/anaconda3/lib/python3.9/site-packages/fastapi/middleware/asyncexitstack.py\", line 21, in __call__\r\n",
      "    raise e\r\n",
      "  File \"/Users/evanhofmeister/opt/anaconda3/lib/python3.9/site-packages/fastapi/middleware/asyncexitstack.py\", line 18, in __call__\r\n",
      "    await self.app(scope, receive, send)\r\n",
      "  File \"/Users/evanhofmeister/opt/anaconda3/lib/python3.9/site-packages/starlette/routing.py\", line 727, in __call__\r\n",
      "    await route.handle(scope, receive, send)\r\n",
      "  File \"/Users/evanhofmeister/opt/anaconda3/lib/python3.9/site-packages/starlette/routing.py\", line 452, in handle\r\n",
      "    await self.app(scope, receive, send)\r\n",
      "  File \"/Users/evanhofmeister/opt/anaconda3/lib/python3.9/site-packages/fastapi/applications.py\", line 276, in __call__\r\n",
      "    await super().__call__(scope, receive, send)\r\n",
      "  File \"/Users/evanhofmeister/opt/anaconda3/lib/python3.9/site-packages/starlette/applications.py\", line 122, in __call__\r\n",
      "    await self.middleware_stack(scope, receive, send)\r\n",
      "  File \"/Users/evanhofmeister/opt/anaconda3/lib/python3.9/site-packages/starlette/middleware/errors.py\", line 184, in __call__\r\n",
      "    raise exc\r\n",
      "  File \"/Users/evanhofmeister/opt/anaconda3/lib/python3.9/site-packages/starlette/middleware/errors.py\", line 162, in __call__\r\n",
      "    await self.app(scope, receive, _send)\r\n",
      "  File \"/Users/evanhofmeister/opt/anaconda3/lib/python3.9/site-packages/starlette/middleware/gzip.py\", line 24, in __call__\r\n",
      "    await responder(scope, receive, send)\r\n",
      "  File \"/Users/evanhofmeister/opt/anaconda3/lib/python3.9/site-packages/starlette/middleware/gzip.py\", line 44, in __call__\r\n",
      "    await self.app(scope, receive, self.send_with_gzip)\r\n",
      "  File \"/Users/evanhofmeister/opt/anaconda3/lib/python3.9/site-packages/starlette/middleware/exceptions.py\", line 62, in __call__\r\n",
      "    await wrap_app_handling_exceptions(self.app, conn)(scope, receive, send)\r\n",
      "  File \"/Users/evanhofmeister/opt/anaconda3/lib/python3.9/site-packages/starlette/_exception_handler.py\", line 57, in wrapped_app\r\n",
      "    raise exc\r\n",
      "  File \"/Users/evanhofmeister/opt/anaconda3/lib/python3.9/site-packages/starlette/_exception_handler.py\", line 46, in wrapped_app\r\n",
      "    await app(scope, receive, sender)\r\n",
      "  File \"/Users/evanhofmeister/opt/anaconda3/lib/python3.9/site-packages/fastapi/middleware/asyncexitstack.py\", line 21, in __call__\r\n",
      "    raise e\r\n",
      "  File \"/Users/evanhofmeister/opt/anaconda3/lib/python3.9/site-packages/fastapi/middleware/asyncexitstack.py\", line 18, in __call__\r\n",
      "    await self.app(scope, receive, send)\r\n",
      "  File \"/Users/evanhofmeister/opt/anaconda3/lib/python3.9/site-packages/starlette/routing.py\", line 727, in __call__\r\n",
      "    await route.handle(scope, receive, send)\r\n",
      "  File \"/Users/evanhofmeister/opt/anaconda3/lib/python3.9/site-packages/starlette/routing.py\", line 285, in handle\r\n",
      "    await self.app(scope, receive, send)\r\n",
      "  File \"/Users/evanhofmeister/opt/anaconda3/lib/python3.9/site-packages/starlette/routing.py\", line 74, in app\r\n",
      "    await wrap_app_handling_exceptions(app, request)(scope, receive, send)\r\n",
      "  File \"/Users/evanhofmeister/opt/anaconda3/lib/python3.9/site-packages/starlette/_exception_handler.py\", line 57, in wrapped_app\r\n",
      "    raise exc\r\n",
      "  File \"/Users/evanhofmeister/opt/anaconda3/lib/python3.9/site-packages/starlette/_exception_handler.py\", line 46, in wrapped_app\r\n",
      "    await app(scope, receive, sender)\r\n",
      "  File \"/Users/evanhofmeister/opt/anaconda3/lib/python3.9/site-packages/starlette/routing.py\", line 69, in app\r\n",
      "    response = await func(request)\r\n",
      "  File \"/Users/evanhofmeister/opt/anaconda3/lib/python3.9/site-packages/prefect/server/utilities/server.py\", line 103, in handle_response_scoped_depends\r\n",
      "    response = await default_handler(request)\r\n",
      "  File \"/Users/evanhofmeister/opt/anaconda3/lib/python3.9/site-packages/fastapi/routing.py\", line 227, in app\r\n",
      "    solved_result = await solve_dependencies(\r\n",
      "  File \"/Users/evanhofmeister/opt/anaconda3/lib/python3.9/site-packages/fastapi/dependencies/utils.py\", line 624, in solve_dependencies\r\n",
      "    solved = await run_in_threadpool(call, **sub_values)\r\n",
      "  File \"/Users/evanhofmeister/opt/anaconda3/lib/python3.9/site-packages/starlette/concurrency.py\", line 41, in run_in_threadpool\r\n",
      "    return await anyio.to_thread.run_sync(func, *args)\r\n",
      "  File \"/Users/evanhofmeister/opt/anaconda3/lib/python3.9/site-packages/anyio/to_thread.py\", line 28, in run_sync\r\n",
      "    return await get_asynclib().run_sync_in_worker_thread(func, *args, cancellable=cancellable,\r\n",
      "  File \"/Users/evanhofmeister/opt/anaconda3/lib/python3.9/site-packages/anyio/_backends/_asyncio.py\", line 818, in run_sync_in_worker_thread\r\n",
      "    return await future\r\n",
      "  File \"/Users/evanhofmeister/opt/anaconda3/lib/python3.9/site-packages/anyio/_backends/_asyncio.py\", line 754, in run\r\n",
      "    result = context.run(func, *args)\r\n",
      "  File \"/Users/evanhofmeister/opt/anaconda3/lib/python3.9/site-packages/prefect/server/database/dependencies.py\", line 81, in provide_database_interface\r\n",
      "    orm = AioSqliteORMConfiguration()\r\n",
      "  File \"/Users/evanhofmeister/opt/anaconda3/lib/python3.9/site-packages/prefect/server/database/orm_models.py\", line 1400, in __init__\r\n",
      "    self._create_orm_models(\r\n",
      "  File \"/Users/evanhofmeister/opt/anaconda3/lib/python3.9/site-packages/prefect/server/database/orm_models.py\", line 1550, in _create_orm_models\r\n",
      "    class Variable(variable_mixin, self.Base):\r\n",
      "  File \"/Users/evanhofmeister/opt/anaconda3/lib/python3.9/site-packages/sqlalchemy/orm/decl_api.py\", line 193, in __init__\r\n",
      "    _as_declarative(reg, cls, dict_)\r\n",
      "  File \"/Users/evanhofmeister/opt/anaconda3/lib/python3.9/site-packages/sqlalchemy/orm/decl_base.py\", line 247, in _as_declarative\r\n",
      "    return _MapperConfig.setup_mapping(registry, cls, dict_, None, {})\r\n",
      "  File \"/Users/evanhofmeister/opt/anaconda3/lib/python3.9/site-packages/sqlalchemy/orm/decl_base.py\", line 328, in setup_mapping\r\n",
      "    return _ClassScanMapperConfig(\r\n",
      "  File \"/Users/evanhofmeister/opt/anaconda3/lib/python3.9/site-packages/sqlalchemy/orm/decl_base.py\", line 563, in __init__\r\n",
      "    self._scan_attributes()\r\n",
      "  File \"/Users/evanhofmeister/opt/anaconda3/lib/python3.9/site-packages/sqlalchemy/orm/decl_base.py\", line 785, in _scan_attributes\r\n",
      "    locally_collected_columns = self._produce_column_copies(\r\n",
      "  File \"/Users/evanhofmeister/opt/anaconda3/lib/python3.9/site-packages/sqlalchemy/orm/decl_base.py\", line 1388, in _produce_column_copies\r\n",
      "    collected_annotation = self._collect_annotation(\r\n",
      "  File \"/Users/evanhofmeister/opt/anaconda3/lib/python3.9/site-packages/sqlalchemy/orm/decl_base.py\", line 1277, in _collect_annotation\r\n",
      "    extracted = _extract_mapped_subtype(\r\n",
      "  File \"/Users/evanhofmeister/opt/anaconda3/lib/python3.9/site-packages/sqlalchemy/orm/util.py\", line 2356, in _extract_mapped_subtype\r\n",
      "    raise sa_exc.ArgumentError(\r\n",
      "sqlalchemy.exc.ArgumentError: Type annotation for \"Variable.name\" can't be correctly interpreted for Annotated Declarative Table form.  ORM annotations should normally make use of the ``Mapped[]`` generic type, or other ORM-compatible generic type, as a container for the actual type, which indicates the intent that the attribute is mapped. Class variables that are not intended to be mapped by the ORM should use ClassVar[].  To allow Annotated Declarative to disregard legacy annotations which don't use Mapped[] to pass, set \"__allow_unmapped__ = True\" on the class or a superclass this class. (Background on this error at: https://sqlalche.me/e/20/zlpr)\r\n"
     ]
    }
   ],
   "source": [
    "!prefect server start"
   ],
   "metadata": {
    "collapsed": false,
    "pycharm": {
     "is_executing": true
    }
   }
  },
  {
   "cell_type": "code",
   "execution_count": 33,
   "outputs": [
    {
     "name": "stdout",
     "output_type": "stream",
     "text": [
      "Created project in \r\n",
      "\u001B[32m/Users/evanhofmeister/PycharmProjects/dezoomcamp-mlops-homework/homework/homewor\u001B[0m\r\n",
      "\u001B[32mk_3\u001B[0m with the following new files:\r\n",
      "\u001B[32m.prefectignore\u001B[0m\r\n",
      "\u001B[32mdeployment.yaml\u001B[0m\r\n",
      "\u001B[32mprefect.yaml\u001B[0m\r\n",
      "\u001B[32m.prefect/\u001B[0m\r\n"
     ]
    }
   ],
   "source": [
    "!rm deployment.yaml prefect.yaml .prefectignore\n",
    "!rm -rf .prefect/\n",
    "!prefect project init"
   ],
   "metadata": {
    "collapsed": false
   }
  },
  {
   "cell_type": "code",
   "execution_count": 34,
   "outputs": [
    {
     "name": "stdout",
     "output_type": "stream",
     "text": [
      "/Users/evanhofmeister/PycharmProjects/dezoomcamp-mlops-homework/homework/homework_3\r\n"
     ]
    }
   ],
   "source": [
    "!echo \"$PWD\""
   ],
   "metadata": {
    "collapsed": false
   }
  },
  {
   "cell_type": "code",
   "execution_count": 35,
   "outputs": [
    {
     "name": "stdout",
     "output_type": "stream",
     "text": [
      "Traceback (most recent call last):\r\n",
      "  File \"/Users/evanhofmeister/opt/anaconda3/lib/python3.9/site-packages/prefect/cli/_utilities.py\", line 41, in wrapper\r\n",
      "    return fn(*args, **kwargs)\r\n",
      "  File \"/Users/evanhofmeister/opt/anaconda3/lib/python3.9/site-packages/prefect/utilities/asyncutils.py\", line 260, in coroutine_wrapper\r\n",
      "    return call()\r\n",
      "  File \"/Users/evanhofmeister/opt/anaconda3/lib/python3.9/site-packages/prefect/_internal/concurrency/calls.py\", line 245, in __call__\r\n",
      "    return self.result()\r\n",
      "  File \"/Users/evanhofmeister/opt/anaconda3/lib/python3.9/site-packages/prefect/_internal/concurrency/calls.py\", line 173, in result\r\n",
      "    return self.future.result(timeout=timeout)\r\n",
      "  File \"/Users/evanhofmeister/opt/anaconda3/lib/python3.9/concurrent/futures/_base.py\", line 439, in result\r\n",
      "    return self.__get_result()\r\n",
      "  File \"/Users/evanhofmeister/opt/anaconda3/lib/python3.9/concurrent/futures/_base.py\", line 391, in __get_result\r\n",
      "    raise self._exception\r\n",
      "  File \"/Users/evanhofmeister/opt/anaconda3/lib/python3.9/site-packages/prefect/_internal/concurrency/calls.py\", line 218, in _run_async\r\n",
      "    result = await coro\r\n",
      "  File \"/Users/evanhofmeister/opt/anaconda3/lib/python3.9/site-packages/prefect/cli/root.py\", line 482, in deploy\r\n",
      "    flow_id = await client.create_flow_from_name(base_deploy[\"flow_name\"])\r\n",
      "  File \"/Users/evanhofmeister/opt/anaconda3/lib/python3.9/site-packages/prefect/client/orchestration.py\", line 303, in create_flow_from_name\r\n",
      "    response = await self._client.post(\r\n",
      "  File \"/Users/evanhofmeister/opt/anaconda3/lib/python3.9/site-packages/httpx/_client.py\", line 1845, in post\r\n",
      "    return await self.request(\r\n",
      "  File \"/Users/evanhofmeister/opt/anaconda3/lib/python3.9/site-packages/httpx/_client.py\", line 1530, in request\r\n",
      "    return await self.send(request, auth=auth, follow_redirects=follow_redirects)\r\n",
      "  File \"/Users/evanhofmeister/opt/anaconda3/lib/python3.9/site-packages/prefect/client/base.py\", line 278, in send\r\n",
      "    response.raise_for_status()\r\n",
      "  File \"/Users/evanhofmeister/opt/anaconda3/lib/python3.9/site-packages/prefect/client/base.py\", line 135, in raise_for_status\r\n",
      "    raise PrefectHTTPStatusError.from_httpx_error(exc) from exc.__cause__\r\n",
      "prefect.exceptions.PrefectHTTPStatusError: Server error '500 Internal Server Error' for url 'http://127.0.0.1:4200/api/flows/'\r\n",
      "Response: {'exception_message': 'Internal Server Error'}\r\n",
      "For more information check: https://httpstatuses.com/500\r\n",
      "\u001B[31mAn exception occurred.\u001B[0m\r\n"
     ]
    }
   ],
   "source": [
    "!prefect deploy orchestrate.py:main_flow -n homework -p pool_ex"
   ],
   "metadata": {
    "collapsed": false
   }
  },
  {
   "cell_type": "code",
   "execution_count": null,
   "outputs": [],
   "source": [
    "!prefect worker start -p pool_ex\n"
   ],
   "metadata": {
    "collapsed": false
   }
  },
  {
   "cell_type": "code",
   "execution_count": null,
   "outputs": [],
   "source": [],
   "metadata": {
    "collapsed": false
   }
  },
  {
   "cell_type": "markdown",
   "source": [
    "Answer: 5.19931"
   ],
   "metadata": {
    "collapsed": false
   }
  },
  {
   "cell_type": "markdown",
   "source": [],
   "metadata": {
    "collapsed": false
   }
  },
  {
   "cell_type": "markdown",
   "source": [
    "## Question 4"
   ],
   "metadata": {
    "collapsed": false
   }
  },
  {
   "cell_type": "code",
   "execution_count": null,
   "outputs": [],
   "source": [
    "!wget -P ./data https://d37ci6vzurychx.cloudfront.net/trip-data/green_tripdata_2023-03.parquet\n"
   ],
   "metadata": {
    "collapsed": false
   }
  },
  {
   "cell_type": "code",
   "execution_count": null,
   "outputs": [],
   "source": [
    "!from prefect.artifacts import create_markdown_artifact"
   ],
   "metadata": {
    "collapsed": false
   }
  },
  {
   "cell_type": "code",
   "execution_count": null,
   "outputs": [],
   "source": [
    "markdown__rmse_report = f\"\"\"# RMSE Report\n"
   ],
   "metadata": {
    "collapsed": false
   }
  },
  {
   "cell_type": "code",
   "execution_count": null,
   "outputs": [],
   "source": [
    "create_markdown_artifact(\n",
    "    key=\"duration-model-report\", markdown=markdown__rmse_report\n",
    ")"
   ],
   "metadata": {
    "collapsed": false
   }
  },
  {
   "cell_type": "code",
   "execution_count": null,
   "outputs": [],
   "source": [
    "def main_flow(\n",
    "    train_path: str = \"./data/green_tripdata_2023-02.parquet\",\n",
    "    val_path: str = \"./data/green_tripdata_2023-03.parquet\",\n",
    ") -> None:"
   ],
   "metadata": {
    "collapsed": false
   }
  },
  {
   "cell_type": "code",
   "execution_count": null,
   "outputs": [],
   "source": [
    "rm deployment.yaml prefect.yaml .prefectignore\n",
    "rm -rf .prefect/"
   ],
   "metadata": {
    "collapsed": false
   }
  },
  {
   "cell_type": "code",
   "execution_count": null,
   "outputs": [],
   "source": [
    "git commit -m \"update\"\n",
    "git push -u origin main"
   ],
   "metadata": {
    "collapsed": false
   }
  },
  {
   "cell_type": "code",
   "execution_count": null,
   "outputs": [],
   "source": [
    "prefect project init\n",
    "prefect deploy /orchestrate.py:main_flow -n homework -p pool_ex\n",
    "prefect worker start -p pool_ex"
   ],
   "metadata": {
    "collapsed": false
   }
  },
  {
   "cell_type": "markdown",
   "source": [
    "Answer: 5.37"
   ],
   "metadata": {
    "collapsed": false
   }
  },
  {
   "cell_type": "markdown",
   "source": [],
   "metadata": {
    "collapsed": false
   }
  },
  {
   "cell_type": "markdown",
   "source": [
    "## Question 5"
   ],
   "metadata": {
    "collapsed": false
   }
  },
  {
   "cell_type": "markdown",
   "source": [
    "Answer: email_send_message"
   ],
   "metadata": {
    "collapsed": false
   }
  },
  {
   "cell_type": "markdown",
   "source": [],
   "metadata": {
    "collapsed": false
   }
  },
  {
   "cell_type": "markdown",
   "source": [
    "## Question 6"
   ],
   "metadata": {
    "collapsed": false
   }
  },
  {
   "cell_type": "markdown",
   "source": [
    "Answer: Actions"
   ],
   "metadata": {
    "collapsed": false
   }
  },
  {
   "cell_type": "markdown",
   "source": [],
   "metadata": {
    "collapsed": false
   }
  }
 ],
 "metadata": {
  "kernelspec": {
   "display_name": "Python 3",
   "language": "python",
   "name": "python3"
  },
  "language_info": {
   "codemirror_mode": {
    "name": "ipython",
    "version": 2
   },
   "file_extension": ".py",
   "mimetype": "text/x-python",
   "name": "python",
   "nbconvert_exporter": "python",
   "pygments_lexer": "ipython2",
   "version": "2.7.6"
  }
 },
 "nbformat": 4,
 "nbformat_minor": 0
}
